Workbook

Sheet Stats
A1: No. | B1: vars | C1: polys | D1: tdeg | E1: Ecs
A2: 17 | B2: 3 | C2: 7 | D2: 2 | E2: 0
A3: 19 | B3: 3 | C3: 7 | D3: 2 | E3: 0
A4: 20 | B4: 3 | C4: 8 | D4: 2 | E4: 0
A5: 22 | B5: 3 | C5: 8 | D5: 2 | E5: 0
A6: 23 | B6: 3 | C6: 9 | D6: 2 | E6: 0
A7: 25 | B7: 3 | C7: 10 | D7: 4 | E7: 0
A8: 26 | B8: 3 | C8: 1 | D8: 4 | E8: 0
A9: 27 | B9: 3 | C9: 10 | D9: 4 | E9: 0
A10: 28 | B10: 3 | C10: 9 | D10: 4 | E10: 0
A11: 29 | B11: 3 | C11: 9 | D11: 4 | E11: 0
A12: 30 | B12: 3 | C12: 11 | D12: 4 | E12: 0
A13: 31 | B13: 3 | C13: 1 | D13: 4 | E13: 0
... A68: 132 | B68: 3 | C68: 14 | D68: 4 | E68: 0

Sheet Template
A1: File | B1: rc_ordering | C1: rc_memory | D1: rc_cputime | E1: rc_realtime | F1: rc_cells | G1: qe_ordering | H1: qe_memory | I1: qe_cputime | J1: qe_realtime | K1: qe_cells | L1: Ordering match | M1: memory diff | N1: win | O1: % of other | P1: cputime diff | Q1: win | R1: % of other | S1: realtime diff | T1: win | U1: % of other | V1: cells diff | W1: win | X1: % of other | Z1: rc_memory_avg | AA1: rc_cputime_avg | AB1: rc_realtime_avg | AC1: rc_cells_avg | AD1: qe_memory_avg | AE1: qe_cputime_avg | AF1: qe_realtime_avg | AG1: qe_cells_avg | AH1: =M1&"_avg" -> memory diff_avg | AI1: =P1&"_avg" -> cputime diff_avg | AJ1: =S1&"_avg" -> realtime diff_avg | AK1: =V1&"_avg" -> cells diff_avg
L2: =IF(OR(ISNUMBER(SEARCH("ERROR", B2)), ISNUMBER(SEARCH("ERROR", G2)), ISNUMBER(SEARCH("TIME OUT", B2)), ISNUMBER(SEARCH("TIME OUT", G2))), "--", B2=G2) -> TRUE | M2: =IF(OR(ISNUMBER(SEARCH("ERROR", C2)), ISNUMBER(SEARCH("ERROR", H2)), ISNUMBER(SEARCH("TIME OUT", C2)), ISNUMBER(SEARCH("TIME OUT", H2))),"--",C2-H2) -> 0 | N2: =IF(AND(OR(ISNUMBER(SEARCH("TIME OUT", C2)), ISNUMBER(SEARCH("ERROR", C2))), OR(ISNUMBER(SEARCH("TIME OUT", H2)), ISNUMBER(SEARCH("ERROR", H2)))), "--", IF(OR(ISNUMBER(SEARCH("TIME OUT", C2)), ISNUMBER(SEARCH("ERROR", C2))), "QE", IF(OR(ISNUMBER(SEARCH("TIME OUT", H2)), ISNUMBER(SEARCH("ERROR", H2))), "RC", IF(M2=0, "TIE", IF(M2>0, "QE", "RC"))))) -> TIE | O2: =IF(M2="--","--",TEXT(MIN(C2,H2)/MAX(C2,H2),"0.000%")) -> #DIV/0! | P2: =IF(OR(ISNUMBER(SEARCH("ERROR", D2)), ISNUMBER(SEARCH("ERROR", I2)), ISNUMBER(SEARCH("TIME OUT", D2)), ISNUMBER(SEARCH("TIME OUT", I2))),"--",D2-I2) -> 0 | Q2: =IF(AND(OR(ISNUMBER(SEARCH("TIME OUT", D2)), ISNUMBER(SEARCH("ERROR", D2))), OR(ISNUMBER(SEARCH("TIME OUT", I2)), ISNUMBER(SEARCH("ERROR", I2)))), "--", IF(OR(ISNUMBER(SEARCH("TIME OUT", D2)), ISNUMBER(SEARCH("ERROR", D2))), "QE", IF(OR(ISNUMBER(SEARCH("TIME OUT", I2)), ISNUMBER(SEARCH("ERROR", I2))), "RC", IF(P2=0, "TIE", IF(P2>0, "QE", "RC"))))) -> TIE | R2: =IF(P2="--","--",TEXT(MIN(D2,I2)/MAX(D2,I2),"0.000%")) -> #DIV/0! | S2: =IF(OR(ISNUMBER(SEARCH("ERROR", E2)), ISNUMBER(SEARCH("ERROR", J2)), ISNUMBER(SEARCH("TIME OUT", E2)), ISNUMBER(SEARCH("TIME OUT", J2))),"--",E2-J2) -> 0 | T2: =IF(AND(OR(ISNUMBER(SEARCH("TIME OUT", E2)), ISNUMBER(SEARCH("ERROR", E2))), OR(ISNUMBER(SEARCH("TIME OUT", J2)), ISNUMBER(SEARCH("ERROR", J2)))), "--", IF(OR(ISNUMBER(SEARCH("TIME OUT", E2)), ISNUMBER(SEARCH("ERROR", E2))), "QE", IF(OR(ISNUMBER(SEARCH("TIME OUT", J2)), ISNUMBER(SEARCH("ERROR", J2))), "RC", IF(S2=0, "TIE", IF(S2>0, "QE", "RC"))))) -> TIE | U2: =IF(S2="--","--",TEXT(MIN(E2,J2)/MAX(E2,J2),"0.000%")) -> #DIV/0! | V2: =IF(OR(ISNUMBER(SEARCH("ERROR", F2)), ISNUMBER(SEARCH("ERROR", K2)), ISNUMBER(SEARCH("TIME OUT", F2)), ISNUMBER(SEARCH("TIME OUT", K2))),"--",F2-K2) -> 0 | W2: =IF(AND(OR(ISNUMBER(SEARCH("TIME OUT", F2)), ISNUMBER(SEARCH("ERROR", F2))), OR(ISNUMBER(SEARCH("TIME OUT", K2)), ISNUMBER(SEARCH("ERROR", K2)))), "--", IF(OR(ISNUMBER(SEARCH("TIME OUT", F2)), ISNUMBER(SEARCH("ERROR", F2))), "QE", IF(OR(ISNUMBER(SEARCH("TIME OUT", K2)), ISNUMBER(SEARCH("ERROR", K2))), "RC", IF(V2=0, "TIE", IF(V2>0, "QE", "RC"))))) -> TIE | X2: =IF(V2="--","--",TEXT(MIN(F2,K2)/MAX(F2,K2),"0.000%")) -> #DIV/0! | Z2: =AVERAGE(C:C) -> #DIV/0! | AA2: =AVERAGE(D:D) -> #DIV/0! | AB2: =AVERAGE(E:E) -> #DIV/0! | AC2: =AVERAGE(F:F) -> #DIV/0! | AD2: =AVERAGE(H:H) -> #DIV/0! | AE2: =AVERAGE(I:I) -> #DIV/0! | AF2: =AVERAGE(J:J) -> #DIV/0! | AG2: =AVERAGE(K:K) -> #DIV/0! | AH2: =AVERAGE(M2) -> 0 | AI2: =AVERAGE(P2) -> 0 | AJ2: =AVERAGE(S2) -> 0 | AK2: =AVERAGE(V2) -> 0
AA6: memory | AC6: cputime | AE6: realtime | AG6: cells | AJ6: Successes | AL6: Timeouts | AN6: Errors | AP6: Total
Z7: RC | AA7: =COUNTIF(N:N,$Z7) -> 0 | AB7: =AA7/AA$11 -> 0 | AC7: =COUNTIF(Q:Q,$Z7) -> 0 | AD7: =AC7/AC$11 -> 0 | AE7: =COUNTIF(T:T,$Z7) -> 0 | AF7: =AE7/AE$11 -> 0 | AG7: =COUNTIF(W:W,$Z7) -> 0 | AH7: =AG7/AG$11 -> 0 | AJ7: =COUNTA(B2:B68)-COUNTIF(B2:B68,"*TIME OUT*")-COUNTIF(B2:B68,"*ERROR*") -> 0 | AK7: =AJ7/67 -> 0 | AL7: =COUNTIF(B2:B68,"*TIME OUT*") -> 0 | AM7: =AL7/67 -> 0 | AN7: =COUNTIF(B2:B68,"*ERROR*") -> 0 | AO7: =AN7/67 -> 0 | AP7: =AJ7+AL7+AN7 -> 0 | AQ7: =AK7+AM7+AO7 -> 0
Z8: QE | AA8: =COUNTIF(N:N,$Z8) -> 0 | AB8: =AA8/AA$11 -> 0 | AC8: =COUNTIF(Q:Q,$Z8) -> 0 | AD8: =AC8/AC$11 -> 0 | AE8: =COUNTIF(T:T,$Z8) -> 0 | AF8: =AE8/AE$11 -> 0 | AG8: =COUNTIF(W:W,$Z8) -> 0 | AH8: =AG8/AG$11 -> 0 | AJ8: =COUNTA(G2:G68)-COUNTIF(G2:G68,"*TIME OUT*")-COUNTIF(G2:G68,"*ERROR*") -> 0 | AK8: =AJ8/67 -> 0 | AL8: =COUNTIF(G2:G68,"*TIME OUT*") -> 0 | AM8: =AL8/67 -> 0 | AN8: =COUNTIF(G2:G68,"*ERROR*") -> 0 | AO8: =AN8/67 -> 0 | AP8: =AJ8+AL8+AN8 -> 0 | AQ8: =AK8+AM8+AO8 -> 0
Z9: TIE | AA9: =COUNTIF(N:N,$Z9) -> 1 | AB9: =AA9/AA$11 -> 1 | AC9: =COUNTIF(Q:Q,$Z9) -> 1 | AD9: =AC9/AC$11 -> 1 | AE9: =COUNTIF(T:T,$Z9) -> 1 | AF9: =AE9/AE$11 -> 1 | AG9: =COUNTIF(W:W,$Z9) -> 1 | AH9: =AG9/AG$11 -> 1
Z10: -- | AA10: =COUNTIF(N:N,$Z10) -> 0 | AB10: =AA10/AA$11 -> 0 | AC10: =COUNTIF(Q:Q,$Z10) -> 0 | AD10: =AC10/AC$11 -> 0 | AE10: =COUNTIF(T:T,$Z10) -> 0 | AF10: =AE10/AE$11 -> 0 | AG10: =COUNTIF(W:W,$Z10) -> 0 | AH10: =AG10/AG$11 -> 0
Z11: total | AA11: =COUNTA(N:N)-1 -> 1 | AB11: =AA11/AA$11 -> 1 | AC11: =COUNTA(O:O)-1 -> 1 | AD11: =AC11/AC$11 -> 1 | AE11: =COUNTA(P:P)-1 -> 1 | AF11: =AE11/AE$11 -> 1 | AG11: =COUNTA(Q:Q)-1 -> 1 | AH11: =AG11/AG$11 -> 1
AA13: memory | AC13: cputime | AE13: realtime | AG13: cells
Z14: RC | AA14: =COUNTIF(N:N,$Z7)-COUNTIFS(N:N,$Z7,O:O,"--") -> 0 | AB14: =AA14/AA$11 -> 0 | AC14: =COUNTIF(Q:Q,$Z7)-COUNTIFS(Q:Q,$Z7,R:R,"--") -> 0 | AD14: =AC14/AC$11 -> 0 | AE14: =COUNTIF(T:T,$Z7)-COUNTIFS(T:T,$Z7,U:U,"--") -> 0 | AF14: =AE14/AE$11 -> 0 | AG14: =COUNTIF(W:W,$Z7)-COUNTIFS(W:W,$Z7,X:X,"--") -> 0 | AH14: =AG14/AG$11 -> 0
Z15: QE | AA15: =COUNTIF(N:N,$Z8)-COUNTIFS(N:N,$Z8,O:O,"--") -> 0 | AB15: =AA15/AA$11 -> 0 | AC15: =COUNTIF(Q:Q,$Z8)-COUNTIFS(Q:Q,$Z8,R:R,"--") -> 0 | AD15: =AC15/AC$11 -> 0 | AE15: =COUNTIF(T:T,$Z8)-COUNTIFS(T:T,$Z8,U:U,"--") -> 0 | AF15: =AE15/AE$11 -> 0 | AG15: =COUNTIF(W:W,$Z8)-COUNTIFS(W:W,$Z8,X:X,"--") -> 0 | AH15: =AG15/AG$11 -> 0
Z16: TIE | AA16: =COUNTIF(N:N,$Z9)-COUNTIFS(N:N,$Z9,O:O,"--") -> 1 | AB16: =AA16/AA$11 -> 1 | AC16: =COUNTIF(Q:Q,$Z9)-COUNTIFS(Q:Q,$Z9,R:R,"--") -> 1 | AD16: =AC16/AC$11 -> 1 | AE16: =COUNTIF(T:T,$Z9)-COUNTIFS(T:T,$Z9,U:U,"--") -> 1 | AF16: =AE16/AE$11 -> 1 | AG16: =COUNTIF(W:W,$Z9)-COUNTIFS(W:W,$Z9,X:X,"--") -> 1 | AH16: =AG16/AG$11 -> 1
Z17: -- | AA17: =COUNTIF(O:O,"--") -> 0 | AB17: =AA17/AA$11 -> 0 | AC17: =COUNTIF(R:R,"--") -> 0 | AD17: =AC17/AC$11 -> 0 | AE17: =COUNTIF(U:U,"--") -> 0 | AF17: =AE17/AE$11 -> 0 | AG17: =COUNTIF(X:X,"--") -> 0 | AH17: =AG17/AG$11 -> 0
Z18: total | AA18: =COUNTA(N:N)-1 -> 1 | AB18: =AA18/AA$11 -> 1 | AC18: =COUNTA(O:O)-1 -> 1 | AD18: =AC18/AC$11 -> 1 | AE18: =COUNTA(P:P)-1 -> 1 | AF18: =AE18/AE$11 -> 1 | AG18: =COUNTA(Q:Q)-1 -> 1 | AH18: =AG18/AG$11 -> 1
AD19: =COUNTIF(W:W,$Z8)-COUNTIFS(W:W,$Z8,V:V,"--") -> 0
Z25: Success Rate
Z26: =Z7&": "&AJ7&" "&AJ6&" ("&TEXT(AK7,"0.00%")&"), "&AL7&" "&AL6&" ("&TEXT(AM7,"0.00%")&"), "&AN7&" "&AN6&" ("&TEXT(AO7,"0.00%")&")." -> RC: 0 Successes (0.00%), 0 Timeouts (0.00%), 0 Errors (0.00%).
Z27: =Z8&": "&AJ8&" "&AJ6&" ("&TEXT(AK8,"0.00%")&"), "&AL8&" "&AL6&" ("&TEXT(AM8,"0.00%")&"), "&AN8&" "&AN6&" ("&TEXT(AO8,"0.00%")&")." -> QE: 0 Successes (0.00%), 0 Timeouts (0.00%), 0 Errors (0.00%).
Z29: No. times faster (cputime)
Z30: =Z7&": "&AC7&" ("&TEXT(AD7,"0.00%")&"), "&AC14&" actual ("&TEXT(AD14,"0.00%")&")" -> RC: 0 (0.00%), 0 actual (0.00%)
Z31: =Z8&": "&AC8&" ("&TEXT(AD8,"0.00%")&"), "&AC15&" actual ("&TEXT(AD15,"0.00%")&")" -> QE: 0 (0.00%), 0 actual (0.00%)
Z33: No. times fewer cells
Z34: =Z7&": "&AG7&" ("&TEXT(AH7,"0.00%")&"), "&AG14&" actual ("&TEXT(AH14,"0.00%")&")" -> RC: 0 (0.00%), 0 actual (0.00%)
Z35: =Z8&": "&AG8&" ("&TEXT(AH8,"0.00%")&"), "&AG15&" actual ("&TEXT(AH15,"0.00%")&")" -> QE: 0 (0.00%), 0 actual (0.00%)

Sheet 1
A1: File | B1: rc_ordering | C1: rc_memory | D1: rc_cputime | E1: rc_realtime | F1: rc_cells | G1: qe_ordering | H1: qe_memory | I1: qe_cputime | J1: qe_realtime | K1: qe_cells | L1: Ordering match | M1: memory diff | N1: win | O1: % of other | P1: cputime diff | Q1: win | R1: % of other | S1: realtime diff | T1: win | U1: % of other | V1: cells diff | W1: win | X1: % of other | Z1: rc_memory_avg | AA1: rc_cputime_avg | AB1: rc_realtime_avg | AC1: rc_cells_avg | AD1: qe_memory_avg | AE1: qe_cputime_avg | AF1: qe_realtime_avg | AG1: qe_cells_avg | AH1: =M1&"_avg" -> memory diff_avg | AI1: =P1&"_avg" -> cputime diff_avg | AJ1: =S1&"_avg" -> realtime diff_avg | AK1: =V1&"_avg" -> cells diff_avg
L2: =IF(OR(ISNUMBER(SEARCH("ERROR", B2)), ISNUMBER(SEARCH("ERROR", G2)), ISNUMBER(SEARCH("TIME OUT", B2)), ISNUMBER(SEARCH("TIME OUT", G2))), "--", B2=G2) -> TRUE | M2: =IF(OR(ISNUMBER(SEARCH("ERROR", C2)), ISNUMBER(SEARCH("ERROR", H2)), ISNUMBER(SEARCH("TIME OUT", C2)), ISNUMBER(SEARCH("TIME OUT", H2))),"--",C2-H2) -> 0 | N2: =IF(AND(OR(ISNUMBER(SEARCH("TIME OUT", C2)), ISNUMBER(SEARCH("ERROR", C2))), OR(ISNUMBER(SEARCH("TIME OUT", H2)), ISNUMBER(SEARCH("ERROR", H2)))), "--", IF(OR(ISNUMBER(SEARCH("TIME OUT", C2)), ISNUMBER(SEARCH("ERROR", C2))), "QE", IF(OR(ISNUMBER(SEARCH("TIME OUT", H2)), ISNUMBER(SEARCH("ERROR", H2))), "RC", IF(M2=0, "TIE", IF(M2>0, "QE", "RC"))))) -> TIE | O2: =IF(M2="--","--",TEXT(MIN(C2,H2)/MAX(C2,H2),"0.000%")) -> #DIV/0! | P2: =IF(OR(ISNUMBER(SEARCH("ERROR", D2)), ISNUMBER(SEARCH("ERROR", I2)), ISNUMBER(SEARCH("TIME OUT", D2)), ISNUMBER(SEARCH("TIME OUT", I2))),"--",D2-I2) -> 0 | Q2: =IF(AND(OR(ISNUMBER(SEARCH("TIME OUT", D2)), ISNUMBER(SEARCH("ERROR", D2))), OR(ISNUMBER(SEARCH("TIME OUT", I2)), ISNUMBER(SEARCH("ERROR", I2)))), "--", IF(OR(ISNUMBER(SEARCH("TIME OUT", D2)), ISNUMBER(SEARCH("ERROR", D2))), "QE", IF(OR(ISNUMBER(SEARCH("TIME OUT", I2)), ISNUMBER(SEARCH("ERROR", I2))), "RC", IF(P2=0, "TIE", IF(P2>0, "QE", "RC"))))) -> TIE | R2: =IF(P2="--","--",TEXT(MIN(D2,I2)/MAX(D2,I2),"0.000%")) -> #DIV/0! | S2: =IF(OR(ISNUMBER(SEARCH("ERROR", E2)), ISNUMBER(SEARCH("ERROR", J2)), ISNUMBER(SEARCH("TIME OUT", E2)), ISNUMBER(SEARCH("TIME OUT", J2))),"--",E2-J2) -> 0 | T2: =IF(AND(OR(ISNUMBER(SEARCH("TIME OUT", E2)), ISNUMBER(SEARCH("ERROR", E2))), OR(ISNUMBER(SEARCH("TIME OUT", J2)), ISNUMBER(SEARCH("ERROR", J2)))), "--", IF(OR(ISNUMBER(SEARCH("TIME OUT", E2)), ISNUMBER(SEARCH("ERROR", E2))), "QE", IF(OR(ISNUMBER(SEARCH("TIME OUT", J2)), ISNUMBER(SEARCH("ERROR", J2))), "RC", IF(S2=0, "TIE", IF(S2>0, "QE", "RC"))))) -> TIE | U2: =IF(S2="--","--",TEXT(MIN(E2,J2)/MAX(E2,J2),"0.000%")) -> #DIV/0! | V2: =IF(OR(ISNUMBER(SEARCH("ERROR", F2)), ISNUMBER(SEARCH("ERROR", K2)), ISNUMBER(SEARCH("TIME OUT", F2)), ISNUMBER(SEARCH("TIME OUT", K2))),"--",F2-K2) -> 0 | W2: =IF(AND(OR(ISNUMBER(SEARCH("TIME OUT", F2)), ISNUMBER(SEARCH("ERROR", F2))), OR(ISNUMBER(SEARCH("TIME OUT", K2)), ISNUMBER(SEARCH("ERROR", K2)))), "--", IF(OR(ISNUMBER(SEARCH("TIME OUT", F2)), ISNUMBER(SEARCH("ERROR", F2))), "QE", IF(OR(ISNUMBER(SEARCH("TIME OUT", K2)), ISNUMBER(SEARCH("ERROR", K2))), "RC", IF(V2=0, "TIE", IF(V2>0, "QE", "RC"))))) -> TIE | X2: =IF(V2="--","--",TEXT(MIN(F2,K2)/MAX(F2,K2),"0.000%")) -> #DIV/0! | Z2: =AVERAGE(C:C) -> #DIV/0! | AA2: =AVERAGE(D:D) -> #DIV/0! | AB2: =AVERAGE(E:E) -> #DIV/0! | AC2: =AVERAGE(F:F) -> #DIV/0! | AD2: =AVERAGE(H:H) -> #DIV/0! | AE2: =AVERAGE(I:I) -> #DIV/0! | AF2: =AVERAGE(J:J) -> #DIV/0! | AG2: =AVERAGE(K:K) -> #DIV/0! | AH2: =AVERAGE(M2) -> 0 | AI2: =AVERAGE(P2) -> 0 | AJ2: =AVERAGE(S2) -> 0 | AK2: =AVERAGE(V2) -> 0
AA6: memory | AC6: cputime | AE6: realtime | AG6: cells | AJ6: Successes | AL6: Timeouts | AN6: Errors | AP6: Total
Z7: RC | AA7: =COUNTIF(N:N,$Z7) -> 0 | AB7: =AA7/AA$11 -> 0 | AC7: =COUNTIF(Q:Q,$Z7) -> 0 | AD7: =AC7/AC$11 -> 0 | AE7: =COUNTIF(T:T,$Z7) -> 0 | AF7: =AE7/AE$11 -> 0 | AG7: =COUNTIF(W:W,$Z7) -> 0 | AH7: =AG7/AG$11 -> 0 | AJ7: =COUNTA(B2:B68)-COUNTIF(B2:B68,"*TIME OUT*")-COUNTIF(B2:B68,"*ERROR*") -> 0 | AK7: =AJ7/67 -> 0 | AL7: =COUNTIF(B2:B68,"*TIME OUT*") -> 0 | AM7: =AL7/67 -> 0 | AN7: =COUNTIF(B2:B68,"*ERROR*") -> 0 | AO7: =AN7/67 -> 0 | AP7: =AJ7+AL7+AN7 -> 0 | AQ7: =AK7+AM7+AO7 -> 0
Z8: QE | AA8: =COUNTIF(N:N,$Z8) -> 0 | AB8: =AA8/AA$11 -> 0 | AC8: =COUNTIF(Q:Q,$Z8) -> 0 | AD8: =AC8/AC$11 -> 0 | AE8: =COUNTIF(T:T,$Z8) -> 0 | AF8: =AE8/AE$11 -> 0 | AG8: =COUNTIF(W:W,$Z8) -> 0 | AH8: =AG8/AG$11 -> 0 | AJ8: =COUNTA(G2:G68)-COUNTIF(G2:G68,"*TIME OUT*")-COUNTIF(G2:G68,"*ERROR*") -> 0 | AK8: =AJ8/67 -> 0 | AL8: =COUNTIF(G2:G68,"*TIME OUT*") -> 0 | AM8: =AL8/67 -> 0 | AN8: =COUNTIF(G2:G68,"*ERROR*") -> 0 | AO8: =AN8/67 -> 0 | AP8: =AJ8+AL8+AN8 -> 0 | AQ8: =AK8+AM8+AO8 -> 0
Z9: TIE | AA9: =COUNTIF(N:N,$Z9) -> 1 | AB9: =AA9/AA$11 -> 1 | AC9: =COUNTIF(Q:Q,$Z9) -> 1 | AD9: =AC9/AC$11 -> 1 | AE9: =COUNTIF(T:T,$Z9) -> 1 | AF9: =AE9/AE$11 -> 1 | AG9: =COUNTIF(W:W,$Z9) -> 1 | AH9: =AG9/AG$11 -> 1
Z10: -- | AA10: =COUNTIF(N:N,$Z10) -> 0 | AB10: =AA10/AA$11 -> 0 | AC10: =COUNTIF(Q:Q,$Z10) -> 0 | AD10: =AC10/AC$11 -> 0 | AE10: =COUNTIF(T:T,$Z10) -> 0 | AF10: =AE10/AE$11 -> 0 | AG10: =COUNTIF(W:W,$Z10) -> 0 | AH10: =AG10/AG$11 -> 0
Z11: total | AA11: =COUNTA(N:N)-1 -> 1 | AB11: =AA11/AA$11 -> 1 | AC11: =COUNTA(O:O)-1 -> 1 | AD11: =AC11/AC$11 -> 1 | AE11: =COUNTA(P:P)-1 -> 1 | AF11: =AE11/AE$11 -> 1 | AG11: =COUNTA(Q:Q)-1 -> 1 | AH11: =AG11/AG$11 -> 1
AA13: memory | AC13: cputime | AE13: realtime | AG13: cells
Z14: RC | AA14: =COUNTIF(N:N,$Z7)-COUNTIFS(N:N,$Z7,O:O,"--") -> 0 | AB14: =AA14/AA$11 -> 0 | AC14: =COUNTIF(Q:Q,$Z7)-COUNTIFS(Q:Q,$Z7,R:R,"--") -> 0 | AD14: =AC14/AC$11 -> 0 | AE14: =COUNTIF(T:T,$Z7)-COUNTIFS(T:T,$Z7,U:U,"--") -> 0 | AF14: =AE14/AE$11 -> 0 | AG14: =COUNTIF(W:W,$Z7)-COUNTIFS(W:W,$Z7,X:X,"--") -> 0 | AH14: =AG14/AG$11 -> 0
Z15: QE | AA15: =COUNTIF(N:N,$Z8)-COUNTIFS(N:N,$Z8,O:O,"--") -> 0 | AB15: =AA15/AA$11 -> 0 | AC15: =COUNTIF(Q:Q,$Z8)-COUNTIFS(Q:Q,$Z8,R:R,"--") -> 0 | AD15: =AC15/AC$11 -> 0 | AE15: =COUNTIF(T:T,$Z8)-COUNTIFS(T:T,$Z8,U:U,"--") -> 0 | AF15: =AE15/AE$11 -> 0 | AG15: =COUNTIF(W:W,$Z8)-COUNTIFS(W:W,$Z8,X:X,"--") -> 0 | AH15: =AG15/AG$11 -> 0
Z16: TIE | AA16: =COUNTIF(N:N,$Z9)-COUNTIFS(N:N,$Z9,O:O,"--") -> 1 | AB16: =AA16/AA$11 -> 1 | AC16: =COUNTIF(Q:Q,$Z9)-COUNTIFS(Q:Q,$Z9,R:R,"--") -> 1 | AD16: =AC16/AC$11 -> 1 | AE16: =COUNTIF(T:T,$Z9)-COUNTIFS(T:T,$Z9,U:U,"--") -> 1 | AF16: =AE16/AE$11 -> 1 | AG16: =COUNTIF(W:W,$Z9)-COUNTIFS(W:W,$Z9,X:X,"--") -> 1 | AH16: =AG16/AG$11 -> 1
Z17: -- | AA17: =COUNTIF(O:O,"--") -> 0 | AB17: =AA17/AA$11 -> 0 | AC17: =COUNTIF(R:R,"--") -> 0 | AD17: =AC17/AC$11 -> 0 | AE17: =COUNTIF(U:U,"--") -> 0 | AF17: =AE17/AE$11 -> 0 | AG17: =COUNTIF(X:X,"--") -> 0 | AH17: =AG17/AG$11 -> 0
Z18: total | AA18: =COUNTA(N:N)-1 -> 1 | AB18: =AA18/AA$11 -> 1 | AC18: =COUNTA(O:O)-1 -> 1 | AD18: =AC18/AC$11 -> 1 | AE18: =COUNTA(P:P)-1 -> 1 | AF18: =AE18/AE$11 -> 1 | AG18: =COUNTA(Q:Q)-1 -> 1 | AH18: =AG18/AG$11 -> 1
AD19: =COUNTIF(W:W,$Z8)-COUNTIFS(W:W,$Z8,V:V,"--") -> 0
Z25: Success Rate
Z26: =Z7&": "&AJ7&" "&AJ6&" ("&TEXT(AK7,"0.00%")&"), "&AL7&" "&AL6&" ("&TEXT(AM7,"0.00%")&"), "&AN7&" "&AN6&" ("&TEXT(AO7,"0.00%")&")." -> RC: 0 Successes (0.00%), 0 Timeouts (0.00%), 0 Errors (0.00%).
Z27: =Z8&": "&AJ8&" "&AJ6&" ("&TEXT(AK8,"0.00%")&"), "&AL8&" "&AL6&" ("&TEXT(AM8,"0.00%")&"), "&AN8&" "&AN6&" ("&TEXT(AO8,"0.00%")&")." -> QE: 0 Successes (0.00%), 0 Timeouts (0.00%), 0 Errors (0.00%).
Z29: No. times faster (cputime)
Z30: =Z7&": "&AC7&" ("&TEXT(AD7,"0.00%")&"), "&AC14&" actual ("&TEXT(AD14,"0.00%")&")" -> RC: 0 (0.00%), 0 actual (0.00%)
Z31: =Z8&": "&AC8&" ("&TEXT(AD8,"0.00%")&"), "&AC15&" actual ("&TEXT(AD15,"0.00%")&")" -> QE: 0 (0.00%), 0 actual (0.00%)
Z33: No. times fewer cells
Z34: =Z7&": "&AG7&" ("&TEXT(AH7,"0.00%")&"), "&AG14&" actual ("&TEXT(AH14,"0.00%")&")" -> RC: 0 (0.00%), 0 actual (0.00%)
Z35: =Z8&": "&AG8&" ("&TEXT(AH8,"0.00%")&"), "&AG15&" actual ("&TEXT(AH15,"0.00%")&")" -> QE: 0 (0.00%), 0 actual (0.00%)

Sheet 2
A1: File | B1: rc_ordering | C1: rc_memory | D1: rc_cputime | E1: rc_realtime | F1: rc_cells | G1: qe_ordering | H1: qe_memory | I1: qe_cputime | J1: qe_realtime | K1: qe_cells | L1: Ordering match | M1: memory diff | N1: win | O1: % of other | P1: cputime diff | Q1: win | R1: % of other | S1: realtime diff | T1: win | U1: % of other | V1: cells diff | W1: win | X1: % of other | Z1: rc_memory_avg | AA1: rc_cputime_avg | AB1: rc_realtime_avg | AC1: rc_cells_avg | AD1: qe_memory_avg | AE1: qe_cputime_avg | AF1: qe_realtime_avg | AG1: qe_cells_avg | AH1: =M1&"_avg" -> memory diff_avg | AI1: =P1&"_avg" -> cputime diff_avg | AJ1: =S1&"_avg" -> realtime diff_avg | AK1: =V1&"_avg" -> cells diff_avg
L2: =IF(OR(ISNUMBER(SEARCH("ERROR", B2)), ISNUMBER(SEARCH("ERROR", G2)), ISNUMBER(SEARCH("TIME OUT", B2)), ISNUMBER(SEARCH("TIME OUT", G2))), "--", B2=G2) -> TRUE | M2: =IF(OR(ISNUMBER(SEARCH("ERROR", C2)), ISNUMBER(SEARCH("ERROR", H2)), ISNUMBER(SEARCH("TIME OUT", C2)), ISNUMBER(SEARCH("TIME OUT", H2))),"--",C2-H2) -> 0 | N2: =IF(AND(OR(ISNUMBER(SEARCH("TIME OUT", C2)), ISNUMBER(SEARCH("ERROR", C2))), OR(ISNUMBER(SEARCH("TIME OUT", H2)), ISNUMBER(SEARCH("ERROR", H2)))), "--", IF(OR(ISNUMBER(SEARCH("TIME OUT", C2)), ISNUMBER(SEARCH("ERROR", C2))), "QE", IF(OR(ISNUMBER(SEARCH("TIME OUT", H2)), ISNUMBER(SEARCH("ERROR", H2))), "RC", IF(M2=0, "TIE", IF(M2>0, "QE", "RC"))))) -> TIE | O2: =IF(M2="--","--",TEXT(MIN(C2,H2)/MAX(C2,H2),"0.000%")) -> #DIV/0! | P2: =IF(OR(ISNUMBER(SEARCH("ERROR", D2)), ISNUMBER(SEARCH("ERROR", I2)), ISNUMBER(SEARCH("TIME OUT", D2)), ISNUMBER(SEARCH("TIME OUT", I2))),"--",D2-I2) -> 0 | Q2: =IF(AND(OR(ISNUMBER(SEARCH("TIME OUT", D2)), ISNUMBER(SEARCH("ERROR", D2))), OR(ISNUMBER(SEARCH("TIME OUT", I2)), ISNUMBER(SEARCH("ERROR", I2)))), "--", IF(OR(ISNUMBER(SEARCH("TIME OUT", D2)), ISNUMBER(SEARCH("ERROR", D2))), "QE", IF(OR(ISNUMBER(SEARCH("TIME OUT", I2)), ISNUMBER(SEARCH("ERROR", I2))), "RC", IF(P2=0, "TIE", IF(P2>0, "QE", "RC"))))) -> TIE | R2: =IF(P2="--","--",TEXT(MIN(D2,I2)/MAX(D2,I2),"0.000%")) -> #DIV/0! | S2: =IF(OR(ISNUMBER(SEARCH("ERROR", E2)), ISNUMBER(SEARCH("ERROR", J2)), ISNUMBER(SEARCH("TIME OUT", E2)), ISNUMBER(SEARCH("TIME OUT", J2))),"--",E2-J2) -> 0 | T2: =IF(AND(OR(ISNUMBER(SEARCH("TIME OUT", E2)), ISNUMBER(SEARCH("ERROR", E2))), OR(ISNUMBER(SEARCH("TIME OUT", J2)), ISNUMBER(SEARCH("ERROR", J2)))), "--", IF(OR(ISNUMBER(SEARCH("TIME OUT", E2)), ISNUMBER(SEARCH("ERROR", E2))), "QE", IF(OR(ISNUMBER(SEARCH("TIME OUT", J2)), ISNUMBER(SEARCH("ERROR", J2))), "RC", IF(S2=0, "TIE", IF(S2>0, "QE", "RC"))))) -> TIE | U2: =IF(S2="--","--",TEXT(MIN(E2,J2)/MAX(E2,J2),"0.000%")) -> #DIV/0! | V2: =IF(OR(ISNUMBER(SEARCH("ERROR", F2)), ISNUMBER(SEARCH("ERROR", K2)), ISNUMBER(SEARCH("TIME OUT", F2)), ISNUMBER(SEARCH("TIME OUT", K2))),"--",F2-K2) -> 0 | W2: =IF(AND(OR(ISNUMBER(SEARCH("TIME OUT", F2)), ISNUMBER(SEARCH("ERROR", F2))), OR(ISNUMBER(SEARCH("TIME OUT", K2)), ISNUMBER(SEARCH("ERROR", K2)))), "--", IF(OR(ISNUMBER(SEARCH("TIME OUT", F2)), ISNUMBER(SEARCH("ERROR", F2))), "QE", IF(OR(ISNUMBER(SEARCH("TIME OUT", K2)), ISNUMBER(SEARCH("ERROR", K2))), "RC", IF(V2=0, "TIE", IF(V2>0, "QE", "RC"))))) -> TIE | X2: =IF(V2="--","--",TEXT(MIN(F2,K2)/MAX(F2,K2),"0.000%")) -> #DIV/0! | Z2: =AVERAGE(C:C) -> #DIV/0! | AA2: =AVERAGE(D:D) -> #DIV/0! | AB2: =AVERAGE(E:E) -> #DIV/0! | AC2: =AVERAGE(F:F) -> #DIV/0! | AD2: =AVERAGE(H:H) -> #DIV/0! | AE2: =AVERAGE(I:I) -> #DIV/0! | AF2: =AVERAGE(J:J) -> #DIV/0! | AG2: =AVERAGE(K:K) -> #DIV/0! | AH2: =AVERAGE(M2) -> 0 | AI2: =AVERAGE(P2) -> 0 | AJ2: =AVERAGE(S2) -> 0 | AK2: =AVERAGE(V2) -> 0
AA6: memory | AC6: cputime | AE6: realtime | AG6: cells | AJ6: Successes | AL6: Timeouts | AN6: Errors | AP6: Total
Z7: RC | AA7: =COUNTIF(N:N,$Z7) -> 0 | AB7: =AA7/AA$11 -> 0 | AC7: =COUNTIF(Q:Q,$Z7) -> 0 | AD7: =AC7/AC$11 -> 0 | AE7: =COUNTIF(T:T,$Z7) -> 0 | AF7: =AE7/AE$11 -> 0 | AG7: =COUNTIF(W:W,$Z7) -> 0 | AH7: =AG7/AG$11 -> 0 | AJ7: =COUNTA(B2:B68)-COUNTIF(B2:B68,"*TIME OUT*")-COUNTIF(B2:B68,"*ERROR*") -> 0 | AK7: =AJ7/67 -> 0 | AL7: =COUNTIF(B2:B68,"*TIME OUT*") -> 0 | AM7: =AL7/67 -> 0 | AN7: =COUNTIF(B2:B68,"*ERROR*") -> 0 | AO7: =AN7/67 -> 0 | AP7: =AJ7+AL7+AN7 -> 0 | AQ7: =AK7+AM7+AO7 -> 0
Z8: QE | AA8: =COUNTIF(N:N,$Z8) -> 0 | AB8: =AA8/AA$11 -> 0 | AC8: =COUNTIF(Q:Q,$Z8) -> 0 | AD8: =AC8/AC$11 -> 0 | AE8: =COUNTIF(T:T,$Z8) -> 0 | AF8: =AE8/AE$11 -> 0 | AG8: =COUNTIF(W:W,$Z8) -> 0 | AH8: =AG8/AG$11 -> 0 | AJ8: =COUNTA(G2:G68)-COUNTIF(G2:G68,"*TIME OUT*")-COUNTIF(G2:G68,"*ERROR*") -> 0 | AK8: =AJ8/67 -> 0 | AL8: =COUNTIF(G2:G68,"*TIME OUT*") -> 0 | AM8: =AL8/67 -> 0 | AN8: =COUNTIF(G2:G68,"*ERROR*") -> 0 | AO8: =AN8/67 -> 0 | AP8: =AJ8+AL8+AN8 -> 0 | AQ8: =AK8+AM8+AO8 -> 0
Z9: TIE | AA9: =COUNTIF(N:N,$Z9) -> 1 | AB9: =AA9/AA$11 -> 1 | AC9: =COUNTIF(Q:Q,$Z9) -> 1 | AD9: =AC9/AC$11 -> 1 | AE9: =COUNTIF(T:T,$Z9) -> 1 | AF9: =AE9/AE$11 -> 1 | AG9: =COUNTIF(W:W,$Z9) -> 1 | AH9: =AG9/AG$11 -> 1
Z10: -- | AA10: =COUNTIF(N:N,$Z10) -> 0 | AB10: =AA10/AA$11 -> 0 | AC10: =COUNTIF(Q:Q,$Z10) -> 0 | AD10: =AC10/AC$11 -> 0 | AE10: =COUNTIF(T:T,$Z10) -> 0 | AF10: =AE10/AE$11 -> 0 | AG10: =COUNTIF(W:W,$Z10) -> 0 | AH10: =AG10/AG$11 -> 0
Z11: total | AA11: =COUNTA(N:N)-1 -> 1 | AB11: =AA11/AA$11 -> 1 | AC11: =COUNTA(O:O)-1 -> 1 | AD11: =AC11/AC$11 -> 1 | AE11: =COUNTA(P:P)-1 -> 1 | AF11: =AE11/AE$11 -> 1 | AG11: =COUNTA(Q:Q)-1 -> 1 | AH11: =AG11/AG$11 -> 1
AA13: memory | AC13: cputime | AE13: realtime | AG13: cells
Z14: RC | AA14: =COUNTIF(N:N,$Z7)-COUNTIFS(N:N,$Z7,O:O,"--") -> 0 | AB14: =AA14/AA$11 -> 0 | AC14: =COUNTIF(Q:Q,$Z7)-COUNTIFS(Q:Q,$Z7,R:R,"--") -> 0 | AD14: =AC14/AC$11 -> 0 | AE14: =COUNTIF(T:T,$Z7)-COUNTIFS(T:T,$Z7,U:U,"--") -> 0 | AF14: =AE14/AE$11 -> 0 | AG14: =COUNTIF(W:W,$Z7)-COUNTIFS(W:W,$Z7,X:X,"--") -> 0 | AH14: =AG14/AG$11 -> 0
Z15: QE | AA15: =COUNTIF(N:N,$Z8)-COUNTIFS(N:N,$Z8,O:O,"--") -> 0 | AB15: =AA15/AA$11 -> 0 | AC15: =COUNTIF(Q:Q,$Z8)-COUNTIFS(Q:Q,$Z8,R:R,"--") -> 0 | AD15: =AC15/AC$11 -> 0 | AE15: =COUNTIF(T:T,$Z8)-COUNTIFS(T:T,$Z8,U:U,"--") -> 0 | AF15: =AE15/AE$11 -> 0 | AG15: =COUNTIF(W:W,$Z8)-COUNTIFS(W:W,$Z8,X:X,"--") -> 0 | AH15: =AG15/AG$11 -> 0
Z16: TIE | AA16: =COUNTIF(N:N,$Z9)-COUNTIFS(N:N,$Z9,O:O,"--") -> 1 | AB16: =AA16/AA$11 -> 1 | AC16: =COUNTIF(Q:Q,$Z9)-COUNTIFS(Q:Q,$Z9,R:R,"--") -> 1 | AD16: =AC16/AC$11 -> 1 | AE16: =COUNTIF(T:T,$Z9)-COUNTIFS(T:T,$Z9,U:U,"--") -> 1 | AF16: =AE16/AE$11 -> 1 | AG16: =COUNTIF(W:W,$Z9)-COUNTIFS(W:W,$Z9,X:X,"--") -> 1 | AH16: =AG16/AG$11 -> 1
Z17: -- | AA17: =COUNTIF(O:O,"--") -> 0 | AB17: =AA17/AA$11 -> 0 | AC17: =COUNTIF(R:R,"--") -> 0 | AD17: =AC17/AC$11 -> 0 | AE17: =COUNTIF(U:U,"--") -> 0 | AF17: =AE17/AE$11 -> 0 | AG17: =COUNTIF(X:X,"--") -> 0 | AH17: =AG17/AG$11 -> 0
Z18: total | AA18: =COUNTA(N:N)-1 -> 1 | AB18: =AA18/AA$11 -> 1 | AC18: =COUNTA(O:O)-1 -> 1 | AD18: =AC18/AC$11 -> 1 | AE18: =COUNTA(P:P)-1 -> 1 | AF18: =AE18/AE$11 -> 1 | AG18: =COUNTA(Q:Q)-1 -> 1 | AH18: =AG18/AG$11 -> 1
AD19: =COUNTIF(W:W,$Z8)-COUNTIFS(W:W,$Z8,V:V,"--") -> 0
Z25: Success Rate
Z26: =Z7&": "&AJ7&" "&AJ6&" ("&TEXT(AK7,"0.00%")&"), "&AL7&" "&AL6&" ("&TEXT(AM7,"0.00%")&"), "&AN7&" "&AN6&" ("&TEXT(AO7,"0.00%")&")." -> RC: 0 Successes (0.00%), 0 Timeouts (0.00%), 0 Errors (0.00%).
Z27: =Z8&": "&AJ8&" "&AJ6&" ("&TEXT(AK8,"0.00%")&"), "&AL8&" "&AL6&" ("&TEXT(AM8,"0.00%")&"), "&AN8&" "&AN6&" ("&TEXT(AO8,"0.00%")&")." -> QE: 0 Successes (0.00%), 0 Timeouts (0.00%), 0 Errors (0.00%).
Z29: No. times faster (cputime)
Z30: =Z7&": "&AC7&" ("&TEXT(AD7,"0.00%")&"), "&AC14&" actual ("&TEXT(AD14,"0.00%")&")" -> RC: 0 (0.00%), 0 actual (0.00%)
Z31: =Z8&": "&AC8&" ("&TEXT(AD8,"0.00%")&"), "&AC15&" actual ("&TEXT(AD15,"0.00%")&")" -> QE: 0 (0.00%), 0 actual (0.00%)
Z33: No. times fewer cells
Z34: =Z7&": "&AG7&" ("&TEXT(AH7,"0.00%")&"), "&AG14&" actual ("&TEXT(AH14,"0.00%")&")" -> RC: 0 (0.00%), 0 actual (0.00%)
Z35: =Z8&": "&AG8&" ("&TEXT(AH8,"0.00%")&"), "&AG15&" actual ("&TEXT(AH15,"0.00%")&")" -> QE: 0 (0.00%), 0 actual (0.00%)

Sheet 3
A1: File | B1: rc_ordering | C1: rc_memory | D1: rc_cputime | E1: rc_realtime | F1: rc_cells | G1: qe_ordering | H1: qe_memory | I1: qe_cputime | J1: qe_realtime | K1: qe_cells | L1: Ordering match | M1: memory diff | N1: win | O1: % of other | P1: cputime diff | Q1: win | R1: % of other | S1: realtime diff | T1: win | U1: % of other | V1: cells diff | W1: win | X1: % of other | Z1: rc_memory_avg | AA1: rc_cputime_avg | AB1: rc_realtime_avg | AC1: rc_cells_avg | AD1: qe_memory_avg | AE1: qe_cputime_avg | AF1: qe_realtime_avg | AG1: qe_cells_avg | AH1: =M1&"_avg" -> memory diff_avg | AI1: =P1&"_avg" -> cputime diff_avg | AJ1: =S1&"_avg" -> realtime diff_avg | AK1: =V1&"_avg" -> cells diff_avg
L2: =IF(OR(ISNUMBER(SEARCH("ERROR", B2)), ISNUMBER(SEARCH("ERROR", G2)), ISNUMBER(SEARCH("TIME OUT", B2)), ISNUMBER(SEARCH("TIME OUT", G2))), "--", B2=G2) -> TRUE | M2: =IF(OR(ISNUMBER(SEARCH("ERROR", C2)), ISNUMBER(SEARCH("ERROR", H2)), ISNUMBER(SEARCH("TIME OUT", C2)), ISNUMBER(SEARCH("TIME OUT", H2))),"--",C2-H2) -> 0 | N2: =IF(AND(OR(ISNUMBER(SEARCH("TIME OUT", C2)), ISNUMBER(SEARCH("ERROR", C2))), OR(ISNUMBER(SEARCH("TIME OUT", H2)), ISNUMBER(SEARCH("ERROR", H2)))), "--", IF(OR(ISNUMBER(SEARCH("TIME OUT", C2)), ISNUMBER(SEARCH("ERROR", C2))), "QE", IF(OR(ISNUMBER(SEARCH("TIME OUT", H2)), ISNUMBER(SEARCH("ERROR", H2))), "RC", IF(M2=0, "TIE", IF(M2>0, "QE", "RC"))))) -> TIE | O2: =IF(M2="--","--",TEXT(MIN(C2,H2)/MAX(C2,H2),"0.000%")) -> #DIV/0! | P2: =IF(OR(ISNUMBER(SEARCH("ERROR", D2)), ISNUMBER(SEARCH("ERROR", I2)), ISNUMBER(SEARCH("TIME OUT", D2)), ISNUMBER(SEARCH("TIME OUT", I2))),"--",D2-I2) -> 0 | Q2: =IF(AND(OR(ISNUMBER(SEARCH("TIME OUT", D2)), ISNUMBER(SEARCH("ERROR", D2))), OR(ISNUMBER(SEARCH("TIME OUT", I2)), ISNUMBER(SEARCH("ERROR", I2)))), "--", IF(OR(ISNUMBER(SEARCH("TIME OUT", D2)), ISNUMBER(SEARCH("ERROR", D2))), "QE", IF(OR(ISNUMBER(SEARCH("TIME OUT", I2)), ISNUMBER(SEARCH("ERROR", I2))), "RC", IF(P2=0, "TIE", IF(P2>0, "QE", "RC"))))) -> TIE | R2: =IF(P2="--","--",TEXT(MIN(D2,I2)/MAX(D2,I2),"0.000%")) -> #DIV/0! | S2: =IF(OR(ISNUMBER(SEARCH("ERROR", E2)), ISNUMBER(SEARCH("ERROR", J2)), ISNUMBER(SEARCH("TIME OUT", E2)), ISNUMBER(SEARCH("TIME OUT", J2))),"--",E2-J2) -> 0 | T2: =IF(AND(OR(ISNUMBER(SEARCH("TIME OUT", E2)), ISNUMBER(SEARCH("ERROR", E2))), OR(ISNUMBER(SEARCH("TIME OUT", J2)), ISNUMBER(SEARCH("ERROR", J2)))), "--", IF(OR(ISNUMBER(SEARCH("TIME OUT", E2)), ISNUMBER(SEARCH("ERROR", E2))), "QE", IF(OR(ISNUMBER(SEARCH("TIME OUT", J2)), ISNUMBER(SEARCH("ERROR", J2))), "RC", IF(S2=0, "TIE", IF(S2>0, "QE", "RC"))))) -> TIE | U2: =IF(S2="--","--",TEXT(MIN(E2,J2)/MAX(E2,J2),"0.000%")) -> #DIV/0! | V2: =IF(OR(ISNUMBER(SEARCH("ERROR", F2)), ISNUMBER(SEARCH("ERROR", K2)), ISNUMBER(SEARCH("TIME OUT", F2)), ISNUMBER(SEARCH("TIME OUT", K2))),"--",F2-K2) -> 0 | W2: =IF(AND(OR(ISNUMBER(SEARCH("TIME OUT", F2)), ISNUMBER(SEARCH("ERROR", F2))), OR(ISNUMBER(SEARCH("TIME OUT", K2)), ISNUMBER(SEARCH("ERROR", K2)))), "--", IF(OR(ISNUMBER(SEARCH("TIME OUT", F2)), ISNUMBER(SEARCH("ERROR", F2))), "QE", IF(OR(ISNUMBER(SEARCH("TIME OUT", K2)), ISNUMBER(SEARCH("ERROR", K2))), "RC", IF(V2=0, "TIE", IF(V2>0, "QE", "RC"))))) -> TIE | X2: =IF(V2="--","--",TEXT(MIN(F2,K2)/MAX(F2,K2),"0.000%")) -> #DIV/0! | Z2: =AVERAGE(C:C) -> #DIV/0! | AA2: =AVERAGE(D:D) -> #DIV/0! | AB2: =AVERAGE(E:E) -> #DIV/0! | AC2: =AVERAGE(F:F) -> #DIV/0! | AD2: =AVERAGE(H:H) -> #DIV/0! | AE2: =AVERAGE(I:I) -> #DIV/0! | AF2: =AVERAGE(J:J) -> #DIV/0! | AG2: =AVERAGE(K:K) -> #DIV/0! | AH2: =AVERAGE(M2) -> 0 | AI2: =AVERAGE(P2) -> 0 | AJ2: =AVERAGE(S2) -> 0 | AK2: =AVERAGE(V2) -> 0
AA6: memory | AC6: cputime | AE6: realtime | AG6: cells | AJ6: Successes | AL6: Timeouts | AN6: Errors | AP6: Total
Z7: RC | AA7: =COUNTIF(N:N,$Z7) -> 0 | AB7: =AA7/AA$11 -> 0 | AC7: =COUNTIF(Q:Q,$Z7) -> 0 | AD7: =AC7/AC$11 -> 0 | AE7: =COUNTIF(T:T,$Z7) -> 0 | AF7: =AE7/AE$11 -> 0 | AG7: =COUNTIF(W:W,$Z7) -> 0 | AH7: =AG7/AG$11 -> 0 | AJ7: =COUNTA(B2:B68)-COUNTIF(B2:B68,"*TIME OUT*")-COUNTIF(B2:B68,"*ERROR*") -> 0 | AK7: =AJ7/67 -> 0 | AL7: =COUNTIF(B2:B68,"*TIME OUT*") -> 0 | AM7: =AL7/67 -> 0 | AN7: =COUNTIF(B2:B68,"*ERROR*") -> 0 | AO7: =AN7/67 -> 0 | AP7: =AJ7+AL7+AN7 -> 0 | AQ7: =AK7+AM7+AO7 -> 0
Z8: QE | AA8: =COUNTIF(N:N,$Z8) -> 0 | AB8: =AA8/AA$11 -> 0 | AC8: =COUNTIF(Q:Q,$Z8) -> 0 | AD8: =AC8/AC$11 -> 0 | AE8: =COUNTIF(T:T,$Z8) -> 0 | AF8: =AE8/AE$11 -> 0 | AG8: =COUNTIF(W:W,$Z8) -> 0 | AH8: =AG8/AG$11 -> 0 | AJ8: =COUNTA(G2:G68)-COUNTIF(G2:G68,"*TIME OUT*")-COUNTIF(G2:G68,"*ERROR*") -> 0 | AK8: =AJ8/67 -> 0 | AL8: =COUNTIF(G2:G68,"*TIME OUT*") -> 0 | AM8: =AL8/67 -> 0 | AN8: =COUNTIF(G2:G68,"*ERROR*") -> 0 | AO8: =AN8/67 -> 0 | AP8: =AJ8+AL8+AN8 -> 0 | AQ8: =AK8+AM8+AO8 -> 0
Z9: TIE | AA9: =COUNTIF(N:N,$Z9) -> 1 | AB9: =AA9/AA$11 -> 1 | AC9: =COUNTIF(Q:Q,$Z9) -> 1 | AD9: =AC9/AC$11 -> 1 | AE9: =COUNTIF(T:T,$Z9) -> 1 | AF9: =AE9/AE$11 -> 1 | AG9: =COUNTIF(W:W,$Z9) -> 1 | AH9: =AG9/AG$11 -> 1
Z10: -- | AA10: =COUNTIF(N:N,$Z10) -> 0 | AB10: =AA10/AA$11 -> 0 | AC10: =COUNTIF(Q:Q,$Z10) -> 0 | AD10: =AC10/AC$11 -> 0 | AE10: =COUNTIF(T:T,$Z10) -> 0 | AF10: =AE10/AE$11 -> 0 | AG10: =COUNTIF(W:W,$Z10) -> 0 | AH10: =AG10/AG$11 -> 0
Z11: total | AA11: =COUNTA(N:N)-1 -> 1 | AB11: =AA11/AA$11 -> 1 | AC11: =COUNTA(O:O)-1 -> 1 | AD11: =AC11/AC$11 -> 1 | AE11: =COUNTA(P:P)-1 -> 1 | AF11: =AE11/AE$11 -> 1 | AG11: =COUNTA(Q:Q)-1 -> 1 | AH11: =AG11/AG$11 -> 1
AA13: memory | AC13: cputime | AE13: realtime | AG13: cells
Z14: RC | AA14: =COUNTIF(N:N,$Z7)-COUNTIFS(N:N,$Z7,O:O,"--") -> 0 | AB14: =AA14/AA$11 -> 0 | AC14: =COUNTIF(Q:Q,$Z7)-COUNTIFS(Q:Q,$Z7,R:R,"--") -> 0 | AD14: =AC14/AC$11 -> 0 | AE14: =COUNTIF(T:T,$Z7)-COUNTIFS(T:T,$Z7,U:U,"--") -> 0 | AF14: =AE14/AE$11 -> 0 | AG14: =COUNTIF(W:W,$Z7)-COUNTIFS(W:W,$Z7,X:X,"--") -> 0 | AH14: =AG14/AG$11 -> 0
Z15: QE | AA15: =COUNTIF(N:N,$Z8)-COUNTIFS(N:N,$Z8,O:O,"--") -> 0 | AB15: =AA15/AA$11 -> 0 | AC15: =COUNTIF(Q:Q,$Z8)-COUNTIFS(Q:Q,$Z8,R:R,"--") -> 0 | AD15: =AC15/AC$11 -> 0 | AE15: =COUNTIF(T:T,$Z8)-COUNTIFS(T:T,$Z8,U:U,"--") -> 0 | AF15: =AE15/AE$11 -> 0 | AG15: =COUNTIF(W:W,$Z8)-COUNTIFS(W:W,$Z8,X:X,"--") -> 0 | AH15: =AG15/AG$11 -> 0
Z16: TIE | AA16: =COUNTIF(N:N,$Z9)-COUNTIFS(N:N,$Z9,O:O,"--") -> 1 | AB16: =AA16/AA$11 -> 1 | AC16: =COUNTIF(Q:Q,$Z9)-COUNTIFS(Q:Q,$Z9,R:R,"--") -> 1 | AD16: =AC16/AC$11 -> 1 | AE16: =COUNTIF(T:T,$Z9)-COUNTIFS(T:T,$Z9,U:U,"--") -> 1 | AF16: =AE16/AE$11 -> 1 | AG16: =COUNTIF(W:W,$Z9)-COUNTIFS(W:W,$Z9,X:X,"--") -> 1 | AH16: =AG16/AG$11 -> 1
Z17: -- | AA17: =COUNTIF(O:O,"--") -> 0 | AB17: =AA17/AA$11 -> 0 | AC17: =COUNTIF(R:R,"--") -> 0 | AD17: =AC17/AC$11 -> 0 | AE17: =COUNTIF(U:U,"--") -> 0 | AF17: =AE17/AE$11 -> 0 | AG17: =COUNTIF(X:X,"--") -> 0 | AH17: =AG17/AG$11 -> 0
Z18: total | AA18: =COUNTA(N:N)-1 -> 1 | AB18: =AA18/AA$11 -> 1 | AC18: =COUNTA(O:O)-1 -> 1 | AD18: =AC18/AC$11 -> 1 | AE18: =COUNTA(P:P)-1 -> 1 | AF18: =AE18/AE$11 -> 1 | AG18: =COUNTA(Q:Q)-1 -> 1 | AH18: =AG18/AG$11 -> 1
AD19: =COUNTIF(W:W,$Z8)-COUNTIFS(W:W,$Z8,V:V,"--") -> 0
Z25: Success Rate
Z26: =Z7&": "&AJ7&" "&AJ6&" ("&TEXT(AK7,"0.00%")&"), "&AL7&" "&AL6&" ("&TEXT(AM7,"0.00%")&"), "&AN7&" "&AN6&" ("&TEXT(AO7,"0.00%")&")." -> RC: 0 Successes (0.00%), 0 Timeouts (0.00%), 0 Errors (0.00%).
Z27: =Z8&": "&AJ8&" "&AJ6&" ("&TEXT(AK8,"0.00%")&"), "&AL8&" "&AL6&" ("&TEXT(AM8,"0.00%")&"), "&AN8&" "&AN6&" ("&TEXT(AO8,"0.00%")&")." -> QE: 0 Successes (0.00%), 0 Timeouts (0.00%), 0 Errors (0.00%).
Z29: No. times faster (cputime)
Z30: =Z7&": "&AC7&" ("&TEXT(AD7,"0.00%")&"), "&AC14&" actual ("&TEXT(AD14,"0.00%")&")" -> RC: 0 (0.00%), 0 actual (0.00%)
Z31: =Z8&": "&AC8&" ("&TEXT(AD8,"0.00%")&"), "&AC15&" actual ("&TEXT(AD15,"0.00%")&")" -> QE: 0 (0.00%), 0 actual (0.00%)
Z33: No. times fewer cells
Z34: =Z7&": "&AG7&" ("&TEXT(AH7,"0.00%")&"), "&AG14&" actual ("&TEXT(AH14,"0.00%")&")" -> RC: 0 (0.00%), 0 actual (0.00%)
Z35: =Z8&": "&AG8&" ("&TEXT(AH8,"0.00%")&"), "&AG15&" actual ("&TEXT(AH15,"0.00%")&")" -> QE: 0 (0.00%), 0 actual (0.00%)

Sheet 4
A1: File | B1: rc_ordering | C1: rc_memory | D1: rc_cputime | E1: rc_realtime | F1: rc_cells | G1: qe_ordering | H1: qe_memory | I1: qe_cputime | J1: qe_realtime | K1: qe_cells | L1: Ordering match | M1: memory diff | N1: win | O1: % of other | P1: cputime diff | Q1: win | R1: % of other | S1: realtime diff | T1: win | U1: % of other | V1: cells diff | W1: win | X1: % of other | Z1: rc_memory_avg | AA1: rc_cputime_avg | AB1: rc_realtime_avg | AC1: rc_cells_avg | AD1: qe_memory_avg | AE1: qe_cputime_avg | AF1: qe_realtime_avg | AG1: qe_cells_avg | AH1: =M1&"_avg" -> memory diff_avg | AI1: =P1&"_avg" -> cputime diff_avg | AJ1: =S1&"_avg" -> realtime diff_avg | AK1: =V1&"_avg" -> cells diff_avg
L2: =IF(OR(ISNUMBER(SEARCH("ERROR", B2)), ISNUMBER(SEARCH("ERROR", G2)), ISNUMBER(SEARCH("TIME OUT", B2)), ISNUMBER(SEARCH("TIME OUT", G2))), "--", B2=G2) -> TRUE | M2: =IF(OR(ISNUMBER(SEARCH("ERROR", C2)), ISNUMBER(SEARCH("ERROR", H2)), ISNUMBER(SEARCH("TIME OUT", C2)), ISNUMBER(SEARCH("TIME OUT", H2))),"--",C2-H2) -> 0 | N2: =IF(AND(OR(ISNUMBER(SEARCH("TIME OUT", C2)), ISNUMBER(SEARCH("ERROR", C2))), OR(ISNUMBER(SEARCH("TIME OUT", H2)), ISNUMBER(SEARCH("ERROR", H2)))), "--", IF(OR(ISNUMBER(SEARCH("TIME OUT", C2)), ISNUMBER(SEARCH("ERROR", C2))), "QE", IF(OR(ISNUMBER(SEARCH("TIME OUT", H2)), ISNUMBER(SEARCH("ERROR", H2))), "RC", IF(M2=0, "TIE", IF(M2>0, "QE", "RC"))))) -> TIE | O2: =IF(M2="--","--",TEXT(MIN(C2,H2)/MAX(C2,H2),"0.000%")) -> #DIV/0! | P2: =IF(OR(ISNUMBER(SEARCH("ERROR", D2)), ISNUMBER(SEARCH("ERROR", I2)), ISNUMBER(SEARCH("TIME OUT", D2)), ISNUMBER(SEARCH("TIME OUT", I2))),"--",D2-I2) -> 0 | Q2: =IF(AND(OR(ISNUMBER(SEARCH("TIME OUT", D2)), ISNUMBER(SEARCH("ERROR", D2))), OR(ISNUMBER(SEARCH("TIME OUT", I2)), ISNUMBER(SEARCH("ERROR", I2)))), "--", IF(OR(ISNUMBER(SEARCH("TIME OUT", D2)), ISNUMBER(SEARCH("ERROR", D2))), "QE", IF(OR(ISNUMBER(SEARCH("TIME OUT", I2)), ISNUMBER(SEARCH("ERROR", I2))), "RC", IF(P2=0, "TIE", IF(P2>0, "QE", "RC"))))) -> TIE | R2: =IF(P2="--","--",TEXT(MIN(D2,I2)/MAX(D2,I2),"0.000%")) -> #DIV/0! | S2: =IF(OR(ISNUMBER(SEARCH("ERROR", E2)), ISNUMBER(SEARCH("ERROR", J2)), ISNUMBER(SEARCH("TIME OUT", E2)), ISNUMBER(SEARCH("TIME OUT", J2))),"--",E2-J2) -> 0 | T2: =IF(AND(OR(ISNUMBER(SEARCH("TIME OUT", E2)), ISNUMBER(SEARCH("ERROR", E2))), OR(ISNUMBER(SEARCH("TIME OUT", J2)), ISNUMBER(SEARCH("ERROR", J2)))), "--", IF(OR(ISNUMBER(SEARCH("TIME OUT", E2)), ISNUMBER(SEARCH("ERROR", E2))), "QE", IF(OR(ISNUMBER(SEARCH("TIME OUT", J2)), ISNUMBER(SEARCH("ERROR", J2))), "RC", IF(S2=0, "TIE", IF(S2>0, "QE", "RC"))))) -> TIE | U2: =IF(S2="--","--",TEXT(MIN(E2,J2)/MAX(E2,J2),"0.000%")) -> #DIV/0! | V2: =IF(OR(ISNUMBER(SEARCH("ERROR", F2)), ISNUMBER(SEARCH("ERROR", K2)), ISNUMBER(SEARCH("TIME OUT", F2)), ISNUMBER(SEARCH("TIME OUT", K2))),"--",F2-K2) -> 0 | W2: =IF(AND(OR(ISNUMBER(SEARCH("TIME OUT", F2)), ISNUMBER(SEARCH("ERROR", F2))), OR(ISNUMBER(SEARCH("TIME OUT", K2)), ISNUMBER(SEARCH("ERROR", K2)))), "--", IF(OR(ISNUMBER(SEARCH("TIME OUT", F2)), ISNUMBER(SEARCH("ERROR", F2))), "QE", IF(OR(ISNUMBER(SEARCH("TIME OUT", K2)), ISNUMBER(SEARCH("ERROR", K2))), "RC", IF(V2=0, "TIE", IF(V2>0, "QE", "RC"))))) -> TIE | X2: =IF(V2="--","--",TEXT(MIN(F2,K2)/MAX(F2,K2),"0.000%")) -> #DIV/0! | Z2: =AVERAGE(C:C) -> #DIV/0! | AA2: =AVERAGE(D:D) -> #DIV/0! | AB2: =AVERAGE(E:E) -> #DIV/0! | AC2: =AVERAGE(F:F) -> #DIV/0! | AD2: =AVERAGE(H:H) -> #DIV/0! | AE2: =AVERAGE(I:I) -> #DIV/0! | AF2: =AVERAGE(J:J) -> #DIV/0! | AG2: =AVERAGE(K:K) -> #DIV/0! | AH2: =AVERAGE(M2) -> 0 | AI2: =AVERAGE(P2) -> 0 | AJ2: =AVERAGE(S2) -> 0 | AK2: =AVERAGE(V2) -> 0
AA6: memory | AC6: cputime | AE6: realtime | AG6: cells | AJ6: Successes | AL6: Timeouts | AN6: Errors | AP6: Total
Z7: RC | AA7: =COUNTIF(N:N,$Z7) -> 0 | AB7: =AA7/AA$11 -> 0 | AC7: =COUNTIF(Q:Q,$Z7) -> 0 | AD7: =AC7/AC$11 -> 0 | AE7: =COUNTIF(T:T,$Z7) -> 0 | AF7: =AE7/AE$11 -> 0 | AG7: =COUNTIF(W:W,$Z7) -> 0 | AH7: =AG7/AG$11 -> 0 | AJ7: =COUNTA(B2:B68)-COUNTIF(B2:B68,"*TIME OUT*")-COUNTIF(B2:B68,"*ERROR*") -> 0 | AK7: =AJ7/67 -> 0 | AL7: =COUNTIF(B2:B68,"*TIME OUT*") -> 0 | AM7: =AL7/67 -> 0 | AN7: =COUNTIF(B2:B68,"*ERROR*") -> 0 | AO7: =AN7/67 -> 0 | AP7: =AJ7+AL7+AN7 -> 0 | AQ7: =AK7+AM7+AO7 -> 0
Z8: QE | AA8: =COUNTIF(N:N,$Z8) -> 0 | AB8: =AA8/AA$11 -> 0 | AC8: =COUNTIF(Q:Q,$Z8) -> 0 | AD8: =AC8/AC$11 -> 0 | AE8: =COUNTIF(T:T,$Z8) -> 0 | AF8: =AE8/AE$11 -> 0 | AG8: =COUNTIF(W:W,$Z8) -> 0 | AH8: =AG8/AG$11 -> 0 | AJ8: =COUNTA(G2:G68)-COUNTIF(G2:G68,"*TIME OUT*")-COUNTIF(G2:G68,"*ERROR*") -> 0 | AK8: =AJ8/67 -> 0 | AL8: =COUNTIF(G2:G68,"*TIME OUT*") -> 0 | AM8: =AL8/67 -> 0 | AN8: =COUNTIF(G2:G68,"*ERROR*") -> 0 | AO8: =AN8/67 -> 0 | AP8: =AJ8+AL8+AN8 -> 0 | AQ8: =AK8+AM8+AO8 -> 0
Z9: TIE | AA9: =COUNTIF(N:N,$Z9) -> 1 | AB9: =AA9/AA$11 -> 1 | AC9: =COUNTIF(Q:Q,$Z9) -> 1 | AD9: =AC9/AC$11 -> 1 | AE9: =COUNTIF(T:T,$Z9) -> 1 | AF9: =AE9/AE$11 -> 1 | AG9: =COUNTIF(W:W,$Z9) -> 1 | AH9: =AG9/AG$11 -> 1
Z10: -- | AA10: =COUNTIF(N:N,$Z10) -> 0 | AB10: =AA10/AA$11 -> 0 | AC10: =COUNTIF(Q:Q,$Z10) -> 0 | AD10: =AC10/AC$11 -> 0 | AE10: =COUNTIF(T:T,$Z10) -> 0 | AF10: =AE10/AE$11 -> 0 | AG10: =COUNTIF(W:W,$Z10) -> 0 | AH10: =AG10/AG$11 -> 0
Z11: total | AA11: =COUNTA(N:N)-1 -> 1 | AB11: =AA11/AA$11 -> 1 | AC11: =COUNTA(O:O)-1 -> 1 | AD11: =AC11/AC$11 -> 1 | AE11: =COUNTA(P:P)-1 -> 1 | AF11: =AE11/AE$11 -> 1 | AG11: =COUNTA(Q:Q)-1 -> 1 | AH11: =AG11/AG$11 -> 1
AA13: memory | AC13: cputime | AE13: realtime | AG13: cells
Z14: RC | AA14: =COUNTIF(N:N,$Z7)-COUNTIFS(N:N,$Z7,O:O,"--") -> 0 | AB14: =AA14/AA$11 -> 0 | AC14: =COUNTIF(Q:Q,$Z7)-COUNTIFS(Q:Q,$Z7,R:R,"--") -> 0 | AD14: =AC14/AC$11 -> 0 | AE14: =COUNTIF(T:T,$Z7)-COUNTIFS(T:T,$Z7,U:U,"--") -> 0 | AF14: =AE14/AE$11 -> 0 | AG14: =COUNTIF(W:W,$Z7)-COUNTIFS(W:W,$Z7,X:X,"--") -> 0 | AH14: =AG14/AG$11 -> 0
Z15: QE | AA15: =COUNTIF(N:N,$Z8)-COUNTIFS(N:N,$Z8,O:O,"--") -> 0 | AB15: =AA15/AA$11 -> 0 | AC15: =COUNTIF(Q:Q,$Z8)-COUNTIFS(Q:Q,$Z8,R:R,"--") -> 0 | AD15: =AC15/AC$11 -> 0 | AE15: =COUNTIF(T:T,$Z8)-COUNTIFS(T:T,$Z8,U:U,"--") -> 0 | AF15: =AE15/AE$11 -> 0 | AG15: =COUNTIF(W:W,$Z8)-COUNTIFS(W:W,$Z8,X:X,"--") -> 0 | AH15: =AG15/AG$11 -> 0
Z16: TIE | AA16: =COUNTIF(N:N,$Z9)-COUNTIFS(N:N,$Z9,O:O,"--") -> 1 | AB16: =AA16/AA$11 -> 1 | AC16: =COUNTIF(Q:Q,$Z9)-COUNTIFS(Q:Q,$Z9,R:R,"--") -> 1 | AD16: =AC16/AC$11 -> 1 | AE16: =COUNTIF(T:T,$Z9)-COUNTIFS(T:T,$Z9,U:U,"--") -> 1 | AF16: =AE16/AE$11 -> 1 | AG16: =COUNTIF(W:W,$Z9)-COUNTIFS(W:W,$Z9,X:X,"--") -> 1 | AH16: =AG16/AG$11 -> 1
Z17: -- | AA17: =COUNTIF(O:O,"--") -> 0 | AB17: =AA17/AA$11 -> 0 | AC17: =COUNTIF(R:R,"--") -> 0 | AD17: =AC17/AC$11 -> 0 | AE17: =COUNTIF(U:U,"--") -> 0 | AF17: =AE17/AE$11 -> 0 | AG17: =COUNTIF(X:X,"--") -> 0 | AH17: =AG17/AG$11 -> 0
Z18: total | AA18: =COUNTA(N:N)-1 -> 1 | AB18: =AA18/AA$11 -> 1 | AC18: =COUNTA(O:O)-1 -> 1 | AD18: =AC18/AC$11 -> 1 | AE18: =COUNTA(P:P)-1 -> 1 | AF18: =AE18/AE$11 -> 1 | AG18: =COUNTA(Q:Q)-1 -> 1 | AH18: =AG18/AG$11 -> 1
AD19: =COUNTIF(W:W,$Z8)-COUNTIFS(W:W,$Z8,V:V,"--") -> 0
Z25: Success Rate
Z26: =Z7&": "&AJ7&" "&AJ6&" ("&TEXT(AK7,"0.00%")&"), "&AL7&" "&AL6&" ("&TEXT(AM7,"0.00%")&"), "&AN7&" "&AN6&" ("&TEXT(AO7,"0.00%")&")." -> RC: 0 Successes (0.00%), 0 Timeouts (0.00%), 0 Errors (0.00%).
Z27: =Z8&": "&AJ8&" "&AJ6&" ("&TEXT(AK8,"0.00%")&"), "&AL8&" "&AL6&" ("&TEXT(AM8,"0.00%")&"), "&AN8&" "&AN6&" ("&TEXT(AO8,"0.00%")&")." -> QE: 0 Successes (0.00%), 0 Timeouts (0.00%), 0 Errors (0.00%).
Z29: No. times faster (cputime)
Z30: =Z7&": "&AC7&" ("&TEXT(AD7,"0.00%")&"), "&AC14&" actual ("&TEXT(AD14,"0.00%")&")" -> RC: 0 (0.00%), 0 actual (0.00%)
Z31: =Z8&": "&AC8&" ("&TEXT(AD8,"0.00%")&"), "&AC15&" actual ("&TEXT(AD15,"0.00%")&")" -> QE: 0 (0.00%), 0 actual (0.00%)
Z33: No. times fewer cells
Z34: =Z7&": "&AG7&" ("&TEXT(AH7,"0.00%")&"), "&AG14&" actual ("&TEXT(AH14,"0.00%")&")" -> RC: 0 (0.00%), 0 actual (0.00%)
Z35: =Z8&": "&AG8&" ("&TEXT(AH8,"0.00%")&"), "&AG15&" actual ("&TEXT(AH15,"0.00%")&")" -> QE: 0 (0.00%), 0 actual (0.00%)

Sheet 5
A1: File | B1: rc_ordering | C1: rc_memory | D1: rc_cputime | E1: rc_realtime | F1: rc_cells | G1: qe_ordering | H1: qe_memory | I1: qe_cputime | J1: qe_realtime | K1: qe_cells | L1: Ordering match | M1: memory diff | N1: win | O1: % of other | P1: cputime diff | Q1: win | R1: % of other | S1: realtime diff | T1: win | U1: % of other | V1: cells diff | W1: win | X1: % of other | Z1: rc_memory_avg | AA1: rc_cputime_avg | AB1: rc_realtime_avg | AC1: rc_cells_avg | AD1: qe_memory_avg | AE1: qe_cputime_avg | AF1: qe_realtime_avg | AG1: qe_cells_avg | AH1: =M1&"_avg" -> memory diff_avg | AI1: =P1&"_avg" -> cputime diff_avg | AJ1: =S1&"_avg" -> realtime diff_avg | AK1: =V1&"_avg" -> cells diff_avg
L2: =IF(OR(ISNUMBER(SEARCH("ERROR", B2)), ISNUMBER(SEARCH("ERROR", G2)), ISNUMBER(SEARCH("TIME OUT", B2)), ISNUMBER(SEARCH("TIME OUT", G2))), "--", B2=G2) -> TRUE | M2: =IF(OR(ISNUMBER(SEARCH("ERROR", C2)), ISNUMBER(SEARCH("ERROR", H2)), ISNUMBER(SEARCH("TIME OUT", C2)), ISNUMBER(SEARCH("TIME OUT", H2))),"--",C2-H2) -> 0 | N2: =IF(AND(OR(ISNUMBER(SEARCH("TIME OUT", C2)), ISNUMBER(SEARCH("ERROR", C2))), OR(ISNUMBER(SEARCH("TIME OUT", H2)), ISNUMBER(SEARCH("ERROR", H2)))), "--", IF(OR(ISNUMBER(SEARCH("TIME OUT", C2)), ISNUMBER(SEARCH("ERROR", C2))), "QE", IF(OR(ISNUMBER(SEARCH("TIME OUT", H2)), ISNUMBER(SEARCH("ERROR", H2))), "RC", IF(M2=0, "TIE", IF(M2>0, "QE", "RC"))))) -> TIE | O2: =IF(M2="--","--",TEXT(MIN(C2,H2)/MAX(C2,H2),"0.000%")) -> #DIV/0! | P2: =IF(OR(ISNUMBER(SEARCH("ERROR", D2)), ISNUMBER(SEARCH("ERROR", I2)), ISNUMBER(SEARCH("TIME OUT", D2)), ISNUMBER(SEARCH("TIME OUT", I2))),"--",D2-I2) -> 0 | Q2: =IF(AND(OR(ISNUMBER(SEARCH("TIME OUT", D2)), ISNUMBER(SEARCH("ERROR", D2))), OR(ISNUMBER(SEARCH("TIME OUT", I2)), ISNUMBER(SEARCH("ERROR", I2)))), "--", IF(OR(ISNUMBER(SEARCH("TIME OUT", D2)), ISNUMBER(SEARCH("ERROR", D2))), "QE", IF(OR(ISNUMBER(SEARCH("TIME OUT", I2)), ISNUMBER(SEARCH("ERROR", I2))), "RC", IF(P2=0, "TIE", IF(P2>0, "QE", "RC"))))) -> TIE | R2: =IF(P2="--","--",TEXT(MIN(D2,I2)/MAX(D2,I2),"0.000%")) -> #DIV/0! | S2: =IF(OR(ISNUMBER(SEARCH("ERROR", E2)), ISNUMBER(SEARCH("ERROR", J2)), ISNUMBER(SEARCH("TIME OUT", E2)), ISNUMBER(SEARCH("TIME OUT", J2))),"--",E2-J2) -> 0 | T2: =IF(AND(OR(ISNUMBER(SEARCH("TIME OUT", E2)), ISNUMBER(SEARCH("ERROR", E2))), OR(ISNUMBER(SEARCH("TIME OUT", J2)), ISNUMBER(SEARCH("ERROR", J2)))), "--", IF(OR(ISNUMBER(SEARCH("TIME OUT", E2)), ISNUMBER(SEARCH("ERROR", E2))), "QE", IF(OR(ISNUMBER(SEARCH("TIME OUT", J2)), ISNUMBER(SEARCH("ERROR", J2))), "RC", IF(S2=0, "TIE", IF(S2>0, "QE", "RC"))))) -> TIE | U2: =IF(S2="--","--",TEXT(MIN(E2,J2)/MAX(E2,J2),"0.000%")) -> #DIV/0! | V2: =IF(OR(ISNUMBER(SEARCH("ERROR", F2)), ISNUMBER(SEARCH("ERROR", K2)), ISNUMBER(SEARCH("TIME OUT", F2)), ISNUMBER(SEARCH("TIME OUT", K2))),"--",F2-K2) -> 0 | W2: =IF(AND(OR(ISNUMBER(SEARCH("TIME OUT", F2)), ISNUMBER(SEARCH("ERROR", F2))), OR(ISNUMBER(SEARCH("TIME OUT", K2)), ISNUMBER(SEARCH("ERROR", K2)))), "--", IF(OR(ISNUMBER(SEARCH("TIME OUT", F2)), ISNUMBER(SEARCH("ERROR", F2))), "QE", IF(OR(ISNUMBER(SEARCH("TIME OUT", K2)), ISNUMBER(SEARCH("ERROR", K2))), "RC", IF(V2=0, "TIE", IF(V2>0, "QE", "RC"))))) -> TIE | X2: =IF(V2="--","--",TEXT(MIN(F2,K2)/MAX(F2,K2),"0.000%")) -> #DIV/0! | Z2: =AVERAGE(C:C) -> #DIV/0! | AA2: =AVERAGE(D:D) -> #DIV/0! | AB2: =AVERAGE(E:E) -> #DIV/0! | AC2: =AVERAGE(F:F) -> #DIV/0! | AD2: =AVERAGE(H:H) -> #DIV/0! | AE2: =AVERAGE(I:I) -> #DIV/0! | AF2: =AVERAGE(J:J) -> #DIV/0! | AG2: =AVERAGE(K:K) -> #DIV/0! | AH2: =AVERAGE(M2) -> 0 | AI2: =AVERAGE(P2) -> 0 | AJ2: =AVERAGE(S2) -> 0 | AK2: =AVERAGE(V2) -> 0
AA6: memory | AC6: cputime | AE6: realtime | AG6: cells | AJ6: Successes | AL6: Timeouts | AN6: Errors | AP6: Total
Z7: RC | AA7: =COUNTIF(N:N,$Z7) -> 0 | AB7: =AA7/AA$11 -> 0 | AC7: =COUNTIF(Q:Q,$Z7) -> 0 | AD7: =AC7/AC$11 -> 0 | AE7: =COUNTIF(T:T,$Z7) -> 0 | AF7: =AE7/AE$11 -> 0 | AG7: =COUNTIF(W:W,$Z7) -> 0 | AH7: =AG7/AG$11 -> 0 | AJ7: =COUNTA(B2:B68)-COUNTIF(B2:B68,"*TIME OUT*")-COUNTIF(B2:B68,"*ERROR*") -> 0 | AK7: =AJ7/67 -> 0 | AL7: =COUNTIF(B2:B68,"*TIME OUT*") -> 0 | AM7: =AL7/67 -> 0 | AN7: =COUNTIF(B2:B68,"*ERROR*") -> 0 | AO7: =AN7/67 -> 0 | AP7: =AJ7+AL7+AN7 -> 0 | AQ7: =AK7+AM7+AO7 -> 0
Z8: QE | AA8: =COUNTIF(N:N,$Z8) -> 0 | AB8: =AA8/AA$11 -> 0 | AC8: =COUNTIF(Q:Q,$Z8) -> 0 | AD8: =AC8/AC$11 -> 0 | AE8: =COUNTIF(T:T,$Z8) -> 0 | AF8: =AE8/AE$11 -> 0 | AG8: =COUNTIF(W:W,$Z8) -> 0 | AH8: =AG8/AG$11 -> 0 | AJ8: =COUNTA(G2:G68)-COUNTIF(G2:G68,"*TIME OUT*")-COUNTIF(G2:G68,"*ERROR*") -> 0 | AK8: =AJ8/67 -> 0 | AL8: =COUNTIF(G2:G68,"*TIME OUT*") -> 0 | AM8: =AL8/67 -> 0 | AN8: =COUNTIF(G2:G68,"*ERROR*") -> 0 | AO8: =AN8/67 -> 0 | AP8: =AJ8+AL8+AN8 -> 0 | AQ8: =AK8+AM8+AO8 -> 0
Z9: TIE | AA9: =COUNTIF(N:N,$Z9) -> 1 | AB9: =AA9/AA$11 -> 1 | AC9: =COUNTIF(Q:Q,$Z9) -> 1 | AD9: =AC9/AC$11 -> 1 | AE9: =COUNTIF(T:T,$Z9) -> 1 | AF9: =AE9/AE$11 -> 1 | AG9: =COUNTIF(W:W,$Z9) -> 1 | AH9: =AG9/AG$11 -> 1
Z10: -- | AA10: =COUNTIF(N:N,$Z10) -> 0 | AB10: =AA10/AA$11 -> 0 | AC10: =COUNTIF(Q:Q,$Z10) -> 0 | AD10: =AC10/AC$11 -> 0 | AE10: =COUNTIF(T:T,$Z10) -> 0 | AF10: =AE10/AE$11 -> 0 | AG10: =COUNTIF(W:W,$Z10) -> 0 | AH10: =AG10/AG$11 -> 0
Z11: total | AA11: =COUNTA(N:N)-1 -> 1 | AB11: =AA11/AA$11 -> 1 | AC11: =COUNTA(O:O)-1 -> 1 | AD11: =AC11/AC$11 -> 1 | AE11: =COUNTA(P:P)-1 -> 1 | AF11: =AE11/AE$11 -> 1 | AG11: =COUNTA(Q:Q)-1 -> 1 | AH11: =AG11/AG$11 -> 1
AA13: memory | AC13: cputime | AE13: realtime | AG13: cells
Z14: RC | AA14: =COUNTIF(N:N,$Z7)-COUNTIFS(N:N,$Z7,O:O,"--") -> 0 | AB14: =AA14/AA$11 -> 0 | AC14: =COUNTIF(Q:Q,$Z7)-COUNTIFS(Q:Q,$Z7,R:R,"--") -> 0 | AD14: =AC14/AC$11 -> 0 | AE14: =COUNTIF(T:T,$Z7)-COUNTIFS(T:T,$Z7,U:U,"--") -> 0 | AF14: =AE14/AE$11 -> 0 | AG14: =COUNTIF(W:W,$Z7)-COUNTIFS(W:W,$Z7,X:X,"--") -> 0 | AH14: =AG14/AG$11 -> 0
Z15: QE | AA15: =COUNTIF(N:N,$Z8)-COUNTIFS(N:N,$Z8,O:O,"--") -> 0 | AB15: =AA15/AA$11 -> 0 | AC15: =COUNTIF(Q:Q,$Z8)-COUNTIFS(Q:Q,$Z8,R:R,"--") -> 0 | AD15: =AC15/AC$11 -> 0 | AE15: =COUNTIF(T:T,$Z8)-COUNTIFS(T:T,$Z8,U:U,"--") -> 0 | AF15: =AE15/AE$11 -> 0 | AG15: =COUNTIF(W:W,$Z8)-COUNTIFS(W:W,$Z8,X:X,"--") -> 0 | AH15: =AG15/AG$11 -> 0
Z16: TIE | AA16: =COUNTIF(N:N,$Z9)-COUNTIFS(N:N,$Z9,O:O,"--") -> 1 | AB16: =AA16/AA$11 -> 1 | AC16: =COUNTIF(Q:Q,$Z9)-COUNTIFS(Q:Q,$Z9,R:R,"--") -> 1 | AD16: =AC16/AC$11 -> 1 | AE16: =COUNTIF(T:T,$Z9)-COUNTIFS(T:T,$Z9,U:U,"--") -> 1 | AF16: =AE16/AE$11 -> 1 | AG16: =COUNTIF(W:W,$Z9)-COUNTIFS(W:W,$Z9,X:X,"--") -> 1 | AH16: =AG16/AG$11 -> 1
Z17: -- | AA17: =COUNTIF(O:O,"--") -> 0 | AB17: =AA17/AA$11 -> 0 | AC17: =COUNTIF(R:R,"--") -> 0 | AD17: =AC17/AC$11 -> 0 | AE17: =COUNTIF(U:U,"--") -> 0 | AF17: =AE17/AE$11 -> 0 | AG17: =COUNTIF(X:X,"--") -> 0 | AH17: =AG17/AG$11 -> 0
Z18: total | AA18: =COUNTA(N:N)-1 -> 1 | AB18: =AA18/AA$11 -> 1 | AC18: =COUNTA(O:O)-1 -> 1 | AD18: =AC18/AC$11 -> 1 | AE18: =COUNTA(P:P)-1 -> 1 | AF18: =AE18/AE$11 -> 1 | AG18: =COUNTA(Q:Q)-1 -> 1 | AH18: =AG18/AG$11 -> 1
AD19: =COUNTIF(W:W,$Z8)-COUNTIFS(W:W,$Z8,V:V,"--") -> 0
Z25: Success Rate
Z26: =Z7&": "&AJ7&" "&AJ6&" ("&TEXT(AK7,"0.00%")&"), "&AL7&" "&AL6&" ("&TEXT(AM7,"0.00%")&"), "&AN7&" "&AN6&" ("&TEXT(AO7,"0.00%")&")." -> RC: 0 Successes (0.00%), 0 Timeouts (0.00%), 0 Errors (0.00%).
Z27: =Z8&": "&AJ8&" "&AJ6&" ("&TEXT(AK8,"0.00%")&"), "&AL8&" "&AL6&" ("&TEXT(AM8,"0.00%")&"), "&AN8&" "&AN6&" ("&TEXT(AO8,"0.00%")&")." -> QE: 0 Successes (0.00%), 0 Timeouts (0.00%), 0 Errors (0.00%).
Z29: No. times faster (cputime)
Z30: =Z7&": "&AC7&" ("&TEXT(AD7,"0.00%")&"), "&AC14&" actual ("&TEXT(AD14,"0.00%")&")" -> RC: 0 (0.00%), 0 actual (0.00%)
Z31: =Z8&": "&AC8&" ("&TEXT(AD8,"0.00%")&"), "&AC15&" actual ("&TEXT(AD15,"0.00%")&")" -> QE: 0 (0.00%), 0 actual (0.00%)
Z33: No. times fewer cells
Z34: =Z7&": "&AG7&" ("&TEXT(AH7,"0.00%")&"), "&AG14&" actual ("&TEXT(AH14,"0.00%")&")" -> RC: 0 (0.00%), 0 actual (0.00%)
Z35: =Z8&": "&AG8&" ("&TEXT(AH8,"0.00%")&"), "&AG15&" actual ("&TEXT(AH15,"0.00%")&")" -> QE: 0 (0.00%), 0 actual (0.00%)

Sheet 6
A1: File | B1: rc_ordering | C1: rc_memory | D1: rc_cputime | E1: rc_realtime | F1: rc_cells | G1: qe_ordering | H1: qe_memory | I1: qe_cputime | J1: qe_realtime | K1: qe_cells | L1: Ordering match | M1: memory diff | N1: win | O1: % of other | P1: cputime diff | Q1: win | R1: % of other | S1: realtime diff | T1: win | U1: % of other | V1: cells diff | W1: win | X1: % of other | Z1: rc_memory_avg | AA1: rc_cputime_avg | AB1: rc_realtime_avg | AC1: rc_cells_avg | AD1: qe_memory_avg | AE1: qe_cputime_avg | AF1: qe_realtime_avg | AG1: qe_cells_avg | AH1: =M1&"_avg" -> memory diff_avg | AI1: =P1&"_avg" -> cputime diff_avg | AJ1: =S1&"_avg" -> realtime diff_avg | AK1: =V1&"_avg" -> cells diff_avg
L2: =IF(OR(ISNUMBER(SEARCH("ERROR", B2)), ISNUMBER(SEARCH("ERROR", G2)), ISNUMBER(SEARCH("TIME OUT", B2)), ISNUMBER(SEARCH("TIME OUT", G2))), "--", B2=G2) -> TRUE | M2: =IF(OR(ISNUMBER(SEARCH("ERROR", C2)), ISNUMBER(SEARCH("ERROR", H2)), ISNUMBER(SEARCH("TIME OUT", C2)), ISNUMBER(SEARCH("TIME OUT", H2))),"--",C2-H2) -> 0 | N2: =IF(AND(OR(ISNUMBER(SEARCH("TIME OUT", C2)), ISNUMBER(SEARCH("ERROR", C2))), OR(ISNUMBER(SEARCH("TIME OUT", H2)), ISNUMBER(SEARCH("ERROR", H2)))), "--", IF(OR(ISNUMBER(SEARCH("TIME OUT", C2)), ISNUMBER(SEARCH("ERROR", C2))), "QE", IF(OR(ISNUMBER(SEARCH("TIME OUT", H2)), ISNUMBER(SEARCH("ERROR", H2))), "RC", IF(M2=0, "TIE", IF(M2>0, "QE", "RC"))))) -> TIE | O2: =IF(M2="--","--",TEXT(MIN(C2,H2)/MAX(C2,H2),"0.000%")) -> #DIV/0! | P2: =IF(OR(ISNUMBER(SEARCH("ERROR", D2)), ISNUMBER(SEARCH("ERROR", I2)), ISNUMBER(SEARCH("TIME OUT", D2)), ISNUMBER(SEARCH("TIME OUT", I2))),"--",D2-I2) -> 0 | Q2: =IF(AND(OR(ISNUMBER(SEARCH("TIME OUT", D2)), ISNUMBER(SEARCH("ERROR", D2))), OR(ISNUMBER(SEARCH("TIME OUT", I2)), ISNUMBER(SEARCH("ERROR", I2)))), "--", IF(OR(ISNUMBER(SEARCH("TIME OUT", D2)), ISNUMBER(SEARCH("ERROR", D2))), "QE", IF(OR(ISNUMBER(SEARCH("TIME OUT", I2)), ISNUMBER(SEARCH("ERROR", I2))), "RC", IF(P2=0, "TIE", IF(P2>0, "QE", "RC"))))) -> TIE | R2: =IF(P2="--","--",TEXT(MIN(D2,I2)/MAX(D2,I2),"0.000%")) -> #DIV/0! | S2: =IF(OR(ISNUMBER(SEARCH("ERROR", E2)), ISNUMBER(SEARCH("ERROR", J2)), ISNUMBER(SEARCH("TIME OUT", E2)), ISNUMBER(SEARCH("TIME OUT", J2))),"--",E2-J2) -> 0 | T2: =IF(AND(OR(ISNUMBER(SEARCH("TIME OUT", E2)), ISNUMBER(SEARCH("ERROR", E2))), OR(ISNUMBER(SEARCH("TIME OUT", J2)), ISNUMBER(SEARCH("ERROR", J2)))), "--", IF(OR(ISNUMBER(SEARCH("TIME OUT", E2)), ISNUMBER(SEARCH("ERROR", E2))), "QE", IF(OR(ISNUMBER(SEARCH("TIME OUT", J2)), ISNUMBER(SEARCH("ERROR", J2))), "RC", IF(S2=0, "TIE", IF(S2>0, "QE", "RC"))))) -> TIE | U2: =IF(S2="--","--",TEXT(MIN(E2,J2)/MAX(E2,J2),"0.000%")) -> #DIV/0! | V2: =IF(OR(ISNUMBER(SEARCH("ERROR", F2)), ISNUMBER(SEARCH("ERROR", K2)), ISNUMBER(SEARCH("TIME OUT", F2)), ISNUMBER(SEARCH("TIME OUT", K2))),"--",F2-K2) -> 0 | W2: =IF(AND(OR(ISNUMBER(SEARCH("TIME OUT", F2)), ISNUMBER(SEARCH("ERROR", F2))), OR(ISNUMBER(SEARCH("TIME OUT", K2)), ISNUMBER(SEARCH("ERROR", K2)))), "--", IF(OR(ISNUMBER(SEARCH("TIME OUT", F2)), ISNUMBER(SEARCH("ERROR", F2))), "QE", IF(OR(ISNUMBER(SEARCH("TIME OUT", K2)), ISNUMBER(SEARCH("ERROR", K2))), "RC", IF(V2=0, "TIE", IF(V2>0, "QE", "RC"))))) -> TIE | X2: =IF(V2="--","--",TEXT(MIN(F2,K2)/MAX(F2,K2),"0.000%")) -> #DIV/0! | Z2: =AVERAGE(C:C) -> #DIV/0! | AA2: =AVERAGE(D:D) -> #DIV/0! | AB2: =AVERAGE(E:E) -> #DIV/0! | AC2: =AVERAGE(F:F) -> #DIV/0! | AD2: =AVERAGE(H:H) -> #DIV/0! | AE2: =AVERAGE(I:I) -> #DIV/0! | AF2: =AVERAGE(J:J) -> #DIV/0! | AG2: =AVERAGE(K:K) -> #DIV/0! | AH2: =AVERAGE(M2) -> 0 | AI2: =AVERAGE(P2) -> 0 | AJ2: =AVERAGE(S2) -> 0 | AK2: =AVERAGE(V2) -> 0
AA6: memory | AC6: cputime | AE6: realtime | AG6: cells | AJ6: Successes | AL6: Timeouts | AN6: Errors | AP6: Total
Z7: RC | AA7: =COUNTIF(N:N,$Z7) -> 0 | AB7: =AA7/AA$11 -> 0 | AC7: =COUNTIF(Q:Q,$Z7) -> 0 | AD7: =AC7/AC$11 -> 0 | AE7: =COUNTIF(T:T,$Z7) -> 0 | AF7: =AE7/AE$11 -> 0 | AG7: =COUNTIF(W:W,$Z7) -> 0 | AH7: =AG7/AG$11 -> 0 | AJ7: =COUNTA(B2:B68)-COUNTIF(B2:B68,"*TIME OUT*")-COUNTIF(B2:B68,"*ERROR*") -> 0 | AK7: =AJ7/67 -> 0 | AL7: =COUNTIF(B2:B68,"*TIME OUT*") -> 0 | AM7: =AL7/67 -> 0 | AN7: =COUNTIF(B2:B68,"*ERROR*") -> 0 | AO7: =AN7/67 -> 0 | AP7: =AJ7+AL7+AN7 -> 0 | AQ7: =AK7+AM7+AO7 -> 0
Z8: QE | AA8: =COUNTIF(N:N,$Z8) -> 0 | AB8: =AA8/AA$11 -> 0 | AC8: =COUNTIF(Q:Q,$Z8) -> 0 | AD8: =AC8/AC$11 -> 0 | AE8: =COUNTIF(T:T,$Z8) -> 0 | AF8: =AE8/AE$11 -> 0 | AG8: =COUNTIF(W:W,$Z8) -> 0 | AH8: =AG8/AG$11 -> 0 | AJ8: =COUNTA(G2:G68)-COUNTIF(G2:G68,"*TIME OUT*")-COUNTIF(G2:G68,"*ERROR*") -> 0 | AK8: =AJ8/67 -> 0 | AL8: =COUNTIF(G2:G68,"*TIME OUT*") -> 0 | AM8: =AL8/67 -> 0 | AN8: =COUNTIF(G2:G68,"*ERROR*") -> 0 | AO8: =AN8/67 -> 0 | AP8: =AJ8+AL8+AN8 -> 0 | AQ8: =AK8+AM8+AO8 -> 0
Z9: TIE | AA9: =COUNTIF(N:N,$Z9) -> 1 | AB9: =AA9/AA$11 -> 1 | AC9: =COUNTIF(Q:Q,$Z9) -> 1 | AD9: =AC9/AC$11 -> 1 | AE9: =COUNTIF(T:T,$Z9) -> 1 | AF9: =AE9/AE$11 -> 1 | AG9: =COUNTIF(W:W,$Z9) -> 1 | AH9: =AG9/AG$11 -> 1
Z10: -- | AA10: =COUNTIF(N:N,$Z10) -> 0 | AB10: =AA10/AA$11 -> 0 | AC10: =COUNTIF(Q:Q,$Z10) -> 0 | AD10: =AC10/AC$11 -> 0 | AE10: =COUNTIF(T:T,$Z10) -> 0 | AF10: =AE10/AE$11 -> 0 | AG10: =COUNTIF(W:W,$Z10) -> 0 | AH10: =AG10/AG$11 -> 0
Z11: total | AA11: =COUNTA(N:N)-1 -> 1 | AB11: =AA11/AA$11 -> 1 | AC11: =COUNTA(O:O)-1 -> 1 | AD11: =AC11/AC$11 -> 1 | AE11: =COUNTA(P:P)-1 -> 1 | AF11: =AE11/AE$11 -> 1 | AG11: =COUNTA(Q:Q)-1 -> 1 | AH11: =AG11/AG$11 -> 1
AA13: memory | AC13: cputime | AE13: realtime | AG13: cells
Z14: RC | AA14: =COUNTIF(N:N,$Z7)-COUNTIFS(N:N,$Z7,O:O,"--") -> 0 | AB14: =AA14/AA$11 -> 0 | AC14: =COUNTIF(Q:Q,$Z7)-COUNTIFS(Q:Q,$Z7,R:R,"--") -> 0 | AD14: =AC14/AC$11 -> 0 | AE14: =COUNTIF(T:T,$Z7)-COUNTIFS(T:T,$Z7,U:U,"--") -> 0 | AF14: =AE14/AE$11 -> 0 | AG14: =COUNTIF(W:W,$Z7)-COUNTIFS(W:W,$Z7,X:X,"--") -> 0 | AH14: =AG14/AG$11 -> 0
Z15: QE | AA15: =COUNTIF(N:N,$Z8)-COUNTIFS(N:N,$Z8,O:O,"--") -> 0 | AB15: =AA15/AA$11 -> 0 | AC15: =COUNTIF(Q:Q,$Z8)-COUNTIFS(Q:Q,$Z8,R:R,"--") -> 0 | AD15: =AC15/AC$11 -> 0 | AE15: =COUNTIF(T:T,$Z8)-COUNTIFS(T:T,$Z8,U:U,"--") -> 0 | AF15: =AE15/AE$11 -> 0 | AG15: =COUNTIF(W:W,$Z8)-COUNTIFS(W:W,$Z8,X:X,"--") -> 0 | AH15: =AG15/AG$11 -> 0
Z16: TIE | AA16: =COUNTIF(N:N,$Z9)-COUNTIFS(N:N,$Z9,O:O,"--") -> 1 | AB16: =AA16/AA$11 -> 1 | AC16: =COUNTIF(Q:Q,$Z9)-COUNTIFS(Q:Q,$Z9,R:R,"--") -> 1 | AD16: =AC16/AC$11 -> 1 | AE16: =COUNTIF(T:T,$Z9)-COUNTIFS(T:T,$Z9,U:U,"--") -> 1 | AF16: =AE16/AE$11 -> 1 | AG16: =COUNTIF(W:W,$Z9)-COUNTIFS(W:W,$Z9,X:X,"--") -> 1 | AH16: =AG16/AG$11 -> 1
Z17: -- | AA17: =COUNTIF(O:O,"--") -> 0 | AB17: =AA17/AA$11 -> 0 | AC17: =COUNTIF(R:R,"--") -> 0 | AD17: =AC17/AC$11 -> 0 | AE17: =COUNTIF(U:U,"--") -> 0 | AF17: =AE17/AE$11 -> 0 | AG17: =COUNTIF(X:X,"--") -> 0 | AH17: =AG17/AG$11 -> 0
Z18: total | AA18: =COUNTA(N:N)-1 -> 1 | AB18: =AA18/AA$11 -> 1 | AC18: =COUNTA(O:O)-1 -> 1 | AD18: =AC18/AC$11 -> 1 | AE18: =COUNTA(P:P)-1 -> 1 | AF18: =AE18/AE$11 -> 1 | AG18: =COUNTA(Q:Q)-1 -> 1 | AH18: =AG18/AG$11 -> 1
AD19: =COUNTIF(W:W,$Z8)-COUNTIFS(W:W,$Z8,V:V,"--") -> 0
Z25: Success Rate
Z26: =Z7&": "&AJ7&" "&AJ6&" ("&TEXT(AK7,"0.00%")&"), "&AL7&" "&AL6&" ("&TEXT(AM7,"0.00%")&"), "&AN7&" "&AN6&" ("&TEXT(AO7,"0.00%")&")." -> RC: 0 Successes (0.00%), 0 Timeouts (0.00%), 0 Errors (0.00%).
Z27: =Z8&": "&AJ8&" "&AJ6&" ("&TEXT(AK8,"0.00%")&"), "&AL8&" "&AL6&" ("&TEXT(AM8,"0.00%")&"), "&AN8&" "&AN6&" ("&TEXT(AO8,"0.00%")&")." -> QE: 0 Successes (0.00%), 0 Timeouts (0.00%), 0 Errors (0.00%).
Z29: No. times faster (cputime)
Z30: =Z7&": "&AC7&" ("&TEXT(AD7,"0.00%")&"), "&AC14&" actual ("&TEXT(AD14,"0.00%")&")" -> RC: 0 (0.00%), 0 actual (0.00%)
Z31: =Z8&": "&AC8&" ("&TEXT(AD8,"0.00%")&"), "&AC15&" actual ("&TEXT(AD15,"0.00%")&")" -> QE: 0 (0.00%), 0 actual (0.00%)
Z33: No. times fewer cells
Z34: =Z7&": "&AG7&" ("&TEXT(AH7,"0.00%")&"), "&AG14&" actual ("&TEXT(AH14,"0.00%")&")" -> RC: 0 (0.00%), 0 actual (0.00%)
Z35: =Z8&": "&AG8&" ("&TEXT(AH8,"0.00%")&"), "&AG15&" actual ("&TEXT(AH15,"0.00%")&")" -> QE: 0 (0.00%), 0 actual (0.00%)

Sheet Meta
A1: File | B1: RC REAL TIME | H1: QE REAL TIME
A2: File | B2: RC1 | C2: RC2 | D2: RC3 | E2: RC4 | F2: RC5 | G2: RC6 | H2: QE1 | I2: QE2 | J2: QE3 | K2: QE4 | L2: QE5 | M2: QE6 | P2: RC error | Q2: QE error
A3: 17 | B3: =VLOOKUP($A3,'1'!$A:$D,4,0) -> #N/A | C3: =VLOOKUP($A3,'2'!$A:$E,5,0) -> #N/A | D3: =VLOOKUP($A3,'3'!$A:$E,5,0) -> #N/A | E3: =VLOOKUP($A3,'4'!$A:$E,5,0) -> #N/A | F3: =VLOOKUP($A3,'5'!$A:$E,5,0) -> #N/A | G3: =VLOOKUP($A3,'6'!$A:$E,5,0) -> #N/A | H3: =VLOOKUP($A3,'1'!$A:$J,10,0) -> #N/A | I3: =VLOOKUP($A3,'2'!$A:$J,10,0) -> #N/A | J3: =VLOOKUP($A3,'3'!$A:$J,10,0) -> #N/A | K3: =VLOOKUP($A3,'4'!$A:$J,10,0) -> #N/A | L3: =VLOOKUP($A3,'5'!$A:$J,10,0) -> #N/A | M3: =VLOOKUP($A3,'6'!$A:$J,10,0) -> #N/A | N3: =IF(MATCH(MIN($B3:$M3),$B3:$M3,0)>6,"QE","RC") -> #N/A | O3: =MATCH(MIN($B3:$M3),$B3:$M3,0) -> #N/A | P3: =IF(LEFT(B3,5)="ERROR","1: "&VLOOKUP(B3,$S$31:$T$34,2,0)&". ","")&IF(LEFT(C3,5)="ERROR","2: "&VLOOKUP(C3,$S$31:$T$34,2,0)&". ","")&IF(LEFT(D3,5)="ERROR","3: "&VLOOKUP(D3,$S$31:$T$34,2,0)&". ","")&IF(LEFT(E3,5)="ERROR","4: "&VLOOKUP(E3,$S$31:$T$34,2,0)&". ","")&IF(LEFT(F3,5)="ERROR","5: "&VLOOKUP(F3,$S$31:$T$34,2,0)&". ","")&IF(LEFT(G3,5)="ERROR","6: "&G3,"") -> #N/A | Q3: =IF(LEFT(H3,5)="ERROR","1: "&VLOOKUP(H3,$S$31:$T$34,2,0)&". ","")&IF(LEFT(I3,5)="ERROR","2: "&VLOOKUP(I3,$S$31:$T$34,2,0)&". ","")&IF(LEFT(J3,5)="ERROR","3: "&VLOOKUP(J3,$S$31:$T$34,2,0)&". ","")&IF(LEFT(K3,5)="ERROR","4: "&VLOOKUP(K3,$S$31:$T$34,2,0)&". ","")&IF(LEFT(L3,5)="ERROR","5: "&VLOOKUP(L3,$S$31:$T$34,2,0)&". ","")&IF(LEFT(M3,5)="ERROR","6: "&M3,"") -> #N/A | T3: Fastest
A4: 19 | B4: =VLOOKUP($A4,'1'!$A:$D,4,0) -> #N/A | C4: =VLOOKUP($A4,'2'!$A:$D,4,0) -> #N/A | D4: =VLOOKUP($A4,'3'!$A:$D,4,0) -> #N/A | E4: =VLOOKUP($A4,'4'!$A:$D,4,0) -> #N/A | F4: =VLOOKUP($A4,'5'!$A:$D,4,0) -> #N/A | G4: =VLOOKUP($A4,'6'!$A:$D,4,0) -> #N/A | H4: =VLOOKUP($A4,'1'!$A:$J,10,0) -> #N/A | I4: =VLOOKUP($A4,'2'!$A:$J,10,0) -> #N/A | J4: =VLOOKUP($A4,'3'!$A:$J,10,0) -> #N/A | K4: =VLOOKUP($A4,'4'!$A:$J,10,0) -> #N/A | L4: =VLOOKUP($A4,'5'!$A:$J,10,0) -> #N/A | M4: =VLOOKUP($A4,'6'!$A:$J,10,0) -> #N/A | N4: =IF(MATCH(MIN($B4:$M4),$B4:$M4,0)>6,"QE","RC") -> #N/A | O4: =MATCH(MIN($B4:$M4),$B4:$M4,0) -> #N/A | P4: =IF(LEFT(B4,5)="ERROR","1: "&VLOOKUP(B4,$S$31:$T$34,2,0)&". ","")&IF(LEFT(C4,5)="ERROR","2: "&VLOOKUP(C4,$S$31:$T$34,2,0)&". ","")&IF(LEFT(D4,5)="ERROR","3: "&VLOOKUP(D4,$S$31:$T$34,2,0)&". ","")&IF(LEFT(E4,5)="ERROR","4: "&VLOOKUP(E4,$S$31:$T$34,2,0)&". ","")&IF(LEFT(F4,5)="ERROR","5: "&VLOOKUP(F4,$S$31:$T$34,2,0)&". ","")&IF(LEFT(G4,5)="ERROR","6: "&G4,"") -> #N/A | Q4: =IF(LEFT(H4,5)="ERROR","1: "&VLOOKUP(H4,$S$31:$T$34,2,0)&". ","")&IF(LEFT(I4,5)="ERROR","2: "&VLOOKUP(I4,$S$31:$T$34,2,0)&". ","")&IF(LEFT(J4,5)="ERROR","3: "&VLOOKUP(J4,$S$31:$T$34,2,0)&". ","")&IF(LEFT(K4,5)="ERROR","4: "&VLOOKUP(K4,$S$31:$T$34,2,0)&". ","")&IF(LEFT(L4,5)="ERROR","5: "&VLOOKUP(L4,$S$31:$T$34,2,0)&". ","")&IF(LEFT(M4,5)="ERROR","6: "&M4,"") -> #N/A | T4: RC | U4: QE | W4: "TIME OUT" | X4: "ERROR
