Workbook

Sheet 1
A1: File | B1: rc_ordering | C1: rc_memory | D1: rc_cputime | E1: rc_realtime | F1: rc_cells | G1: qe_ordering | H1: qe_memory | I1: qe_cputime | J1: qe_realtime | K1: qe_cells | L1: Ordering match | M1: memory diff | N1: win | O1: % of other | P1: cputime diff | Q1: win | R1: % of other | S1: realtime diff | T1: win | U1: % of other | V1: cells diff | W1: win | X1: % of other | Z1: rc_memory_avg | AA1: rc_cputime_avg | AB1: rc_realtime_avg | AC1: rc_cells_avg | AD1: qe_memory_avg | AE1: qe_cputime_avg | AF1: qe_realtime_avg | AG1: qe_cells_avg | AH1: =M1&"_avg" -> memory diff_avg | AI1: =P1&"_avg" -> cputime diff_avg | AJ1: =S1&"_avg" -> realtime diff_avg | AK1: =V1&"_avg" -> cells diff_avg
A2: 17 | B2: [skoE, skoR, skoX] | C2: 25141480 | D2: 0.2297 | E2: 0.2284 | F2: 189 | G2: [skoE, skoR, skoX] | H2: 17426908 | I2: 0.2203 | J2: 0.2164 | K2: 189 | L2: =IF(OR(ISNUMBER(SEARCH("ERROR", B2)), ISNUMBER(SEARCH("ERROR", G2)), ISNUMBER(SEARCH("TIME OUT", B2)), ISNUMBER(SEARCH("TIME OUT", G2))), "--", B2=G2) -> TRUE | M2: =IF(OR(ISNUMBER(SEARCH("ERROR", C2)), ISNUMBER(SEARCH("ERROR", H2)), ISNUMBER(SEARCH("TIME OUT", C2)), ISNUMBER(SEARCH("TIME OUT", H2))),"--",C2-H2) -> 7714572 | N2: =IF(AND(OR(ISNUMBER(SEARCH("TIME OUT", C2)), ISNUMBER(SEARCH("ERROR", C2))), OR(ISNUMBER(SEARCH("TIME OUT", H2)), ISNUMBER(SEARCH("ERROR", H2)))), "--", IF(OR(ISNUMBER(SEARCH("TIME OUT", C2)), ISNUMBER(SEARCH("ERROR", C2))), "QE", IF(OR(ISNUMBER(SEARCH("TIME OUT", H2)), ISNUMBER(SEARCH("ERROR", H2))), "RC", IF(M2=0, "TIE", IF(M2>0, "QE", "RC"))))) -> QE | O2: =IF(M2="--","--",TEXT(MIN(C2,H2)/MAX(C2,H2),"0.000%")) -> 69.315% | P2: =IF(OR(ISNUMBER(SEARCH("ERROR", D2)), ISNUMBER(SEARCH("ERROR", I2)), ISNUMBER(SEARCH("TIME OUT", D2)), ISNUMBER(SEARCH("TIME OUT", I2))),"--",D2-I2) -> 0.0094 | Q2: =IF(AND(OR(ISNUMBER(SEARCH("TIME OUT", D2)), ISNUMBER(SEARCH("ERROR", D2))), OR(ISNUMBER(SEARCH("TIME OUT", I2)), ISNUMBER(SEARCH("ERROR", I2)))), "--", IF(OR(ISNUMBER(SEARCH("TIME OUT", D2)), ISNUMBER(SEARCH("ERROR", D2))), "QE", IF(OR(ISNUMBER(SEARCH("TIME OUT", I2)), ISNUMBER(SEARCH("ERROR", I2))), "RC", IF(P2=0, "TIE", IF(P2>0, "QE", "RC"))))) -> QE | R2: =IF(P2="--","--",TEXT(MIN(D2,I2)/MAX(D2,I2),"0.000%")) -> 95.908% | S2: =IF(OR(ISNUMBER(SEARCH("ERROR", E2)), ISNUMBER(SEARCH("ERROR", J2)), ISNUMBER(SEARCH("TIME OUT", E2)), ISNUMBER(SEARCH("TIME OUT", J2))),"--",E2-J2) -> 0.012 | T2: =IF(AND(OR(ISNUMBER(SEARCH("TIME OUT", E2)), ISNUMBER(SEARCH("ERROR", E2))), OR(ISNUMBER(SEARCH("TIME OUT", J2)), ISNUMBER(SEARCH("ERROR", J2)))), "--", IF(OR(ISNUMBER(SEARCH("TIME OUT", E2)), ISNUMBER(SEARCH("ERROR", E2))), "QE", IF(OR(ISNUMBER(SEARCH("TIME OUT", J2)), ISNUMBER(SEARCH("ERROR", J2))), "RC", IF(S2=0, "TIE", IF(S2>0, "QE", "RC"))))) -> QE | U2: =IF(S2="--","--",TEXT(MIN(E2,J2)/MAX(E2,J2),"0.000%")) -> 94.746% | V2: =IF(OR(ISNUMBER(SEARCH("ERROR", F2)), ISNUMBER(SEARCH("ERROR", K2)), ISNUMBER(SEARCH("TIME OUT", F2)), ISNUMBER(SEARCH("TIME OUT", K2))),"--",F2-K2) -> 0 | W2: =IF(AND(OR(ISNUMBER(SEARCH("TIME OUT", F2)), ISNUMBER(SEARCH("ERROR", F2))), OR(ISNUMBER(SEARCH("TIME OUT", K2)), ISNUMBER(SEARCH("ERROR", K2)))), "--", IF(OR(ISNUMBER(SEARCH("TIME OUT", F2)), ISNUMBER(SEARCH("ERROR", F2))), "QE", IF(OR(ISNUMBER(SEARCH("TIME OUT", K2)), ISNUMBER(SEARCH("ERROR", K2))), "RC", IF(V2=0, "TIE", IF(V2>0, "QE", "RC"))))) -> TIE | X2: =IF(V2="--","--",TEXT(MIN(F2,K2)/MAX(F2,K2),"0.000%")) -> 100.000% | Z2: =AVERAGE(C:C) -> 5.1233055e+09 | AA2: =AVERAGE(D:D) -> 73.36 | AB2: =AVERAGE(E:E) -> 51.585493 | AC2: =AVERAGE(F:F) -> 40459.089 | AD2: =AVERAGE(H:H) -> 19340267 | AE2: =AVERAGE(I:I) -> 0.23079286 | AF2: =AVERAGE(J:J) -> 0.22651429 | AG2: =AVERAGE(K:K) -> 210.42857 | AH2: =AVERAGE(M:M) -> 8652888.4 | AI2: =AVERAGE(P:P) -> 0.015171429 | AJ2: =AVERAGE(S:S) -> 0.0166 | AK2: =AVERAGE(V:V) -> -13.714286
A3: 19 | B3: [skoE, skoR, skoX] | C3: 25141407 | D3: 0.2218 | E3: 0.2208 | F3: 189 | G3: [skoE, skoR, skoX] | H3: 17427183 | I3: 0.2156 | J3: 0.2109 | K3: 189 | L3: =IF(OR(ISNUMBER(SEARCH("ERROR", B3)), ISNUMBER(SEARCH("ERROR", G3)), ISNUMBER(SEARCH("TIME OUT", B3)), ISNUMBER(SEARCH("TIME OUT", G3))), "--", B3=G3) -> TRUE | M3: =IF(OR(ISNUMBER(SEARCH("ERROR", C3)), ISNUMBER(SEARCH("ERROR", H3)), ISNUMBER(SEARCH("TIME OUT", C3)), ISNUMBER(SEARCH("TIME OUT", H3))),"--",C3-H3) -> 7714224 | N3: =IF(AND(OR(ISNUMBER(SEARCH("TIME OUT", C3)), ISNUMBER(SEARCH("ERROR", C3))), OR(ISNUMBER(SEARCH("TIME OUT", H3)), ISNUMBER(SEARCH("ERROR", H3)))), "--", IF(OR(ISNUMBER(SEARCH("TIME OUT", C3)), ISNUMBER(SEARCH("ERROR", C3))), "QE", IF(OR(ISNUMBER(SEARCH("TIME OUT", H3)), ISNUMBER(SEARCH("ERROR", H3))), "RC", IF(M3=0, "TIE", IF(M3>0, "QE", "RC"))))) -> QE | O3: =IF(M3="--","--",TEXT(MIN(C3,H3)/MAX(C3,H3),"0.000%")) -> 69.317% | P3: =IF(OR(ISNUMBER(SEARCH("ERROR", D3)), ISNUMBER(SEARCH("ERROR", I3)), ISNUMBER(SEARCH("TIME OUT", D3)), ISNUMBER(SEARCH("TIME OUT", I3))),"--",D3-I3) -> 0.0062 | Q3: =IF(AND(OR(ISNUMBER(SEARCH("TIME OUT", D3)), ISNUMBER(SEARCH("ERROR", D3))), OR(ISNUMBER(SEARCH("TIME OUT", I3)), ISNUMBER(SEARCH("ERROR", I3)))), "--", IF(OR(ISNUMBER(SEARCH("TIME OUT", D3)), ISNUMBER(SEARCH("ERROR", D3))), "QE", IF(OR(ISNUMBER(SEARCH("TIME OUT", I3)), ISNUMBER(SEARCH("ERROR", I3))), "RC", IF(P3=0, "TIE", IF(P3>0, "QE", "RC"))))) -> QE | R3: =IF(P3="--","--",TEXT(MIN(D3,I3)/MAX(D3,I3),"0.000%")) -> 97.205% | S3: =IF(OR(ISNUMBER(SEARCH("ERROR", E3)), ISNUMBER(SEARCH("ERROR", J3)), ISNUMBER(SEARCH("TIME OUT", E3)), ISNUMBER(SEARCH("TIME OUT", J3))),"--",E3-J3) -> 0.0099 | T3: =IF(AND(OR(ISNUMBER(SEARCH("TIME OUT", E3)), ISNUMBER(SEARCH("ERROR", E3))), OR(ISNUMBER(SEARCH("TIME OUT", J3)), ISNUMBER(SEARCH("ERROR", J3)))), "--", IF(OR(ISNUMBER(SEARCH("TIME OUT", E3)), ISNUMBER(SEARCH("ERROR", E3))), "QE", IF(OR(ISNUMBER(SEARCH("TIME OUT", J3)), ISNUMBER(SEARCH("ERROR", J3))), "RC", IF(S3=0, "TIE", IF(S3>0, "QE", "RC"))))) -> QE | U3: =IF(S3="--","--",TEXT(MIN(E3,J3)/MAX(E3,J3),"0.000%")) -> 95.516% | V3: =IF(OR(ISNUMBER(SEARCH("ERROR", F3)), ISNUMBER(SEARCH("ERROR", K3)), ISNUMBER(SEARCH("TIME OUT", F3)), ISNUMBER(SEARCH("TIME OUT", K3))),"--",F3-K3) -> 0 | W3: =IF(AND(OR(ISNUMBER(SEARCH("TIME OUT", F3)), ISNUMBER(SEARCH("ERROR", F3))), OR(ISNUMBER(SEARCH("TIME OUT", K3)), ISNUMBER(SEARCH("ERROR", K3)))), "--", IF(OR(ISNUMBER(SEARCH("TIME OUT", F3)), ISNUMBER(SEARCH("ERROR", F3))), "QE", IF(OR(ISNUMBER(SEARCH("TIME OUT", K3)), ISNUMBER(SEARCH("ERROR", K3))), "RC", IF(V3=0, "TIE", IF(V3>0, "QE", "RC"))))) -> TIE | X3: =IF(V3="--","--",TEXT(MIN(F3,K3)/MAX(F3,K3),"0.000%")) -> 100.000%
A4: 20 | B4: [skoE, skoR, skoX] | C4: 47006724 | D4: 0.4343 | E4: 0.4274 | F4: 327 | G4: [skoE, skoR, skoX] | H4: 30564586 | I4: 0.3859 | J4: 0.3799 | K4: 327 | L4: =IF(OR(ISNUMBER(SEARCH("ERROR", B4)), ISNUMBER(SEARCH("ERROR", G4)), ISNUMBER(SEARCH("TIME OUT", B4)), ISNUMBER(SEARCH("TIME OUT", G4))), "--", B4=G4) -> TRUE | M4: =IF(OR(ISNUMBER(SEARCH("ERROR", C4)), ISNUMBER(SEARCH("ERROR", H4)), ISNUMBER(SEARCH("TIME OUT", C4)), ISNUMBER(SEARCH("TIME OUT", H4))),"--",C4-H4) -> 16442138 | N4: =IF(AND(OR(ISNUMBER(SEARCH("TIME OUT", C4)), ISNUMBER(SEARCH("ERROR", C4))), OR(ISNUMBER(SEARCH("TIME OUT", H4)), ISNUMBER(SEARCH("ERROR", H4)))), "--", IF(OR(ISNUMBER(SEARCH("TIME OUT", C4)), ISNUMBER(SEARCH("ERROR", C4))), "QE", IF(OR(ISNUMBER(SEARCH("TIME OUT", H4)), ISNUMBER(SEARCH("ERROR", H4))), "RC", IF(M4=0, "TIE", IF(M4>0, "QE", "RC"))))) -> QE | O4: =IF(M4="--","--",TEXT(MIN(C4,H4)/MAX(C4,H4),"0.000%")) -> 65.022% | P4: =IF(OR(ISNUMBER(SEARCH("ERROR", D4)), ISNUMBER(SEARCH("ERROR", I4)), ISNUMBER(SEARCH("TIME OUT", D4)), ISNUMBER(SEARCH("TIME OUT", I4))),"--",D4-I4) -> 0.0484 | Q4: =IF(AND(OR(ISNUMBER(SEARCH("TIME OUT", D4)), ISNUMBER(SEARCH("ERROR", D4))), OR(ISNUMBER(SEARCH("TIME OUT", I4)), ISNUMBER(SEARCH("ERROR", I4)))), "--", IF(OR(ISNUMBER(SEARCH("TIME OUT", D4)), ISNUMBER(SEARCH("ERROR", D4))), "QE", IF(OR(ISNUMBER(SEARCH("TIME OUT", I4)), ISNUMBER(SEARCH("ERROR", I4))), "RC", IF(P4=0, "TIE", IF(P4>0, "QE", "RC"))))) -> QE | R4: =IF(P4="--","--",TEXT(MIN(D4,I4)/MAX(D4,I4),"0.000%")) -> 88.856% | S4: =IF(OR(ISNUMBER(SEARCH("ERROR", E4)), ISNUMBER(SEARCH("ERROR", J4)), ISNUMBER(SEARCH("TIME OUT", E4)), ISNUMBER(SEARCH("TIME OUT", J4))),"--",E4-J4) -> 0.0475 | T4: =IF(AND(OR(ISNUMBER(SEARCH("TIME OUT", E4)), ISNUMBER(SEARCH("ERROR", E4))), OR(ISNUMBER(SEARCH("TIME OUT", J4)), ISNUMBER(SEARCH("ERROR", J4)))), "--", IF(OR(ISNUMBER(SEARCH("TIME OUT", E4)), ISNUMBER(SEARCH("ERROR", E4))), "QE", IF(OR(ISNUMBER(SEARCH("TIME OUT", J4)), ISNUMBER(SEARCH("ERROR", J4))), "RC", IF(S4=0, "TIE", IF(S4>0, "QE", "RC"))))) -> QE | U4: =IF(S4="--","--",TEXT(MIN(E4,J4)/MAX(E4,J4),"0.000%")) -> 88.886% | V4: =IF(OR(ISNUMBER(SEARCH("ERROR", F4)), ISNUMBER(SEARCH("ERROR", K4)), ISNUMBER(SEARCH("TIME OUT", F4)), ISNUMBER(SEARCH("TIME OUT", K4))),"--",F4-K4) -> 0 | W4: =IF(AND(OR(ISNUMBER(SEARCH("TIME OUT", F4)), ISNUMBER(SEARCH("ERROR", F4))), OR(ISNUMBER(SEARCH("TIME OUT", K4)), ISNUMBER(SEARCH("ERROR", K4)))), "--", IF(OR(ISNUMBER(SEARCH("TIME OUT", F4)), ISNUMBER(SEARCH("ERROR", F4))), "QE", IF(OR(ISNUMBER(SEARCH("TIME OUT", K4)), ISNUMBER(SEARCH("ERROR", K4))), "RC", IF(V4=0, "TIE", IF(V4>0, "QE", "RC"))))) -> TIE | X4: =IF(V4="--","--",TEXT(MIN(F4,K4)/MAX(F4,K4),"0.000%")) -> 100.000%
A5: 22 | B5: [skoE, skoR, skoX] | C5: 46986784 | D5: 0.4313 | E5: 0.428 | F5: 327 | G5: [skoE, skoR, skoX] | H5: 30558938 | I5: 0.3687 | J5: 0.3648 | K5: 327 | L5: =IF(OR(ISNUMBER(SEARCH("ERROR", B5)), ISNUMBER(SEARCH("ERROR", G5)), ISNUMBER(SEARCH("TIME OUT", B5)), ISNUMBER(SEARCH("TIME OUT", G5))), "--", B5=G5) -> TRUE | M5: =IF(OR(ISNUMBER(SEARCH("ERROR", C5)), ISNUMBER(SEARCH("ERROR", H5)), ISNUMBER(SEARCH("TIME OUT", C5)), ISNUMBER(SEARCH("TIME OUT", H5))),"--",C5-H5) -> 16427846 | N5: =IF(AND(OR(ISNUMBER(SEARCH("TIME OUT", C5)), ISNUMBER(SEARCH("ERROR", C5))), OR(ISNUMBER(SEARCH("TIME OUT", H5)), ISNUMBER(SEARCH("ERROR", H5)))), "--", IF(OR(ISNUMBER(SEARCH("TIME OUT", C5)), ISNUMBER(SEARCH("ERROR", C5))), "QE", IF(OR(ISNUMBER(SEARCH("TIME OUT", H5)), ISNUMBER(SEARCH("ERROR", H5))), "RC", IF(M5=0, "TIE", IF(M5>0, "QE", "RC"))))) -> QE | O5: =IF(M5="--","--",TEXT(MIN(C5,H5)/MAX(C5,H5),"0.000%")) -> 65.037% | P5: =IF(OR(ISNUMBER(SEARCH("ERROR", D5)), ISNUMBER(SEARCH("ERROR", I5)), ISNUMBER(SEARCH("TIME OUT", D5)), ISNUMBER(SEARCH("TIME OUT", I5))),"--",D5-I5) -> 0.0626 | Q5: =IF(AND(OR(ISNUMBER(SEARCH("TIME OUT", D5)), ISNUMBER(SEARCH("ERROR", D5))), OR(ISNUMBER(SEARCH("TIME OUT", I5)), ISNUMBER(SEARCH("ERROR", I5)))), "--", IF(OR(ISNUMBER(SEARCH("TIME OUT", D5)), ISNUMBER(SEARCH("ERROR", D5))), "QE", IF(OR(ISNUMBER(SEARCH("TIME OUT", I5)), ISNUMBER(SEARCH("ERROR", I5))), "RC", IF(P5=0, "TIE", IF(P5>0, "QE", "RC"))))) -> QE | R5: =IF(P5="--","--",TEXT(MIN(D5,I5)/MAX(D5,I5),"0.000%")) -> 85.486% | S5: =IF(OR(ISNUMBER(SEARCH("ERROR", E5)), ISNUMBER(SEARCH("ERROR", J5)), ISNUMBER(SEARCH("TIME OUT", E5)), ISNUMBER(SEARCH("TIME OUT", J5))),"--",E5-J5) -> 0.0632 | T5: =IF(AND(OR(ISNUMBER(SEARCH("TIME OUT", E5)), ISNUMBER(SEARCH("ERROR", E5))), OR(ISNUMBER(SEARCH("TIME OUT", J5)), ISNUMBER(SEARCH("ERROR", J5)))), "--", IF(OR(ISNUMBER(SEARCH("TIME OUT", E5)), ISNUMBER(SEARCH("ERROR", E5))), "QE", IF(OR(ISNUMBER(SEARCH("TIME OUT", J5)), ISNUMBER(SEARCH("ERROR", J5))), "RC", IF(S5=0, "TIE", IF(S5>0, "QE", "RC"))))) -> QE | U5: =IF(S5="--","--",TEXT(MIN(E5,J5)/MAX(E5,J5),"0.000%")) -> 85.234% | V5: =IF(OR(ISNUMBER(SEARCH("ERROR", F5)), ISNUMBER(SEARCH("ERROR", K5)), ISNUMBER(SEARCH("TIME OUT", F5)), ISNUMBER(SEARCH("TIME OUT", K5))),"--",F5-K5) -> 0 | W5: =IF(AND(OR(ISNUMBER(SEARCH("TIME OUT", F5)), ISNUMBER(SEARCH("ERROR", F5))), OR(ISNUMBER(SEARCH("TIME OUT", K5)), ISNUMBER(SEARCH("ERROR", K5)))), "--", IF(OR(ISNUMBER(SEARCH("TIME OUT", F5)), ISNUMBER(SEARCH("ERROR", F5))), "QE", IF(OR(ISNUMBER(SEARCH("TIME OUT", K5)), ISNUMBER(SEARCH("ERROR", K5))), "RC", IF(V5=0, "TIE", IF(V5>0, "QE", "RC"))))) -> TIE | X5: =IF(V5="--","--",TEXT(MIN(F5,K5)/MAX(F5,K5),"0.000%")) -> 100.000%
A6: 23 | B6: [skoE, skoR, skoX] | C6: 47018416 | D6: 0.4188 | E6: 0.4147 | F6: 327 | G6: [skoE, skoR, skoX] | H6: 30562685 | I6: 0.3704 | J6: 0.3625 | K6: 327 | L6: =IF(OR(ISNUMBER(SEARCH("ERROR", B6)), ISNUMBER(SEARCH("ERROR", G6)), ISNUMBER(SEARCH("TIME OUT", B6)), ISNUMBER(SEARCH("TIME OUT", G6))), "--", B6=G6) -> TRUE | M6: =IF(OR(ISNUMBER(SEARCH("ERROR", C6)), ISNUMBER(SEARCH("ERROR", H6)), ISNUMBER(SEARCH("TIME OUT", C6)), ISNUMBER(SEARCH("TIME OUT", H6))),"--",C6-H6) -> 16455731 | N6: =IF(AND(OR(ISNUMBER(SEARCH("TIME OUT", C6)), ISNUMBER(SEARCH("ERROR", C6))), OR(ISNUMBER(SEARCH("TIME OUT", H6)), ISNUMBER(SEARCH("ERROR", H6)))), "--", IF(OR(ISNUMBER(SEARCH("TIME OUT", C6)), ISNUMBER(SEARCH("ERROR", C6))), "QE", IF(OR(ISNUMBER(SEARCH("TIME OUT", H6)), ISNUMBER(SEARCH("ERROR", H6))), "RC", IF(M6=0, "TIE", IF(M6>0, "QE", "RC"))))) -> QE | O6: =IF(M6="--","--",TEXT(MIN(C6,H6)/MAX(C6,H6),"0.000%")) -> 65.002% | P6: =IF(OR(ISNUMBER(SEARCH("ERROR", D6)), ISNUMBER(SEARCH("ERROR", I6)), ISNUMBER(SEARCH("TIME OUT", D6)), ISNUMBER(SEARCH("TIME OUT", I6))),"--",D6-I6) -> 0.0484 | Q6: =IF(AND(OR(ISNUMBER(SEARCH("TIME OUT", D6)), ISNUMBER(SEARCH("ERROR", D6))), OR(ISNUMBER(SEARCH("TIME OUT", I6)), ISNUMBER(SEARCH("ERROR", I6)))), "--", IF(OR(ISNUMBER(SEARCH("TIME OUT", D6)), ISNUMBER(SEARCH("ERROR", D6))), "QE", IF(OR(ISNUMBER(SEARCH("TIME OUT", I6)), ISNUMBER(SEARCH("ERROR", I6))), "RC", IF(P6=0, "TIE", IF(P6>0, "QE", "RC"))))) -> QE | R6: =IF(P6="--","--",TEXT(MIN(D6,I6)/MAX(D6,I6),"0.000%")) -> 88.443% | S6: =IF(OR(ISNUMBER(SEARCH("ERROR", E6)), ISNUMBER(SEARCH("ERROR", J6)), ISNUMBER(SEARCH("TIME OUT", E6)), ISNUMBER(SEARCH("TIME OUT", J6))),"--",E6-J6) -> 0.0522 | T6: =IF(AND(OR(ISNUMBER(SEARCH("TIME OUT", E6)), ISNUMBER(SEARCH("ERROR", E6))), OR(ISNUMBER(SEARCH("TIME OUT", J6)), ISNUMBER(SEARCH("ERROR", J6)))), "--", IF(OR(ISNUMBER(SEARCH("TIME OUT", E6)), ISNUMBER(SEARCH("ERROR", E6))), "QE", IF(OR(ISNUMBER(SEARCH("TIME OUT", J6)), ISNUMBER(SEARCH("ERROR", J6))), "RC", IF(S6=0, "TIE", IF(S6>0, "QE", "RC"))))) -> QE | U6: =IF(S6="--","--",TEXT(MIN(E6,J6)/MAX(E6,J6),"0.000%")) -> 87.413% | V6: =IF(OR(ISNUMBER(SEARCH("ERROR", F6)), ISNUMBER(SEARCH("ERROR", K6)), ISNUMBER(SEARCH("TIME OUT", F6)), ISNUMBER(SEARCH("TIME OUT", K6))),"--",F6-K6) -> 0 | W6: =IF(AND(OR(ISNUMBER(SEARCH("TIME OUT", F6)), ISNUMBER(SEARCH("ERROR", F6))), OR(ISNUMBER(SEARCH("TIME OUT", K6)), ISNUMBER(SEARCH("ERROR", K6)))), "--", IF(OR(ISNUMBER(SEARCH("TIME OUT", F6)), ISNUMBER(SEARCH("ERROR", F6))), "QE", IF(OR(ISNUMBER(SEARCH("TIME OUT", K6)), ISNUMBER(SEARCH("ERROR", K6))), "RC", IF(V6=0, "TIE", IF(V6>0, "QE", "RC"))))) -> TIE | X6: =IF(V6="--","--",TEXT(MIN(F6,K6)/MAX(F6,K6),"0.000%")) -> 100.000% | AA6: memory | AC6: cputime | AE6: realtime | AG6: cells | AJ6: Successes | AL6: Timeouts | AN6: Errors | AP6: Total
A7: 25 | B7: [skoE, skoR, skoX] | C7: 1747240238 | D7: 20.2843 | E7: 16.6554 | F7: 13005 | G7: TIME OUT | H7: TIME OUT | I7: TIME OUT | J7: TIME OUT | K7: TIME OUT | L7: =IF(OR(ISNUMBER(SEARCH("ERROR", B7)), ISNUMBER(SEARCH("ERROR", G7)), ISNUMBER(SEARCH("TIME OUT", B7)), ISNUMBER(SEARCH("TIME OUT", G7))), "--", B7=G7) -> -- | M7: =IF(OR(ISNUMBER(SEARCH("ERROR", C7)), ISNUMBER(SEARCH("ERROR", H7)), ISNUMBER(SEARCH("TIME OUT", C7)), ISNUMBER(SEARCH("TIME OUT", H7))),"--",C7-H7) -> -- | N7: =IF(AND(OR(ISNUMBER(SEARCH("TIME OUT", C7)), ISNUMBER(SEARCH("ERROR", C7))), OR(ISNUMBER(SEARCH("TIME OUT", H7)), ISNUMBER(SEARCH("ERROR", H7)))), "--", IF(OR(ISNUMBER(SEARCH("TIME OUT", C7)), ISNUMBER(SEARCH("ERROR", C7))), "QE", IF(OR(ISNUMBER(SEARCH("TIME OUT", H7)), ISNUMBER(SEARCH("ERROR", H7))), "RC", IF(M7=0, "TIE", IF(M7>0, "QE", "RC"))))) -> RC | O7: =IF(M7="--","--",TEXT(MIN(C7,H7)/MAX(C7,H7),"0.000%")) -> -- | P7: =IF(OR(ISNUMBER(SEARCH("ERROR", D7)), ISNUMBER(SEARCH("ERROR", I7)), ISNUMBER(SEARCH("TIME OUT", D7)), ISNUMBER(SEARCH("TIME OUT", I7))),"--",D7-I7) -> -- | Q7: =IF(AND(OR(ISNUMBER(SEARCH("TIME OUT", D7)), ISNUMBER(SEARCH("ERROR", D7))), OR(ISNUMBER(SEARCH("TIME OUT", I7)), ISNUMBER(SEARCH("ERROR", I7)))), "--", IF(OR(ISNUMBER(SEARCH("TIME OUT", D7)), ISNUMBER(SEARCH("ERROR", D7))), "QE", IF(OR(ISNUMBER(SEARCH("TIME OUT", I7)), ISNUMBER(SEARCH("ERROR", I7))), "RC", IF(P7=0, "TIE", IF(P7>0, "QE", "RC"))))) -> RC | R7: =IF(P7="--","--",TEXT(MIN(D7,I7)/MAX(D7,I7),"0.000%")) -> -- | S7: =IF(OR(ISNUMBER(SEARCH("ERROR", E7)), ISNUMBER(SEARCH("ERROR", J7)), ISNUMBER(SEARCH("TIME OUT", E7)), ISNUMBER(SEARCH("TIME OUT", J7))),"--",E7-J7) -> -- | T7: =IF(AND(OR(ISNUMBER(SEARCH("TIME OUT", E7)), ISNUMBER(SEARCH("ERROR", E7))), OR(ISNUMBER(SEARCH("TIME OUT", J7)), ISNUMBER(SEARCH("ERROR", J7)))), "--", IF(OR(ISNUMBER(SEARCH("TIME OUT", E7)), ISNUMBER(SEARCH("ERROR", E7))), "QE", IF(OR(ISNUMBER(SEARCH("TIME OUT", J7)), ISNUMBER(SEARCH("ERROR", J7))), "RC", IF(S7=0, "TIE", IF(S7>0, "QE", "RC"))))) -> RC | U7: =IF(S7="--","--",TEXT(MIN(E7,J7)/MAX(E7,J7),"0.000%")) -> -- | V7: =IF(OR(ISNUMBER(SEARCH("ERROR", F7)), ISNUMBER(SEARCH("ERROR", K7)), ISNUMBER(SEARCH("TIME OUT", F7)), ISNUMBER(SEARCH("TIME OUT", K7))),"--",F7-K7) -> -- | W7: =IF(AND(OR(ISNUMBER(SEARCH("TIME OUT", F7)), ISNUMBER(SEARCH("ERROR", F7))), OR(ISNUMBER(SEARCH("TIME OUT", K7)), ISNUMBER(SEARCH("ERROR", K7)))), "--", IF(OR(ISNUMBER(SEARCH("TIME OUT", F7)), ISNUMBER(SEARCH("ERROR", F7))), "QE", IF(OR(ISNUMBER(SEARCH("TIME OUT", K7)), ISNUMBER(SEARCH("ERROR", K7))), "RC", IF(V7=0, "TIE", IF(V7>0, "QE", "RC"))))) -> RC | X7: =IF(V7="--","--",TEXT(MIN(F7,K7)/MAX(F7,K7),"0.000%")) -> -- | Z7: RC | AA7: =COUNTIF(N:N,$Z7) -> 35 | AB7: =AA7/AA$11 -> 0.52238806 | AC7: =COUNTIF(Q:Q,$Z7) -> 35 | AD7: =AC7/AC$11 -> 0.52238806 | AE7: =COUNTIF(T:T,$Z7) -> 35 | AF7: =AE7/AE$11 -> 0.52238806 | AG7: =COUNTIF(W:W,$Z7) -> 35 | AH7: =AG7/AG$11 -> 0.52238806 | AJ7: =COUNTA(B2:B68)-COUNTIF(B2:B68,"*TIME OUT*")-COUNTIF(B2:B68,"*ERROR*") -> 45 | AK7: =AJ7/67 -> 0.67164179 | AL7: =COUNTIF(B2:B68,"*TIME OUT*") -> 21 | AM7: =AL7/67 -> 0.31343284 | AN7: =COUNTIF(B2:B68,"*ERROR*") -> 1 | AO7: =AN7/67 -> 0.014925373 | AP7: =AJ7+AL7+AN7 -> 67 | AQ7: =AK7+AM7+AO7 -> 1
A8: 26 | B8: [skoE, skoR, skoX] | C8: 2329616 | D8: 0.0171 | E8: 0.0166 | F8: 9 | G8: [skoE, skoR, skoX] | H8: 4424962 | I8: 0.05 | J8: 0.0486 | K8: 57 | L8: =IF(OR(ISNUMBER(SEARCH("ERROR", B8)), ISNUMBER(SEARCH("ERROR", G8)), ISNUMBER(SEARCH("TIME OUT", B8)), ISNUMBER(SEARCH("TIME OUT", G8))), "--", B8=G8) -> TRUE | M8: =IF(OR(ISNUMBER(SEARCH("ERROR", C8)), ISNUMBER(SEARCH("ERROR", H8)), ISNUMBER(SEARCH("TIME OUT", C8)), ISNUMBER(SEARCH("TIME OUT", H8))),"--",C8-H8) -> -2095346 | N8: =IF(AND(OR(ISNUMBER(SEARCH("TIME OUT", C8)), ISNUMBER(SEARCH("ERROR", C8))), OR(ISNUMBER(SEARCH("TIME OUT", H8)), ISNUMBER(SEARCH("ERROR", H8)))), "--", IF(OR(ISNUMBER(SEARCH("TIME OUT", C8)), ISNUMBER(SEARCH("ERROR", C8))), "QE", IF(OR(ISNUMBER(SEARCH("TIME OUT", H8)), ISNUMBER(SEARCH("ERROR", H8))), "RC", IF(M8=0, "TIE", IF(M8>0, "QE", "RC"))))) -> RC | O8: =IF(M8="--","--",TEXT(MIN(C8,H8)/MAX(C8,H8),"0.000%")) -> 52.647% | P8: =IF(OR(ISNUMBER(SEARCH("ERROR", D8)), ISNUMBER(SEARCH("ERROR", I8)), ISNUMBER(SEARCH("TIME OUT", D8)), ISNUMBER(SEARCH("TIME OUT", I8))),"--",D8-I8) -> -0.0329 | Q8: =IF(AND(OR(ISNUMBER(SEARCH("TIME OUT", D8)), ISNUMBER(SEARCH("ERROR", D8))), OR(ISNUMBER(SEARCH("TIME OUT", I8)), ISNUMBER(SEARCH("ERROR", I8)))), "--", IF(OR(ISNUMBER(SEARCH("TIME OUT", D8)), ISNUMBER(SEARCH("ERROR", D8))), "QE", IF(OR(ISNUMBER(SEARCH("TIME OUT", I8)), ISNUMBER(SEARCH("ERROR", I8))), "RC", IF(P8=0, "TIE", IF(P8>0, "QE", "RC"))))) -> RC | R8: =IF(P8="--","--",TEXT(MIN(D8,I8)/MAX(D8,I8),"0.000%")) -> 34.200% | S8: =IF(OR(ISNUMBER(SEARCH("ERROR", E8)), ISNUMBER(SEARCH("ERROR", J8)), ISNUMBER(SEARCH("TIME OUT", E8)), ISNUMBER(SEARCH("TIME OUT", J8))),"--",E8-J8) -> -0.032 | T8: =IF(AND(OR(ISNUMBER(SEARCH("TIME OUT", E8)), ISNUMBER(SEARCH("ERROR", E8))), OR(ISNUMBER(SEARCH("TIME OUT", J8)), ISNUMBER(SEARCH("ERROR", J8)))), "--", IF(OR(ISNUMBER(SEARCH("TIME OUT", E8)), ISNUMBER(SEARCH("ERROR", E8))), "QE", IF(OR(ISNUMBER(SEARCH("TIME OUT", J8)), ISNUMBER(SEARCH("ERROR", J8))), "RC", IF(S8=0, "TIE", IF(S8>0, "QE", "RC"))))) -> RC | U8: =IF(S8="--","--",TEXT(MIN(E8,J8)/MAX(E8,J8),"0.000%")) -> 34.156% | V8: =IF(OR(ISNUMBER(SEARCH("ERROR", F8)), ISNUMBER(SEARCH("ERROR", K8)), ISNUMBER(SEARCH("TIME OUT", F8)), ISNUMBER(SEARCH("TIME OUT", K8))),"--",F8-K8) -> -48 | W8: =IF(AND(OR(ISNUMBER(SEARCH("TIME OUT", F8)), ISNUMBER(SEARCH("ERROR", F8))), OR(ISNUMBER(SEARCH("TIME OUT", K8)), ISNUMBER(SEARCH("ERROR", K8)))), "--", IF(OR(ISNUMBER(SEARCH("TIME OUT", F8)), ISNUMBER(SEARCH("ERROR", F8))), "QE", IF(OR(ISNUMBER(SEARCH("TIME OUT", K8)), ISNUMBER(SEARCH("ERROR", K8))), "RC", IF(V8=0, "TIE", IF(V8>0, "QE", "RC"))))) -> RC | X8: =IF(V8="--","--",TEXT(MIN(F8,K8)/MAX(F8,K8),"0.000%")) -> 15.789% | Z8: QE | AA8: =COUNTIF(N:N,$Z8) -> 10 | AB8: =AA8/AA$11 -> 0.14925373 | AC8: =COUNTIF(Q:Q,$Z8) -> 10 | AD8: =AC8/AC$11 -> 0.14925373 | AE8: =COUNTIF(T:T,$Z8) -> 10 | AF8: =AE8/AE$11 -> 0.14925373 | AG8: =COUNTIF(W:W,$Z8) -> 0 | AH8: =AG8/AG$11 -> 0 | AJ8: =COUNTA(G2:G68)-COUNTIF(G2:G68,"*TIME OUT*")-COUNTIF(G2:G68,"*ERROR*") -> 14 | AK8: =AJ8/67 -> 0.20895522 | AL8: =COUNTIF(G2:G68,"*TIME OUT*") -> 21 | AM8: =AL8/67 -> 0.31343284 | AN8: =COUNTIF(G2:G68,"*ERROR*") -> 32 | AO8: =AN8/67 -> 0.47761194 | AP8: =AJ8+AL8+AN8 -> 67 | AQ8: =AK8+AM8+AO8 -> 1
A9: 27 | B9: [skoE, skoR, skoX] | C9: 1747272133 | D9: 20.5609 | E9: 16.9047 | F9: 13005 | G9: TIME OUT | H9: TIME OUT | I9: TIME OUT | J9: TIME OUT | K9: TIME OUT | L9: =IF(OR(ISNUMBER(SEARCH("ERROR", B9)), ISNUMBER(SEARCH("ERROR", G9)), ISNUMBER(SEARCH("TIME OUT", B9)), ISNUMBER(SEARCH("TIME OUT", G9))), "--", B9=G9) -> -- | M9: =IF(OR(ISNUMBER(SEARCH("ERROR", C9)), ISNUMBER(SEARCH("ERROR", H9)), ISNUMBER(SEARCH("TIME OUT", C9)), ISNUMBER(SEARCH("TIME OUT", H9))),"--",C9-H9) -> -- | N9: =IF(AND(OR(ISNUMBER(SEARCH("TIME OUT", C9)), ISNUMBER(SEARCH("ERROR", C9))), OR(ISNUMBER(SEARCH("TIME OUT", H9)), ISNUMBER(SEARCH("ERROR", H9)))), "--", IF(OR(ISNUMBER(SEARCH("TIME OUT", C9)), ISNUMBER(SEARCH("ERROR", C9))), "QE", IF(OR(ISNUMBER(SEARCH("TIME OUT", H9)), ISNUMBER(SEARCH("ERROR", H9))), "RC", IF(M9=0, "TIE", IF(M9>0, "QE", "RC"))))) -> RC | O9: =IF(M9="--","--",TEXT(MIN(C9,H9)/MAX(C9,H9),"0.000%")) -> -- | P9: =IF(OR(ISNUMBER(SEARCH("ERROR", D9)), ISNUMBER(SEARCH("ERROR", I9)), ISNUMBER(SEARCH("TIME OUT", D9)), ISNUMBER(SEARCH("TIME OUT", I9))),"--",D9-I9) -> -- | Q9: =IF(AND(OR(ISNUMBER(SEARCH("TIME OUT", D9)), ISNUMBER(SEARCH("ERROR", D9))), OR(ISNUMBER(SEARCH("TIME OUT", I9)), ISNUMBER(SEARCH("ERROR", I9)))), "--", IF(OR(ISNUMBER(SEARCH("TIME OUT", D9)), ISNUMBER(SEARCH("ERROR", D9))), "QE", IF(OR(ISNUMBER(SEARCH("TIME OUT", I9)), ISNUMBER(SEARCH("ERROR", I9))), "RC", IF(P9=0, "TIE", IF(P9>0, "QE", "RC"))))) -> RC | R9: =IF(P9="--","--",TEXT(MIN(D9,I9)/MAX(D9,I9),"0.000%")) -> -- | S9: =IF(OR(ISNUMBER(SEARCH("ERROR", E9)), ISNUMBER(SEARCH("ERROR", J9)), ISNUMBER(SEARCH("TIME OUT", E9)), ISNUMBER(SEARCH("TIME OUT", J9))),"--",E9-J9) -> -- | T9: =IF(AND(OR(ISNUMBER(SEARCH("TIME OUT", E9)), ISNUMBER(SEARCH("ERROR", E9))), OR(ISNUMBER(SEARCH("TIME OUT", J9)), ISNUMBER(SEARCH("ERROR", J9)))), "--", IF(OR(ISNUMBER(SEARCH("TIME OUT", E9)), ISNUMBER(SEARCH("ERROR", E9))), "QE", IF(OR(ISNUMBER(SEARCH("TIME OUT", J9)), ISNUMBER(SEARCH("ERROR", J9))), "RC", IF(S9=0, "TIE", IF(S9>0, "QE", "RC"))))) -> RC | U9: =IF(S9="--","--",TEXT(MIN(E9,J9)/MAX(E9,J9),"0.000%")) -> -- | V9: =IF(OR(ISNUMBER(SEARCH("ERROR", F9)), ISNUMBER(SEARCH("ERROR", K9)), ISNUMBER(SEARCH("TIME OUT", F9)), ISNUMBER(SEARCH("TIME OUT", K9))),"--",F9-K9) -> -- | W9: =IF(AND(OR(ISNUMBER(SEARCH("TIME OUT", F9)), ISNUMBER(SEARCH("ERROR", F9))), OR(ISNUMBER(SEARCH("TIME OUT", K9)), ISNUMBER(SEARCH("ERROR", K9)))), "--", IF(OR(ISNUMBER(SEARCH("TIME OUT", F9)), ISNUMBER(SEARCH("ERROR", F9))), "QE", IF(OR(ISNUMBER(SEARCH("TIME OUT", K9)), ISNUMBER(SEARCH("ERROR", K9))), "RC", IF(V9=0, "TIE", IF(V9>0, "QE", "RC"))))) -> RC | X9: =IF(V9="--","--",TEXT(MIN(F9,K9)/MAX(F9,K9),"0.000%")) -> -- | Z9: TIE | AA9: =COUNTIF(N:N,$Z9) -> 0 | AB9: =AA9/AA$11 -> 0 | AC9: =COUNTIF(Q:Q,$Z9) -> 0 | AD9: =AC9/AC$11 -> 0 | AE9: =COUNTIF(T:T,$Z9) -> 0 | AF9: =AE9/AE$11 -> 0 | AG9: =COUNTIF(W:W,$Z9) -> 10 | AH9: =AG9/AG$11 -> 0.14925373
A10: 28 | B10: [skoE, skoR, skoX] | C10: 1729110988 | D10: 19.9157 | E10: 16.2376 | F10: 13005 | G10: TIME OUT | H10: TIME OUT | I10: TIME OUT | J10: TIME OUT | K10: TIME OUT | L10: =IF(OR(ISNUMBER(SEARCH("ERROR", B10)), ISNUMBER(SEARCH("ERROR", G10)), ISNUMBER(SEARCH("TIME OUT", B10)), ISNUMBER(SEARCH("TIME OUT", G10))), "--", B10=G10) -> -- | M10: =IF(OR(ISNUMBER(SEARCH("ERROR", C10)), ISNUMBER(SEARCH("ERROR", H10)), ISNUMBER(SEARCH("TIME OUT", C10)), ISNUMBER(SEARCH("TIME OUT", H10))),"--",C10-H10) -> -- | N10: =IF(AND(OR(ISNUMBER(SEARCH("TIME OUT", C10)), ISNUMBER(SEARCH("ERROR", C10))), OR(ISNUMBER(SEARCH("TIME OUT", H10)), ISNUMBER(SEARCH("ERROR", H10)))), "--", IF(OR(ISNUMBER(SEARCH("TIME OUT", C10)), ISNUMBER(SEARCH("ERROR", C10))), "QE", IF(OR(ISNUMBER(SEARCH("TIME OUT", H10)), ISNUMBER(SEARCH("ERROR", H10))), "RC", IF(M10=0, "TIE", IF(M10>0, "QE", "RC"))))) -> RC | O10: =IF(M10="--","--",TEXT(MIN(C10,H10)/MAX(C10,H10),"0.000%")) -> -- | P10: =IF(OR(ISNUMBER(SEARCH("ERROR", D10)), ISNUMBER(SEARCH("ERROR", I10)), ISNUMBER(SEARCH("TIME OUT", D10)), ISNUMBER(SEARCH("TIME OUT", I10))),"--",D10-I10) -> -- | Q10: =IF(AND(OR(ISNUMBER(SEARCH("TIME OUT", D10)), ISNUMBER(SEARCH("ERROR", D10))), OR(ISNUMBER(SEARCH("TIME OUT", I10)), ISNUMBER(SEARCH("ERROR", I10)))), "--", IF(OR(ISNUMBER(SEARCH("TIME OUT", D10)), ISNUMBER(SEARCH("ERROR", D10))), "QE", IF(OR(ISNUMBER(SEARCH("TIME OUT", I10)), ISNUMBER(SEARCH("ERROR", I10))), "RC", IF(P10=0, "TIE", IF(P10>0, "QE", "RC"))))) -> RC | R10: =IF(P10="--","--",TEXT(MIN(D10,I10)/MAX(D10,I10),"0.000%")) -> -- | S10: =IF(OR(ISNUMBER(SEARCH("ERROR", E10)), ISNUMBER(SEARCH("ERROR", J10)), ISNUMBER(SEARCH("TIME OUT", E10)), ISNUMBER(SEARCH("TIME OUT", J10))),"--",E10-J10) -> -- | T10: =IF(AND(OR(ISNUMBER(SEARCH("TIME OUT", E10)), ISNUMBER(SEARCH("ERROR", E10))), OR(ISNUMBER(SEARCH("TIME OUT", J10)), ISNUMBER(SEARCH("ERROR", J10)))), "--", IF(OR(ISNUMBER(SEARCH("TIME OUT", E10)), ISNUMBER(SEARCH("ERROR", E10))), "QE", IF(OR(ISNUMBER(SEARCH("TIME OUT", J10)), ISNUMBER(SEARCH("ERROR", J10))), "RC", IF(S10=0, "TIE", IF(S10>0, "QE", "RC"))))) -> RC | U10: =IF(S10="--","--",TEXT(MIN(E10,J10)/MAX(E10,J10),"0.000%")) -> -- | V10: =IF(OR(ISNUMBER(SEARCH("ERROR", F10)), ISNUMBER(SEARCH("ERROR", K10)), ISNUMBER(SEARCH("TIME OUT", F10)), ISNUMBER(SEARCH("TIME OUT", K10))),"--",F10-K10) -> -- | W10: =IF(AND(OR(ISNUMBER(SEARCH("TIME OUT", F10)), ISNUMBER(SEARCH("ERROR", F10))), OR(ISNUMBER(SEARCH("TIME OUT", K10)), ISNUMBER(SEARCH("ERROR", K10)))), "--", IF(OR(ISNUMBER(SEARCH("TIME OUT", F10)), ISNUMBER(SEARCH("ERROR", F10))), "QE", IF(OR(ISNUMBER(SEARCH("TIME OUT", K10)), ISNUMBER(SEARCH("ERROR", K10))), "RC", IF(V10=0, "TIE", IF(V10>0, "QE", "RC"))))) -> RC | X10: =IF(V10="--","--",TEXT(MIN(F10,K10)/MAX(F10,K10),"0.000%")) -> -- | Z10: -- | AA10: =COUNTIF(N:N,$Z10) -> 22 | AB10: =AA10/AA$11 -> 0.32835821 | AC10: =COUNTIF(Q:Q,$Z10) -> 22 | AD10: =AC10/AC$11 -> 0.32835821 | AE10: =COUNTIF(T:T,$Z10) -> 22 | AF10: =AE10/AE$11 -> 0.32835821 | AG10: =COUNTIF(W:W,$Z10) -> 22 | AH10: =AG10/AG$11 -> 0.32835821
A11: 29 | B11: [skoE, skoR, skoX] | C11: 1746753072 | D11: 19.8406 | E11: 16.1698 | F11: 13005 | G11: TIME OUT | H11: TIME OUT | I11: TIME OUT | J11: TIME OUT | K11: TIME OUT | L11: =IF(OR(ISNUMBER(SEARCH("ERROR", B11)), ISNUMBER(SEARCH("ERROR", G11)), ISNUMBER(SEARCH("TIME OUT", B11)), ISNUMBER(SEARCH("TIME OUT", G11))), "--", B11=G11) -> -- | M11: =IF(OR(ISNUMBER(SEARCH("ERROR", C11)), ISNUMBER(SEARCH("ERROR", H11)), ISNUMBER(SEARCH("TIME OUT", C11)), ISNUMBER(SEARCH("TIME OUT", H11))),"--",C11-H11) -> -- | N11: =IF(AND(OR(ISNUMBER(SEARCH("TIME OUT", C11)), ISNUMBER(SEARCH("ERROR", C11))), OR(ISNUMBER(SEARCH("TIME OUT", H11)), ISNUMBER(SEARCH("ERROR", H11)))), "--", IF(OR(ISNUMBER(SEARCH("TIME OUT", C11)), ISNUMBER(SEARCH("ERROR", C11))), "QE", IF(OR(ISNUMBER(SEARCH("TIME OUT", H11)), ISNUMBER(SEARCH("ERROR", H11))), "RC", IF(M11=0, "TIE", IF(M11>0, "QE", "RC"))))) -> RC | O11: =IF(M11="--","--",TEXT(MIN(C11,H11)/MAX(C11,H11),"0.000%")) -> -- | P11: =IF(OR(ISNUMBER(SEARCH("ERROR", D11)), ISNUMBER(SEARCH("ERROR", I11)), ISNUMBER(SEARCH("TIME OUT", D11)), ISNUMBER(SEARCH("TIME OUT", I11))),"--",D11-I11) -> -- | Q11: =IF(AND(OR(ISNUMBER(SEARCH("TIME OUT", D11)), ISNUMBER(SEARCH("ERROR", D11))), OR(ISNUMBER(SEARCH("TIME OUT", I11)), ISNUMBER(SEARCH("ERROR", I11)))), "--", IF(OR(ISNUMBER(SEARCH("TIME OUT", D11)), ISNUMBER(SEARCH("ERROR", D11))), "QE", IF(OR(ISNUMBER(SEARCH("TIME OUT", I11)), ISNUMBER(SEARCH("ERROR", I11))), "RC", IF(P11=0, "TIE", IF(P11>0, "QE", "RC"))))) -> RC | R11: =IF(P11="--","--",TEXT(MIN(D11,I11)/MAX(D11,I11),"0.000%")) -> -- | S11: =IF(OR(ISNUMBER(SEARCH("ERROR", E11)), ISNUMBER(SEARCH("ERROR", J11)), ISNUMBER(SEARCH("TIME OUT", E11)), ISNUMBER(SEARCH("TIME OUT", J11))),"--",E11-J11) -> -- | T11: =IF(AND(OR(ISNUMBER(SEARCH("TIME OUT", E11)), ISNUMBER(SEARCH("ERROR", E11))), OR(ISNUMBER(SEARCH("TIME OUT", J11)), ISNUMBER(SEARCH("ERROR", J11)))), "--", IF(OR(ISNUMBER(SEARCH("TIME OUT", E11)), ISNUMBER(SEARCH("ERROR", E11))), "QE", IF(OR(ISNUMBER(SEARCH("TIME OUT", J11)), ISNUMBER(SEARCH("ERROR", J11))), "RC", IF(S11=0, "TIE", IF(S11>0, "QE", "RC"))))) -> RC | U11: =IF(S11="--","--",TEXT(MIN(E11,J11)/MAX(E11,J11),"0.000%")) -> -- | V11: =IF(OR(ISNUMBER(SEARCH("ERROR", F11)), ISNUMBER(SEARCH("ERROR", K11)), ISNUMBER(SEARCH("TIME OUT", F11)), ISNUMBER(SEARCH("TIME OUT", K11))),"--",F11-K11) -> -- | W11: =IF(AND(OR(ISNUMBER(SEARCH("TIME OUT", F11)), ISNUMBER(SEARCH("ERROR", F11))), OR(ISNUMBER(SEARCH("TIME OUT", K11)), ISNUMBER(SEARCH("ERROR", K11)))), "--", IF(OR(ISNUMBER(SEARCH("TIME OUT", F11)), ISNUMBER(SEARCH("ERROR", F11))), "QE", IF(OR(ISNUMBER(SEARCH("TIME OUT", K11)), ISNUMBER(SEARCH("ERROR", K11))), "RC", IF(V11=0, "TIE", IF(V11>0, "QE", "RC"))))) -> RC | X11: =IF(V11="--","--",TEXT(MIN(F11,K11)/MAX(F11,K11),"0.000%")) -> -- | Z11: total | AA11: =COUNTA(N:N)-1 -> 67 | AB11: =AA11/AA$11 -> 1 | AC11: =COUNTA(O:O)-1 -> 67 | AD11: =AC11/AC$11 -> 1 | AE11: =COUNTA(P:P)-1 -> 67 | AF11: =AE11/AE$11 -> 1 | AG11: =COUNTA(Q:Q)-1 -> 67 | AH11: =AG11/AG$11 -> 1
A12: 30 | B12: [skoE, skoR, skoX] | C12: 1745207882 | D12: 19.9687 | E12: 16.3587 | F12: 13005 | G12: TIME OUT | H12: TIME OUT | I12: TIME OUT | J12: TIME OUT | K12: TIME OUT | L12: =IF(OR(ISNUMBER(SEARCH("ERROR", B12)), ISNUMBER(SEARCH("ERROR", G12)), ISNUMBER(SEARCH("TIME OUT", B12)), ISNUMBER(SEARCH("TIME OUT", G12))), "--", B12=G12) -> -- | M12: =IF(OR(ISNUMBER(SEARCH("ERROR", C12)), ISNUMBER(SEARCH("ERROR", H12)), ISNUMBER(SEARCH("TIME OUT", C12)), ISNUMBER(SEARCH("TIME OUT", H12))),"--",C12-H12) -> -- | N12: =IF(AND(OR(ISNUMBER(SEARCH("TIME OUT", C12)), ISNUMBER(SEARCH("ERROR", C12))), OR(ISNUMBER(SEARCH("TIME OUT", H12)), ISNUMBER(SEARCH("ERROR", H12)))), "--", IF(OR(ISNUMBER(SEARCH("TIME OUT", C12)), ISNUMBER(SEARCH("ERROR", C12))), "QE", IF(OR(ISNUMBER(SEARCH("TIME OUT", H12)), ISNUMBER(SEARCH("ERROR", H12))), "RC", IF(M12=0, "TIE", IF(M12>0, "QE", "RC"))))) -> RC | O12: =IF(M12="--","--",TEXT(MIN(C12,H12)/MAX(C12,H12),"0.000%")) -> -- | P12: =IF(OR(ISNUMBER(SEARCH("ERROR", D12)), ISNUMBER(SEARCH("ERROR", I12)), ISNUMBER(SEARCH("TIME OUT", D12)), ISNUMBER(SEARCH("TIME OUT", I12))),"--",D12-I12) -> -- | Q12: =IF(AND(OR(ISNUMBER(SEARCH("TIME OUT", D12)), ISNUMBER(SEARCH("ERROR", D12))), OR(ISNUMBER(SEARCH("TIME OUT", I12)), ISNUMBER(SEARCH("ERROR", I12)))), "--", IF(OR(ISNUMBER(SEARCH("TIME OUT", D12)), ISNUMBER(SEARCH("ERROR", D12))), "QE", IF(OR(ISNUMBER(SEARCH("TIME OUT", I12)), ISNUMBER(SEARCH("ERROR", I12))), "RC", IF(P12=0, "TIE", IF(P12>0, "QE", "RC"))))) -> RC | R12: =IF(P12="--","--",TEXT(MIN(D12,I12)/MAX(D12,I12),"0.000%")) -> -- | S12: =IF(OR(ISNUMBER(SEARCH("ERROR", E12)), ISNUMBER(SEARCH("ERROR", J12)), ISNUMBER(SEARCH("TIME OUT", E12)), ISNUMBER(SEARCH("TIME OUT", J12))),"--",E12-J12) -> -- | T12: =IF(AND(OR(ISNUMBER(SEARCH("TIME OUT", E12)), ISNUMBER(SEARCH("ERROR", E12))), OR(ISNUMBER(SEARCH("TIME OUT", J12)), ISNUMBER(SEARCH("ERROR", J12)))), "--", IF(OR(ISNUMBER(SEARCH("TIME OUT", E12)), ISNUMBER(SEARCH("ERROR", E12))), "QE", IF(OR(ISNUMBER(SEARCH("TIME OUT", J12)), ISNUMBER(SEARCH("ERROR", J12))), "RC", IF(S12=0, "TIE", IF(S12>0, "QE", "RC"))))) -> RC | U12: =IF(S12="--","--",TEXT(MIN(E12,J12)/MAX(E12,J12),"0.000%")) -> -- | V12: =IF(OR(ISNUMBER(SEARCH("ERROR", F12)), ISNUMBER(SEARCH("ERROR", K12)), ISNUMBER(SEARCH("TIME OUT", F12)), ISNUMBER(SEARCH("TIME OUT", K12))),"--",F12-K12) -> -- | W12: =IF(AND(OR(ISNUMBER(SEARCH("TIME OUT", F12)), ISNUMBER(SEARCH("ERROR", F12))), OR(ISNUMBER(SEARCH("TIME OUT", K12)), ISNUMBER(SEARCH("ERROR", K12)))), "--", IF(OR(ISNUMBER(SEARCH("TIME OUT", F12)), ISNUMBER(SEARCH("ERROR", F12))), "QE", IF(OR(ISNUMBER(SEARCH("TIME OUT", K12)), ISNUMBER(SEARCH("ERROR", K12))), "RC", IF(V12=0, "TIE", IF(V12>0, "QE", "RC"))))) -> RC | X12: =IF(V12="--","--",TEXT(MIN(F12,K12)/MAX(F12,K12),"0.000%")) -> --
A13: 31 | B13: [skoE, skoR, skoX] | C13: 2329616 | D13: 0.0156 | E13: 0.0161 | F13: 9 | G13: [skoE, skoR, skoX] | H13: 4424440 | I13: 0.05 | J13: 0.0491 | K13: 57 | L13: =IF(OR(ISNUMBER(SEARCH("ERROR", B13)), ISNUMBER(SEARCH("ERROR", G13)), ISNUMBER(SEARCH("TIME OUT", B13)), ISNUMBER(SEARCH("TIME OUT", G13))), "--", B13=G13) -> TRUE | M13: =IF(OR(ISNUMBER(SEARCH("ERROR", C13)), ISNUMBER(SEARCH("ERROR", H13)), ISNUMBER(SEARCH("TIME OUT", C13)), ISNUMBER(SEARCH("TIME OUT", H13))),"--",C13-H13) -> -2094824 | N13: =IF(AND(OR(ISNUMBER(SEARCH("TIME OUT", C13)), ISNUMBER(SEARCH("ERROR", C13))), OR(ISNUMBER(SEARCH("TIME OUT", H13)), ISNUMBER(SEARCH("ERROR", H13)))), "--", IF(OR(ISNUMBER(SEARCH("TIME OUT", C13)), ISNUMBER(SEARCH("ERROR", C13))), "QE", IF(OR(ISNUMBER(SEARCH("TIME OUT", H13)), ISNUMBER(SEARCH("ERROR", H13))), "RC", IF(M13=0, "TIE", IF(M13>0, "QE", "RC"))))) -> RC | O13: =IF(M13="--","--",TEXT(MIN(C13,H13)/MAX(C13,H13),"0.000%")) -> 52.653% | P13: =IF(OR(ISNUMBER(SEARCH("ERROR", D13)), ISNUMBER(SEARCH("ERROR", I13)), ISNUMBER(SEARCH("TIME OUT", D13)), ISNUMBER(SEARCH("TIME OUT", I13))),"--",D13-I13) -> -0.0344 | Q13: =IF(AND(OR(ISNUMBER(SEARCH("TIME OUT", D13)), ISNUMBER(SEARCH("ERROR", D13))), OR(ISNUMBER(SEARCH("TIME OUT", I13)), ISNUMBER(SEARCH("ERROR", I13)))), "--", IF(OR(ISNUMBER(SEARCH("TIME OUT", D13)), ISNUMBER(SEARCH("ERROR", D13))), "QE", IF(OR(ISNUMBER(SEARCH("TIME OUT", I13)), ISNUMBER(SEARCH("ERROR", I13))), "RC", IF(P13=0, "TIE", IF(P13>0, "QE", "RC"))))) -> RC | R13: =IF(P13="--","--",TEXT(MIN(D13,I13)/MAX(D13,I13),"0.000%")) -> 31.200% | S13: =IF(OR(ISNUMBER(SEARCH("ERROR", E13)), ISNUMBER(SEARCH("ERROR", J13)), ISNUMBER(SEARCH("TIME OUT", E13)), ISNUMBER(SEARCH("TIME OUT", J13))),"--",E13-J13) -> -0.033 | T13: =IF(AND(OR(ISNUMBER(SEARCH("TIME OUT", E13)), ISNUMBER(SEARCH("ERROR", E13))), OR(ISNUMBER(SEARCH("TIME OUT", J13)), ISNUMBER(SEARCH("ERROR", J13)))), "--", IF(OR(ISNUMBER(SEARCH("TIME OUT", E13)), ISNUMBER(SEARCH("ERROR", E13))), "QE", IF(OR(ISNUMBER(SEARCH("TIME OUT", J13)), ISNUMBER(SEARCH("ERROR", J13))), "RC", IF(S13=0, "TIE", IF(S13>0, "QE", "RC"))))) -> RC | U13: =IF(S13="--","--",TEXT(MIN(E13,J13)/MAX(E13,J13),"0.000%")) -> 32.790% | V13: =IF(OR(ISNUMBER(SEARCH("ERROR", F13)), ISNUMBER(SEARCH("ERROR", K13)), ISNUMBER(SEARCH("TIME OUT", F13)), ISNUMBER(SEARCH("TIME OUT", K13))),"--",F13-K13) -> -48 | W13: =IF(AND(OR(ISNUMBER(SEARCH("TIME OUT", F13)), ISNUMBER(SEARCH("ERROR", F13))), OR(ISNUMBER(SEARCH("TIME OUT", K13)), ISNUMBER(SEARCH("ERROR", K13)))), "--", IF(OR(ISNUMBER(SEARCH("TIME OUT", F13)), ISNUMBER(SEARCH("ERROR", F13))), "QE", IF(OR(ISNUMBER(SEARCH("TIME OUT", K13)), ISNUMBER(SEARCH("ERROR", K13))), "RC", IF(V13=0, "TIE", IF(V13>0, "QE", "RC"))))) -> RC | X13: =IF(V13="--","--",TEXT(MIN(F13,K13)/MAX(F13,K13),"0.000%")) -> 15.789% | AA13: memory | AC13: cputime | AE13: realtime | AG13: cells
A14: 32 | B14: [skoE, skoR, skoX] | C14: 1736508348 | D14: 19.8515 | E14: 16.2543 | F14: 13005 | G14: TIME OUT | H14: TIME OUT | I14: TIME OUT | J14: TIME OUT | K14: TIME OUT | L14: =IF(OR(ISNUMBER(SEARCH("ERROR", B14)), ISNUMBER(SEARCH("ERROR", G14)), ISNUMBER(SEARCH("TIME OUT", B14)), ISNUMBER(SEARCH("TIME OUT", G14))), "--", B14=G14) -> -- | M14: =IF(OR(ISNUMBER(SEARCH("ERROR", C14)), ISNUMBER(SEARCH("ERROR", H14)), ISNUMBER(SEARCH("TIME OUT", C14)), ISNUMBER(SEARCH("TIME OUT", H14))),"--",C14-H14) -> -- | N14: =IF(AND(OR(ISNUMBER(SEARCH("TIME OUT", C14)), ISNUMBER(SEARCH("ERROR", C14))), OR(ISNUMBER(SEARCH("TIME OUT", H14)), ISNUMBER(SEARCH("ERROR", H14)))), "--", IF(OR(ISNUMBER(SEARCH("TIME OUT", C14)), ISNUMBER(SEARCH("ERROR", C14))), "QE", IF(OR(ISNUMBER(SEARCH("TIME OUT", H14)), ISNUMBER(SEARCH("ERROR", H14))), "RC", IF(M14=0, "TIE", IF(M14>0, "QE", "RC"))))) -> RC | O14: =IF(M14="--","--",TEXT(MIN(C14,H14)/MAX(C14,H14),"0.000%")) -> -- | P14: =IF(OR(ISNUMBER(SEARCH("ERROR", D14)), ISNUMBER(SEARCH("ERROR", I14)), ISNUMBER(SEARCH("TIME OUT", D14)), ISNUMBER(SEARCH("TIME OUT", I14))),"--",D14-I14) -> -- | Q14: =IF(AND(OR(ISNUMBER(SEARCH("TIME OUT", D14)), ISNUMBER(SEARCH("ERROR", D14))), OR(ISNUMBER(SEARCH("TIME OUT", I14)), ISNUMBER(SEARCH("ERROR", I14)))), "--", IF(OR(ISNUMBER(SEARCH("TIME OUT", D14)), ISNUMBER(SEARCH("ERROR", D14))), "QE", IF(OR(ISNUMBER(SEARCH("TIME OUT", I14)), ISNUMBER(SEARCH("ERROR", I14))), "RC", IF(P14=0, "TIE", IF(P14>0, "QE", "RC"))))) -> RC | R14: =IF(P14="--","--",TEXT(MIN(D14,I14)/MAX(D14,I14),"0.000%")) -> -- | S14: =IF(OR(ISNUMBER(SEARCH("ERROR", E14)), ISNUMBER(SEARCH("ERROR", J14)), ISNUMBER(SEARCH("TIME OUT", E14)), ISNUMBER(SEARCH("TIME OUT", J14))),"--",E14-J14) -> -- | T14: =IF(AND(OR(ISNUMBER(SEARCH("TIME OUT", E14)), ISNUMBER(SEARCH("ERROR", E14))), OR(ISNUMBER(SEARCH("TIME OUT", J14)), ISNUMBER(SEARCH("ERROR", J14)))), "--", IF(OR(ISNUMBER(SEARCH("TIME OUT", E14)), ISNUMBER(SEARCH("ERROR", E14))), "QE", IF(OR(ISNUMBER(SEARCH("TIME OUT", J14)), ISNUMBER(SEARCH("ERROR", J14))), "RC", IF(S14=0, "TIE", IF(S14>0, "QE", "RC"))))) -> RC | U14: =IF(S14="--","--",TEXT(MIN(E14,J14)/MAX(E14,J14),"0.000%")) -> -- | V14: =IF(OR(ISNUMBER(SEARCH("ERROR", F14)), ISNUMBER(SEARCH("ERROR", K14)), ISNUMBER(SEARCH("TIME OUT", F14)), ISNUMBER(SEARCH("TIME OUT", K14))),"--",F14-K14) -> -- | W14: =IF(AND(OR(ISNUMBER(SEARCH("TIME OUT", F14)), ISNUMBER(SEARCH("ERROR", F14))), OR(ISNUMBER(SEARCH("TIME OUT", K14)), ISNUMBER(SEARCH("ERROR", K14)))), "--", IF(OR(ISNUMBER(SEARCH("TIME OUT", F14)), ISNUMBER(SEARCH("ERROR", F14))), "QE", IF(OR(ISNUMBER(SEARCH("TIME OUT", K14)), ISNUMBER(SEARCH("ERROR", K14))), "RC", IF(V14=0, "TIE", IF(V14>0, "QE", "RC"))))) -> RC | X14: =IF(V14="--","--",TEXT(MIN(F14,K14)/MAX(F14,K14),"0.000%")) -> -- | Z14: RC | AA14: =COUNTIF(N:N,$Z7)-COUNTIFS(N:N,$Z7,O:O,"--") -> 4 | AB14: =AA14/AA$11 -> 0.059701493 | AC14: =COUNTIF(Q:Q,$Z7)-COUNTIFS(Q:Q,$Z7,R:R,"--") -> 4 | AD14: =AC14/AC$11 -> 0.059701493 | AE14: =COUNTIF(T:T,$Z7)-COUNTIFS(T:T,$Z7,U:U,"--") -> 4 | AF14: =AE14/AE$11 -> 0.059701493 | AG14: =COUNTIF(W:W,$Z7)-COUNTIFS(W:W,$Z7,X:X,"--") -> 4 | AH14: =AG14/AG$11 -> 0.059701493
A15: 33 | B15: [skoE, skoR, skoX] | C15: 1745061377 | D15: 19.8422 | E15: 16.1832 | F15: 13005 | G15: TIME OUT | H15: TIME OUT | I15: TIME OUT | J15: TIME OUT | K15: TIME OUT | L15: =IF(OR(ISNUMBER(SEARCH("ERROR", B15)), ISNUMBER(SEARCH("ERROR", G15)), ISNUMBER(SEARCH("TIME OUT", B15)), ISNUMBER(SEARCH("TIME OUT", G15))), "--", B15=G15) -> -- | M15: =IF(OR(ISNUMBER(SEARCH("ERROR", C15)), ISNUMBER(SEARCH("ERROR", H15)), ISNUMBER(SEARCH("TIME OUT", C15)), ISNUMBER(SEARCH("TIME OUT", H15))),"--",C15-H15) -> -- | N15: =IF(AND(OR(ISNUMBER(SEARCH("TIME OUT", C15)), ISNUMBER(SEARCH("ERROR", C15))), OR(ISNUMBER(SEARCH("TIME OUT", H15)), ISNUMBER(SEARCH("ERROR", H15)))), "--", IF(OR(ISNUMBER(SEARCH("TIME OUT", C15)), ISNUMBER(SEARCH("ERROR", C15))), "QE", IF(OR(ISNUMBER(SEARCH("TIME OUT", H15)), ISNUMBER(SEARCH("ERROR", H15))), "RC", IF(M15=0, "TIE", IF(M15>0, "QE", "RC"))))) -> RC | O15: =IF(M15="--","--",TEXT(MIN(C15,H15)/MAX(C15,H15),"0.000%")) -> -- | P15: =IF(OR(ISNUMBER(SEARCH("ERROR", D15)), ISNUMBER(SEARCH("ERROR", I15)), ISNUMBER(SEARCH("TIME OUT", D15)), ISNUMBER(SEARCH("TIME OUT", I15))),"--",D15-I15) -> -- | Q15: =IF(AND(OR(ISNUMBER(SEARCH("TIME OUT", D15)), ISNUMBER(SEARCH("ERROR", D15))), OR(ISNUMBER(SEARCH("TIME OUT", I15)), ISNUMBER(SEARCH("ERROR", I15)))), "--", IF(OR(ISNUMBER(SEARCH("TIME OUT", D15)), ISNUMBER(SEARCH("ERROR", D15))), "QE", IF(OR(ISNUMBER(SEARCH("TIME OUT", I15)), ISNUMBER(SEARCH("ERROR", I15))), "RC", IF(P15=0, "TIE", IF(P15>0, "QE", "RC"))))) -> RC | R15: =IF(P15="--","--",TEXT(MIN(D15,I15)/MAX(D15,I15),"0.000%")) -> -- | S15: =IF(OR(ISNUMBER(SEARCH("ERROR", E15)), ISNUMBER(SEARCH("ERROR", J15)), ISNUMBER(SEARCH("TIME OUT", E15)), ISNUMBER(SEARCH("TIME OUT", J15))),"--",E15-J15) -> -- | T15: =IF(AND(OR(ISNUMBER(SEARCH("TIME OUT", E15)), ISNUMBER(SEARCH("ERROR", E15))), OR(ISNUMBER(SEARCH("TIME OUT", J15)), ISNUMBER(SEARCH("ERROR", J15)))), "--", IF(OR(ISNUMBER(SEARCH("TIME OUT", E15)), ISNUMBER(SEARCH("ERROR", E15))), "QE", IF(OR(ISNUMBER(SEARCH("TIME OUT", J15)), ISNUMBER(SEARCH("ERROR", J15))), "RC", IF(S15=0, "TIE", IF(S15>0, "QE", "RC"))))) -> RC | U15: =IF(S15="--","--",TEXT(MIN(E15,J15)/MAX(E15,J15),"0.000%")) -> -- | V15: =IF(OR(ISNUMBER(SEARCH("ERROR", F15)), ISNUMBER(SEARCH("ERROR", K15)), ISNUMBER(SEARCH("TIME OUT", F15)), ISNUMBER(SEARCH("TIME OUT", K15))),"--",F15-K15) -> -- | W15: =IF(AND(OR(ISNUMBER(SEARCH("TIME OUT", F15)), ISNUMBER(SEARCH("ERROR", F15))), OR(ISNUMBER(SEARCH("TIME OUT", K15)), ISNUMBER(SEARCH("ERROR", K15)))), "--", IF(OR(ISNUMBER(SEARCH("TIME OUT", F15)), ISNUMBER(SEARCH("ERROR", F15))), "QE", IF(OR(ISNUMBER(SEARCH("TIME OUT", K15)), ISNUMBER(SEARCH("ERROR", K15))), "RC", IF(V15=0, "TIE", IF(V15>0, "QE", "RC"))))) -> RC | X15: =IF(V15="--","--",TEXT(MIN(F15,K15)/MAX(F15,K15),"0.000%")) -> -- | Z15: QE | AA15: =COUNTIF(N:N,$Z8)-COUNTIFS(N:N,$Z8,O:O,"--") -> 10 | AB15: =AA15/AA$11 -> 0.14925373 | AC15: =COUNTIF(Q:Q,$Z8)-COUNTIFS(Q:Q,$Z8,R:R,"--") -> 10 | AD15: =AC15/AC$11 -> 0.14925373 | AE15: =COUNTIF(T:T,$Z8)-COUNTIFS(T:T,$Z8,U:U,"--") -> 10 | AF15: =AE15/AE$11 -> 0.14925373 | AG15: =COUNTIF(W:W,$Z8)-COUNTIFS(W:W,$Z8,X:X,"--") -> 0 | AH15: =AG15/AG$11 -> 0
A16: 34 | B16: [skoE, skoR, skoX] | C16: 1745288586 | D16: 19.9328 | E16: 16.2109 | F16: 13005 | G16: TIME OUT | H16: TIME OUT | I16: TIME OUT | J16: TIME OUT | K16: TIME OUT | L16: =IF(OR(ISNUMBER(SEARCH("ERROR", B16)), ISNUMBER(SEARCH("ERROR", G16)), ISNUMBER(SEARCH("TIME OUT", B16)), ISNUMBER(SEARCH("TIME OUT", G16))), "--", B16=G16) -> -- | M16: =IF(OR(ISNUMBER(SEARCH("ERROR", C16)), ISNUMBER(SEARCH("ERROR", H16)), ISNUMBER(SEARCH("TIME OUT", C16)), ISNUMBER(SEARCH("TIME OUT", H16))),"--",C16-H16) -> -- | N16: =IF(AND(OR(ISNUMBER(SEARCH("TIME OUT", C16)), ISNUMBER(SEARCH("ERROR", C16))), OR(ISNUMBER(SEARCH("TIME OUT", H16)), ISNUMBER(SEARCH("ERROR", H16)))), "--", IF(OR(ISNUMBER(SEARCH("TIME OUT", C16)), ISNUMBER(SEARCH("ERROR", C16))), "QE", IF(OR(ISNUMBER(SEARCH("TIME OUT", H16)), ISNUMBER(SEARCH("ERROR", H16))), "RC", IF(M16=0, "TIE", IF(M16>0, "QE", "RC"))))) -> RC | O16: =IF(M16="--","--",TEXT(MIN(C16,H16)/MAX(C16,H16),"0.000%")) -> -- | P16: =IF(OR(ISNUMBER(SEARCH("ERROR", D16)), ISNUMBER(SEARCH("ERROR", I16)), ISNUMBER(SEARCH("TIME OUT", D16)), ISNUMBER(SEARCH("TIME OUT", I16))),"--",D16-I16) -> -- | Q16: =IF(AND(OR(ISNUMBER(SEARCH("TIME OUT", D16)), ISNUMBER(SEARCH("ERROR", D16))), OR(ISNUMBER(SEARCH("TIME OUT", I16)), ISNUMBER(SEARCH("ERROR", I16)))), "--", IF(OR(ISNUMBER(SEARCH("TIME OUT", D16)), ISNUMBER(SEARCH("ERROR", D16))), "QE", IF(OR(ISNUMBER(SEARCH("TIME OUT", I16)), ISNUMBER(SEARCH("ERROR", I16))), "RC", IF(P16=0, "TIE", IF(P16>0, "QE", "RC"))))) -> RC | R16: =IF(P16="--","--",TEXT(MIN(D16,I16)/MAX(D16,I16),"0.000%")) -> -- | S16: =IF(OR(ISNUMBER(SEARCH("ERROR", E16)), ISNUMBER(SEARCH("ERROR", J16)), ISNUMBER(SEARCH("TIME OUT", E16)), ISNUMBER(SEARCH("TIME OUT", J16))),"--",E16-J16) -> -- | T16: =IF(AND(OR(ISNUMBER(SEARCH("TIME OUT", E16)), ISNUMBER(SEARCH("ERROR", E16))), OR(ISNUMBER(SEARCH("TIME OUT", J16)), ISNUMBER(SEARCH("ERROR", J16)))), "--", IF(OR(ISNUMBER(SEARCH("TIME OUT", E16)), ISNUMBER(SEARCH("ERROR", E16))), "QE", IF(OR(ISNUMBER(SEARCH("TIME OUT", J16)), ISNUMBER(SEARCH("ERROR", J16))), "RC", IF(S16=0, "TIE", IF(S16>0, "QE", "RC"))))) -> RC | U16: =IF(S16="--","--",TEXT(MIN(E16,J16)/MAX(E16,J16),"0.000%")) -> -- | V16: =IF(OR(ISNUMBER(SEARCH("ERROR", F16)), ISNUMBER(SEARCH("ERROR", K16)), ISNUMBER(SEARCH("TIME OUT", F16)), ISNUMBER(SEARCH("TIME OUT", K16))),"--",F16-K16) -> -- | W16: =IF(AND(OR(ISNUMBER(SEARCH("TIME OUT", F16)), ISNUMBER(SEARCH("ERROR", F16))), OR(ISNUMBER(SEARCH("TIME OUT", K16)), ISNUMBER(SEARCH("ERROR", K16)))), "--", IF(OR(ISNUMBER(SEARCH("TIME OUT", F16)), ISNUMBER(SEARCH("ERROR", F16))), "QE", IF(OR(ISNUMBER(SEARCH("TIME OUT", K16)), ISNUMBER(SEARCH("ERROR", K16))), "RC", IF(V16=0, "TIE", IF(V16>0, "QE", "RC"))))) -> RC | X16: =IF(V16="--","--",TEXT(MIN(F16,K16)/MAX(F16,K16),"0.000%")) -> -- | Z16: TIE | AA16: =COUNTIF(N:N,$Z9)-COUNTIFS(N:N,$Z9,O:O,"--") -> 0 | AB16: =AA16/AA$11 -> 0 | AC16: =COUNTIF(Q:Q,$Z9)-COUNTIFS(Q:Q,$Z9,R:R,"--") -> 0 | AD16: =AC16/AC$11 -> 0 | AE16: =COUNTIF(T:T,$Z9)-COUNTIFS(T:T,$Z9,U:U,"--") -> 0 | AF16: =AE16/AE$11 -> 0 | AG16: =COUNTIF(W:W,$Z9)-COUNTIFS(W:W,$Z9,X:X,"--") -> 10 | AH16: =AG16/AG$11 -> 0.14925373
A17: 36 | B17: [skoE, skoR, skoX] | C17: 4960122087 | D17: 59.9641 | E17: 46.5638 | F17: 33047 | G17: TIME OUT | H17: TIME OUT | I17: TIME OUT | J17: TIME OUT | K17: TIME OUT | L17: =IF(OR(ISNUMBER(SEARCH("ERROR", B17)), ISNUMBER(SEARCH("ERROR", G17)), ISNUMBER(SEARCH("TIME OUT", B17)), ISNUMBER(SEARCH("TIME OUT", G17))), "--", B17=G17) -> -- | M17: =IF(OR(ISNUMBER(SEARCH("ERROR", C17)), ISNUMBER(SEARCH("ERROR", H17)), ISNUMBER(SEARCH("TIME OUT", C17)), ISNUMBER(SEARCH("TIME OUT", H17))),"--",C17-H17) -> -- | N17: =IF(AND(OR(ISNUMBER(SEARCH("TIME OUT", C17)), ISNUMBER(SEARCH("ERROR", C17))), OR(ISNUMBER(SEARCH("TIME OUT", H17)), ISNUMBER(SEARCH("ERROR", H17)))), "--", IF(OR(ISNUMBER(SEARCH("TIME OUT", C17)), ISNUMBER(SEARCH("ERROR", C17))), "QE", IF(OR(ISNUMBER(SEARCH("TIME OUT", H17)), ISNUMBER(SEARCH("ERROR", H17))), "RC", IF(M17=0, "TIE", IF(M17>0, "QE", "RC"))))) -> RC | O17: =IF(M17="--","--",TEXT(MIN(C17,H17)/MAX(C17,H17),"0.000%")) -> -- | P17: =IF(OR(ISNUMBER(SEARCH("ERROR", D17)), ISNUMBER(SEARCH("ERROR", I17)), ISNUMBER(SEARCH("TIME OUT", D17)), ISNUMBER(SEARCH("TIME OUT", I17))),"--",D17-I17) -> -- | Q17: =IF(AND(OR(ISNUMBER(SEARCH("TIME OUT", D17)), ISNUMBER(SEARCH("ERROR", D17))), OR(ISNUMBER(SEARCH("TIME OUT", I17)), ISNUMBER(SEARCH("ERROR", I17)))), "--", IF(OR(ISNUMBER(SEARCH("TIME OUT", D17)), ISNUMBER(SEARCH("ERROR", D17))), "QE", IF(OR(ISNUMBER(SEARCH("TIME OUT", I17)), ISNUMBER(SEARCH("ERROR", I17))), "RC", IF(P17=0, "TIE", IF(P17>0, "QE", "RC"))))) -> RC | R17: =IF(P17="--","--",TEXT(MIN(D17,I17)/MAX(D17,I17),"0.000%")) -> -- | S17: =IF(OR(ISNUMBER(SEARCH("ERROR", E17)), ISNUMBER(SEARCH("ERROR", J17)), ISNUMBER(SEARCH("TIME OUT", E17)), ISNUMBER(SEARCH("TIME OUT", J17))),"--",E17-J17) -> -- | T17: =IF(AND(OR(ISNUMBER(SEARCH("TIME OUT", E17)), ISNUMBER(SEARCH("ERROR", E17))), OR(ISNUMBER(SEARCH("TIME OUT", J17)), ISNUMBER(SEARCH("ERROR", J17)))), "--", IF(OR(ISNUMBER(SEARCH("TIME OUT", E17)), ISNUMBER(SEARCH("ERROR", E17))), "QE", IF(OR(ISNUMBER(SEARCH("TIME OUT", J17)), ISNUMBER(SEARCH("ERROR", J17))), "RC", IF(S17=0, "TIE", IF(S17>0, "QE", "RC"))))) -> RC | U17: =IF(S17="--","--",TEXT(MIN(E17,J17)/MAX(E17,J17),"0.000%")) -> -- | V17: =IF(OR(ISNUMBER(SEARCH("ERROR", F17)), ISNUMBER(SEARCH("ERROR", K17)), ISNUMBER(SEARCH("TIME OUT", F17)), ISNUMBER(SEARCH("TIME OUT", K17))),"--",F17-K17) -> -- | W17: =IF(AND(OR(ISNUMBER(SEARCH("TIME OUT", F17)), ISNUMBER(SEARCH("ERROR", F17))), OR(ISNUMBER(SEARCH("TIME OUT", K17)), ISNUMBER(SEARCH("ERROR", K17)))), "--", IF(OR(ISNUMBER(SEARCH("TIME OUT", F17)), ISNUMBER(SEARCH("ERROR", F17))), "QE", IF(OR(ISNUMBER(SEARCH("TIME OUT", K17)), ISNUMBER(SEARCH("ERROR", K17))), "RC", IF(V17=0, "TIE", IF(V17>0, "QE", "RC"))))) -> RC | X17: =IF(V17="--","--",TEXT(MIN(F17,K17)/MAX(F17,K17),"0.000%")) -> -- | Z17: -- | AA17: =COUNTIF(O:O,"--") -> 53 | AB17: =AA17/AA$11 -> 0.79104478 | AC17: =COUNTIF(R:R,"--") -> 53 | AD17: =AC17/AC$11 -> 0.79104478 | AE17: =COUNTIF(U:U,"--") -> 53 | AF17: =AE17/AE$11 -> 0.79104478 | AG17: =COUNTIF(X:X,"--") -> 53 | AH17: =AG17/AG$11 -> 0.79104478
A18: 38 | B18: [skoE, skoR, skoX] | C18: 4956943306 | D18: 60.164 | E18: 46.4364 | F18: 33047 | G18: TIME OUT | H18: TIME OUT | I18: TIME OUT | J18: TIME OUT | K18: TIME OUT | L18: =IF(OR(ISNUMBER(SEARCH("ERROR", B18)), ISNUMBER(SEARCH("ERROR", G18)), ISNUMBER(SEARCH("TIME OUT", B18)), ISNUMBER(SEARCH("TIME OUT", G18))), "--", B18=G18) -> -- | M18: =IF(OR(ISNUMBER(SEARCH("ERROR", C18)), ISNUMBER(SEARCH("ERROR", H18)), ISNUMBER(SEARCH("TIME OUT", C18)), ISNUMBER(SEARCH("TIME OUT", H18))),"--",C18-H18) -> -- | N18: =IF(AND(OR(ISNUMBER(SEARCH("TIME OUT", C18)), ISNUMBER(SEARCH("ERROR", C18))), OR(ISNUMBER(SEARCH("TIME OUT", H18)), ISNUMBER(SEARCH("ERROR", H18)))), "--", IF(OR(ISNUMBER(SEARCH("TIME OUT", C18)), ISNUMBER(SEARCH("ERROR", C18))), "QE", IF(OR(ISNUMBER(SEARCH("TIME OUT", H18)), ISNUMBER(SEARCH("ERROR", H18))), "RC", IF(M18=0, "TIE", IF(M18>0, "QE", "RC"))))) -> RC | O18: =IF(M18="--","--",TEXT(MIN(C18,H18)/MAX(C18,H18),"0.000%")) -> -- | P18: =IF(OR(ISNUMBER(SEARCH("ERROR", D18)), ISNUMBER(SEARCH("ERROR", I18)), ISNUMBER(SEARCH("TIME OUT", D18)), ISNUMBER(SEARCH("TIME OUT", I18))),"--",D18-I18) -> -- | Q18: =IF(AND(OR(ISNUMBER(SEARCH("TIME OUT", D18)), ISNUMBER(SEARCH("ERROR", D18))), OR(ISNUMBER(SEARCH("TIME OUT", I18)), ISNUMBER(SEARCH("ERROR", I18)))), "--", IF(OR(ISNUMBER(SEARCH("TIME OUT", D18)), ISNUMBER(SEARCH("ERROR", D18))), "QE", IF(OR(ISNUMBER(SEARCH("TIME OUT", I18)), ISNUMBER(SEARCH("ERROR", I18))), "RC", IF(P18=0, "TIE", IF(P18>0, "QE", "RC"))))) -> RC | R18: =IF(P18="--","--",TEXT(MIN(D18,I18)/MAX(D18,I18),"0.000%")) -> -- | S18: =IF(OR(ISNUMBER(SEARCH("ERROR", E18)), ISNUMBER(SEARCH("ERROR", J18)), ISNUMBER(SEARCH("TIME OUT", E18)), ISNUMBER(SEARCH("TIME OUT", J18))),"--",E18-J18) -> -- | T18: =IF(AND(OR(ISNUMBER(SEARCH("TIME OUT", E18)), ISNUMBER(SEARCH("ERROR", E18))), OR(ISNUMBER(SEARCH("TIME OUT", J18)), ISNUMBER(SEARCH("ERROR", J18)))), "--", IF(OR(ISNUMBER(SEARCH("TIME OUT", E18)), ISNUMBER(SEARCH("ERROR", E18))), "QE", IF(OR(ISNUMBER(SEARCH("TIME OUT", J18)), ISNUMBER(SEARCH("ERROR", J18))), "RC", IF(S18=0, "TIE", IF(S18>0, "QE", "RC"))))) -> RC | U18: =IF(S18="--","--",TEXT(MIN(E18,J18)/MAX(E18,J18),"0.000%")) -> -- | V18: =IF(OR(ISNUMBER(SEARCH("ERROR", F18)), ISNUMBER(SEARCH("ERROR", K18)), ISNUMBER(SEARCH("TIME OUT", F18)), ISNUMBER(SEARCH("TIME OUT", K18))),"--",F18-K18) -> -- | W18: =IF(AND(OR(ISNUMBER(SEARCH("TIME OUT", F18)), ISNUMBER(SEARCH("ERROR", F18))), OR(ISNUMBER(SEARCH("TIME OUT", K18)), ISNUMBER(SEARCH("ERROR", K18)))), "--", IF(OR(ISNUMBER(SEARCH("TIME OUT", F18)), ISNUMBER(SEARCH("ERROR", F18))), "QE", IF(OR(ISNUMBER(SEARCH("TIME OUT", K18)), ISNUMBER(SEARCH("ERROR", K18))), "RC", IF(V18=0, "TIE", IF(V18>0, "QE", "RC"))))) -> RC | X18: =IF(V18="--","--",TEXT(MIN(F18,K18)/MAX(F18,K18),"0.000%")) -> -- | Z18: total | AA18: =COUNTA(N:N)-1 -> 67 | AB18: =AA18/AA$11 -> 1 | AC18: =COUNTA(O:O)-1 -> 67 | AD18: =AC18/AC$11 -> 1 | AE18: =COUNTA(P:P)-1 -> 67 | AF18: =AE18/AE$11 -> 1 | AG18: =COUNTA(Q:Q)-1 -> 67 | AH18: =AG18/AG$11 -> 1
A19: 40 | B19: [skoE, skoR, skoX] | C19: 4678431006 | D19: 56.7532 | E19: 43.8675 | F19: 28799 | G19: TIME OUT | H19: TIME OUT | I19: TIME OUT | J19: TIME OUT | K19: TIME OUT | L19: =IF(OR(ISNUMBER(SEARCH("ERROR", B19)), ISNUMBER(SEARCH("ERROR", G19)), ISNUMBER(SEARCH("TIME OUT", B19)), ISNUMBER(SEARCH("TIME OUT", G19))), "--", B19=G19) -> -- | M19: =IF(OR(ISNUMBER(SEARCH("ERROR", C19)), ISNUMBER(SEARCH("ERROR", H19)), ISNUMBER(SEARCH("TIME OUT", C19)), ISNUMBER(SEARCH("TIME OUT", H19))),"--",C19-H19) -> -- | N19: =IF(AND(OR(ISNUMBER(SEARCH("TIME OUT", C19)), ISNUMBER(SEARCH("ERROR", C19))), OR(ISNUMBER(SEARCH("TIME OUT", H19)), ISNUMBER(SEARCH("ERROR", H19)))), "--", IF(OR(ISNUMBER(SEARCH("TIME OUT", C19)), ISNUMBER(SEARCH("ERROR", C19))), "QE", IF(OR(ISNUMBER(SEARCH("TIME OUT", H19)), ISNUMBER(SEARCH("ERROR", H19))), "RC", IF(M19=0, "TIE", IF(M19>0, "QE", "RC"))))) -> RC | O19: =IF(M19="--","--",TEXT(MIN(C19,H19)/MAX(C19,H19),"0.000%")) -> -- | P19: =IF(OR(ISNUMBER(SEARCH("ERROR", D19)), ISNUMBER(SEARCH("ERROR", I19)), ISNUMBER(SEARCH("TIME OUT", D19)), ISNUMBER(SEARCH("TIME OUT", I19))),"--",D19-I19) -> -- | Q19: =IF(AND(OR(ISNUMBER(SEARCH("TIME OUT", D19)), ISNUMBER(SEARCH("ERROR", D19))), OR(ISNUMBER(SEARCH("TIME OUT", I19)), ISNUMBER(SEARCH("ERROR", I19)))), "--", IF(OR(ISNUMBER(SEARCH("TIME OUT", D19)), ISNUMBER(SEARCH("ERROR", D19))), "QE", IF(OR(ISNUMBER(SEARCH("TIME OUT", I19)), ISNUMBER(SEARCH("ERROR", I19))), "RC", IF(P19=0, "TIE", IF(P19>0, "QE", "RC"))))) -> RC | R19: =IF(P19="--","--",TEXT(MIN(D19,I19)/MAX(D19,I19),"0.000%")) -> -- | S19: =IF(OR(ISNUMBER(SEARCH("ERROR", E19)), ISNUMBER(SEARCH("ERROR", J19)), ISNUMBER(SEARCH("TIME OUT", E19)), ISNUMBER(SEARCH("TIME OUT", J19))),"--",E19-J19) -> -- | T19: =IF(AND(OR(ISNUMBER(SEARCH("TIME OUT", E19)), ISNUMBER(SEARCH("ERROR", E19))), OR(ISNUMBER(SEARCH("TIME OUT", J19)), ISNUMBER(SEARCH("ERROR", J19)))), "--", IF(OR(ISNUMBER(SEARCH("TIME OUT", E19)), ISNUMBER(SEARCH("ERROR", E19))), "QE", IF(OR(ISNUMBER(SEARCH("TIME OUT", J19)), ISNUMBER(SEARCH("ERROR", J19))), "RC", IF(S19=0, "TIE", IF(S19>0, "QE", "RC"))))) -> RC | U19: =IF(S19="--","--",TEXT(MIN(E19,J19)/MAX(E19,J19),"0.000%")) -> -- | V19: =IF(OR(ISNUMBER(SEARCH("ERROR", F19)), ISNUMBER(SEARCH("ERROR", K19)), ISNUMBER(SEARCH("TIME OUT", F19)), ISNUMBER(SEARCH("TIME OUT", K19))),"--",F19-K19) -> -- | W19: =IF(AND(OR(ISNUMBER(SEARCH("TIME OUT", F19)), ISNUMBER(SEARCH("ERROR", F19))), OR(ISNUMBER(SEARCH("TIME OUT", K19)), ISNUMBER(SEARCH("ERROR", K19)))), "--", IF(OR(ISNUMBER(SEARCH("TIME OUT", F19)), ISNUMBER(SEARCH("ERROR", F19))), "QE", IF(OR(ISNUMBER(SEARCH("TIME OUT", K19)), ISNUMBER(SEARCH("ERROR", K19))), "RC", IF(V19=0, "TIE", IF(V19>0, "QE", "RC"))))) -> RC | X19: =IF(V19="--","--",TEXT(MIN(F19,K19)/MAX(F19,K19),"0.000%")) -> -- | AD19: =COUNTIF(W:W,$Z8)-COUNTIFS(W:W,$Z8,V:V,"--") -> 0
A20: 41 | B20: [skoE, skoR, skoX] | C20: 4687097897 | D20: 56.75 | E20: 44.0067 | F20: 28799 | G20: TIME OUT | H20: TIME OUT | I20: TIME OUT | J20: TIME OUT | K20: TIME OUT | L20: =IF(OR(ISNUMBER(SEARCH("ERROR", B20)), ISNUMBER(SEARCH("ERROR", G20)), ISNUMBER(SEARCH("TIME OUT", B20)), ISNUMBER(SEARCH("TIME OUT", G20))), "--", B20=G20) -> -- | M20: =IF(OR(ISNUMBER(SEARCH("ERROR", C20)), ISNUMBER(SEARCH("ERROR", H20)), ISNUMBER(SEARCH("TIME OUT", C20)), ISNUMBER(SEARCH("TIME OUT", H20))),"--",C20-H20) -> -- | N20: =IF(AND(OR(ISNUMBER(SEARCH("TIME OUT", C20)), ISNUMBER(SEARCH("ERROR", C20))), OR(ISNUMBER(SEARCH("TIME OUT", H20)), ISNUMBER(SEARCH("ERROR", H20)))), "--", IF(OR(ISNUMBER(SEARCH("TIME OUT", C20)), ISNUMBER(SEARCH("ERROR", C20))), "QE", IF(OR(ISNUMBER(SEARCH("TIME OUT", H20)), ISNUMBER(SEARCH("ERROR", H20))), "RC", IF(M20=0, "TIE", IF(M20>0, "QE", "RC"))))) -> RC | O20: =IF(M20="--","--",TEXT(MIN(C20,H20)/MAX(C20,H20),"0.000%")) -> -- | P20: =IF(OR(ISNUMBER(SEARCH("ERROR", D20)), ISNUMBER(SEARCH("ERROR", I20)), ISNUMBER(SEARCH("TIME OUT", D20)), ISNUMBER(SEARCH("TIME OUT", I20))),"--",D20-I20) -> -- | Q20: =IF(AND(OR(ISNUMBER(SEARCH("TIME OUT", D20)), ISNUMBER(SEARCH("ERROR", D20))), OR(ISNUMBER(SEARCH("TIME OUT", I20)), ISNUMBER(SEARCH("ERROR", I20)))), "--", IF(OR(ISNUMBER(SEARCH("TIME OUT", D20)), ISNUMBER(SEARCH("ERROR", D20))), "QE", IF(OR(ISNUMBER(SEARCH("TIME OUT", I20)), ISNUMBER(SEARCH("ERROR", I20))), "RC", IF(P20=0, "TIE", IF(P20>0, "QE", "RC"))))) -> RC | R20: =IF(P20="--","--",TEXT(MIN(D20,I20)/MAX(D20,I20),"0.000%")) -> -- | S20: =IF(OR(ISNUMBER(SEARCH("ERROR", E20)), ISNUMBER(SEARCH("ERROR", J20)), ISNUMBER(SEARCH("TIME OUT", E20)), ISNUMBER(SEARCH("TIME OUT", J20))),"--",E20-J20) -> -- | T20: =IF(AND(OR(ISNUMBER(SEARCH("TIME OUT", E20)), ISNUMBER(SEARCH("ERROR", E20))), OR(ISNUMBER(SEARCH("TIME OUT", J20)), ISNUMBER(SEARCH("ERROR", J20)))), "--", IF(OR(ISNUMBER(SEARCH("TIME OUT", E20)), ISNUMBER(SEARCH("ERROR", E20))), "QE", IF(OR(ISNUMBER(SEARCH("TIME OUT", J20)), ISNUMBER(SEARCH("ERROR", J20))), "RC", IF(S20=0, "TIE", IF(S20>0, "QE", "RC"))))) -> RC | U20: =IF(S20="--","--",TEXT(MIN(E20,J20)/MAX(E20,J20),"0.000%")) -> -- | V20: =IF(OR(ISNUMBER(SEARCH("ERROR", F20)), ISNUMBER(SEARCH("ERROR", K20)), ISNUMBER(SEARCH("TIME OUT", F20)), ISNUMBER(SEARCH("TIME OUT", K20))),"--",F20-K20) -> -- | W20: =IF(AND(OR(ISNUMBER(SEARCH("TIME OUT", F20)), ISNUMBER(SEARCH("ERROR", F20))), OR(ISNUMBER(SEARCH("TIME OUT", K20)), ISNUMBER(SEARCH("ERROR", K20)))), "--", IF(OR(ISNUMBER(SEARCH("TIME OUT", F20)), ISNUMBER(SEARCH("ERROR", F20))), "QE", IF(OR(ISNUMBER(SEARCH("TIME OUT", K20)), ISNUMBER(SEARCH("ERROR", K20))), "RC", IF(V20=0, "TIE", IF(V20>0, "QE", "RC"))))) -> RC | X20: =IF(V20="--","--",TEXT(MIN(F20,K20)/MAX(F20,K20),"0.000%")) -> --
